Workbook
Name Button_429: "LeaseCalc_Lease_Data_List"
Name CellAbove: INDIRECT(ADDRESS(ROW()-1,COLUMN()))
Name CIT: #N/A
Name IQ_CH: 110000
Name IQ_CQ: 5000
Name IQ_CY: 10000
Name IQ_DAILY: 500000
Name IQ_FH: 100000
Name IQ_FQ: 500
Name IQ_FY: 1000
Name IQ_LTM: 2000
Name IQ_MONTH: 15000
Name IQ_NTM: 6000
Name IQ_WEEK: 50000
Name IQ_YTD: 3000
Name TM1REBUILDOPTION: 1

Sheet Data | TB
A1: Data | TB
A2: Source: <document_source>
A4: Template Note | B4: Pack A scaffold only: direct formulas/values, no Excel Tables, no required named ranges.
A7: Data | TB
A8: Entity | B8: AccountNumber | C8: AccountName | D8: FS_SignConvention | E8: Currency | F8: SourceSystem | G8: ='Control | Setup'!A22 | H8: ='Control | Setup'!A23 | I8: ='Control | Setup'!A24 | J8: ='Control | Setup'!A25 | K8: ='Control | Setup'!A26 | L8: ='Control | Setup'!A27 | M8: ='Control | Setup'!A28 | N8: ='Control | Setup'!A29 | O8: ='Control | Setup'!A30 | P8: ='Control | Setup'!A31 | Q8: ='Control | Setup'!A32 | R8: ='Control | Setup'!A33 | S8: ='Control | Setup'!A34 | T8: ='Control | Setup'!A35 | U8: ='Control | Setup'!A36 | V8: ='Control | Setup'!A37 | W8: ='Control | Setup'!A38 | X8: ='Control | Setup'!A39 | Y8: ='Control | Setup'!A40 | Z8: ='Control | Setup'!A41 | AA8: ='Control | Setup'!A42 | AB8: ='Control | Setup'!A43 | AC8: ='Control | Setup'!A44 | AD8: ='Control | Setup'!A45 | AE8: ='Control | Setup'!A46 | AF8: ='Control | Setup'!A47 | AG8: ='Control | Setup'!A48 | AH8: ='Control | Setup'!A49 | AI8: ='Control | Setup'!A50 | AJ8: ='Control | Setup'!A51 | AK8: ='Control | Setup'!A52 | AL8: ='Control | Setup'!A53 | AM8: ='Control | Setup'!A54 | AN8: ='Control | Setup'!A55 | AO8: ='Control | Setup'!A56 | AP8: ='Control | Setup'!A57 | AQ8: FY-2 | AR8: FY-1 | AS8: TTM
A9: Entity 1 | B9: 4000 | C9: Revenue | D9: 1 | E9: USD | F9: Synthetic Pack F | G9: 1200 | H9: 1218 | I9: 1236 | J9: 1254 | K9: 1272 | L9: 1290 | M9: 1308 | N9: 1326 | O9: 1344 | P9: 1362 | Q9: 1380 | R9: 1398 | S9: 1416 | T9: 1434 | U9: 1452 | V9: 1470 | W9: 1488 | X9: 1506 | Y9: 1524 | Z9: 1542 | AA9: 1560 | AB9: 1578 | AC9: 1596 | AD9: 1614 | AE9: 1632 | AF9: 1650 | AG9: 1668 | AH9: 1686 | AI9: 1704 | AJ9: 1722 | AK9: 1740 | AL9: 1758 | AM9: 1776 | AN9: 1794 | AO9: 1812 | AP9: 1830 | AQ9: =SUM(S9:AD9) | AR9: =SUM(AE9:AP9) | AS9: =SUM(AE9:AP9)
A10: Entity 1 | B10: 5000 | C10: Cost of goods sold | D10: 1 | E10: USD | F10: Synthetic Pack F | G10: -672 | H10: -682.08 | I10: -692.16 | J10: -702.24 | K10: -712.32 | L10: -722.4 | M10: -732.48 | N10: -742.56 | O10: -752.64 | P10: -762.72 | Q10: -772.8 | R10: -782.88 | S10: -792.96 | T10: -803.04 | U10: -813.12 | V10: -823.2 | W10: -833.28 | X10: -843.36 | Y10: -853.44 | Z10: -863.52 | AA10: -873.6 | AB10: -883.68 | AC10: -893.76 | AD10: -903.84 | AE10: -913.92 | AF10: -924 | AG10: -934.08 | AH10: -944.16 | AI10: -954.24 | AJ10: -964.32 | AK10: -974.4 | AL10: -984.48 | AM10: -994.56 | AN10: -1004.64 | AO10: -1014.72 | AP10: -1024.8 | AQ10: =SUM(S10:AD10) | AR10: =SUM(AE10:AP10) | AS10: =SUM(AE10:AP10)
A11: Entity 1 | B11: 6100 | C11: Operating expenses | D11: 1 | E11: USD | F11: Synthetic Pack F | G11: -264 | H11: -267.96 | I11: -271.92 | J11: -275.88 | K11: -279.84 | L11: -283.8 | M11: -287.76 | N11: -291.72 | O11: -295.68 | P11: -299.64 | Q11: -303.6 | R11: -307.56 | S11: -311.52 | T11: -315.48 | U11: -319.44 | V11: -323.4 | W11: -327.36 | X11: -331.32 | Y11: -335.28 | Z11: -339.24 | AA11: -343.2 | AB11: -347.16 | AC11: -351.12 | AD11: -355.08 | AE11: -359.04 | AF11: -363 | AG11: -366.96 | AH11: -370.92 | AI11: -374.88 | AJ11: -378.84 | AK11: -382.8 | AL11: -386.76 | AM11: -390.72 | AN11: -394.68 | AO11: -398.64 | AP11: -402.6 | AQ11: =SUM(S11:AD11) | AR11: =SUM(AE11:AP11) | AS11: =SUM(AE11:AP11)
A12: Entity 1 | B12: 7100 | C12: Interest expense | D12: 1 | E12: USD | F12: Synthetic Pack F | G12: -36 | H12: -36.54 | I12: -37.08 | J12: -37.62 | K12: -38.16 | L12: -38.7 | M12: -39.24 | N12: -39.78 | O12: -40.32 | P12: -40.86 | Q12: -41.4 | R12: -41.94 | S12: -42.48 | T12: -43.02 | U12: -43.56 | V12: -44.1 | W12: -44.64 | X12: -45.18 | Y12: -45.72 | Z12: -46.26 | AA12: -46.8 | AB12: -47.34 | AC12: -47.88 | AD12: -48.42 | AE12: -48.96 | AF12: -49.5 | AG12: -50.04 | AH12: -50.58 | AI12: -51.12 | AJ12: -51.66 | AK12: -52.2 | AL12: -52.74 | AM12: -53.28 | AN12: -53.82 | AO12: -54.36 | AP12: -54.9 | AQ12: =SUM(S12:AD12) | AR12: =SUM(AE12:AP12) | AS12: =SUM(AE12:AP12)
A13: Entity 1 | B13: 7200 | C13: Taxes | D13: 1 | E13: USD | F13: Synthetic Pack F | G13: -48 | H13: -48.72 | I13: -49.44 | J13: -50.16 | K13: -50.88 | L13: -51.6 | M13: -52.32 | N13: -53.04 | O13: -53.76 | P13: -54.48 | Q13: -55.2 | R13: -55.92 | S13: -56.64 | T13: -57.36 | U13: -58.08 | V13: -58.8 | W13: -59.52 | X13: -60.24 | Y13: -60.96 | Z13: -61.68 | AA13: -62.4 | AB13: -63.12 | AC13: -63.84 | AD13: -64.56 | AE13: -65.28 | AF13: -66 | AG13: -66.72 | AH13: -67.44 | AI13: -68.16 | AJ13: -68.88 | AK13: -69.6 | AL13: -70.32 | AM13: -71.04 | AN13: -71.76 | AO13: -72.48 | AP13: -73.2 | AQ13: =SUM(S13:AD13) | AR13: =SUM(AE13:AP13) | AS13: =SUM(AE13:AP13)
A14: Entity 1 | B14: 7300 | C14: Depreciation & amortization add-back | D14: 1 | E14: USD | F14: Synthetic Pack F | G14: 72 | H14: 73.08 | I14: 74.16 | J14: 75.24 | K14: 76.32 | L14: 77.4 | M14: 78.48 | N14: 79.56 | O14: 80.64 | P14: 81.72 | Q14: 82.8 | R14: 83.88 | S14: 84.96 | T14: 86.04 | U14: 87.12 | V14: 88.2 | W14: 89.28 | X14: 90.36 | Y14: 91.44 | Z14: 92.52 | AA14: 93.6 | AB14: 94.68 | AC14: 95.76 | AD14: 96.84 | AE14: 97.92 | AF14: 99 | AG14: 100.08 | AH14: 101.16 | AI14: 102.24 | AJ14: 103.32 | AK14: 104.4 | AL14: 105.48 | AM14: 106.56 | AN14: 107.64 | AO14: 108.72 | AP14: 109.8 | AQ14: =SUM(S14:AD14) | AR14: =SUM(AE14:AP14) | AS14: =SUM(AE14:AP14)
A15: Entity 1 | B15: 7310 | C15: Interest add-back | D15: 1 | E15: USD | F15: Synthetic Pack F | G15: 36 | H15: 36.54 | I15: 37.08 | J15: 37.62 | K15: 38.16 | L15: 38.7 | M15: 39.24 | N15: 39.78 | O15: 40.32 | P15: 40.86 | Q15: 41.4 | R15: 41.94 | S15: 42.48 | T15: 43.02 | U15: 43.56 | V15: 44.1 | W15: 44.64 | X15: 45.18 | Y15: 45.72 | Z15: 46.26 | AA15: 46.8 | AB15: 47.34 | AC15: 47.88 | AD15: 48.42 | AE15: 48.96 | AF15: 49.5 | AG15: 50.04 | AH15: 50.58 | AI15: 51.12 | AJ15: 51.66 | AK15: 52.2 | AL15: 52.74 | AM15: 53.28 | AN15: 53.82 | AO15: 54.36 | AP15: 54.9 | AQ15: =SUM(S15:AD15) | AR15: =SUM(AE15:AP15) | AS15: =SUM(AE15:AP15)
A16: Entity 1 | B16: 7320 | C16: Taxes add-back | D16: 1 | E16: USD | F16: Synthetic Pack F | G16: 48 | H16: 48.72 | I16: 49.44 | J16: 50.16 | K16: 50.88 | L16: 51.6 | M16: 52.32 | N16: 53.04 | O16: 53.76 | P16: 54.48 | Q16: 55.2 | R16: 55.92 | S16: 56.64 | T16: 57.36 | U16: 58.08 | V16: 58.8 | W16: 59.52 | X16: 60.24 | Y16: 60.96 | Z16: 61.68 | AA16: 62.4 | AB16: 63.12 | AC16: 63.84 | AD16: 64.56 | AE16: 65.28 | AF16: 66 | AG16: 66.72 | AH16: 67.44 | AI16: 68.16 | AJ16: 68.88 | AK16: 69.6 | AL16: 70.32 | AM16: 71.04 | AN16: 71.76 | AO16: 72.48 | AP16: 73.2 | AQ16: =SUM(S16:AD16) | AR16: =SUM(AE16:AP16) | AS16: =SUM(AE16:AP16)
A17: Entity 1 | B17: 7400 | C17: Capex | D17: 1 | E17: USD | F17: Synthetic Pack F | G17: -36 | H17: -36.54 | I17: -37.08 | J17: -37.62 | K17: -38.16 | L17: -38.7 | M17: -39.24 | N17: -39.78 | O17: -40.32 | P17: -40.86 | Q17: -41.4 | R17: -41.94 | S17: -42.48 | T17: -43.02 | U17: -43.56 | V17: -44.1 | W17: -44.64 | X17: -45.18 | Y17: -45.72 | Z17: -46.26 | AA17: -46.8 | AB17: -47.34 | AC17: -47.88 | AD17: -48.42 | AE17: -48.96 | AF17: -49.5 | AG17: -50.04 | AH17: -50.58 | AI17: -51.12 | AJ17: -51.66 | AK17: -52.2 | AL17: -52.74 | AM17: -53.28 | AN17: -53.82 | AO17: -54.36 | AP17: -54.9 | AQ17: =SUM(S17:AD17) | AR17: =SUM(AE17:AP17) | AS17: =SUM(AE17:AP17)
A18: Entity 1 | B18: 8100 | C18: Change in NWC | D18: 1 | E18: USD | F18: Synthetic Pack F | G18: -18 | H18: -18.27 | I18: -18.54 | J18: -18.81 | K18: -19.08 | L18: -19.35 | M18: -19.62 | N18: -19.89 | O18: -20.16 | P18: -20.43 | Q18: -20.7 | R18: -20.97 | S18: -21.24 | T18: -21.51 | U18: -21.78 | V18: -22.05 | W18: -22.32 | X18: -22.59 | Y18: -22.86 | Z18: -23.13 | AA18: -23.4 | AB18: -23.67 | AC18: -23.94 | AD18: -24.21 | AE18: -24.48 | AF18: -24.75 | AG18: -25.02 | AH18: -25.29 | AI18: -25.56 | AJ18: -25.83 | AK18: -26.1 | AL18: -26.37 | AM18: -26.64 | AN18: -26.91 | AO18: -27.18 | AP18: -27.45 | AQ18: =SUM(S18:AD18) | AR18: =SUM(AE18:AP18) | AS18: =SUM(AE18:AP18)
A19: Entity 1 | B19: 8200 | C19: Other cash flow | D19: 1 | E19: USD | F19: Synthetic Pack F | G19: 12 | H19: 12.18 | I19: 12.36 | J19: 12.54 | K19: 12.72 | L19: 12.9 | M19: 13.08 | N19: 13.26 | O19: 13.44 | P19: 13.62 | Q19: 13.8 | R19: 13.98 | S19: 14.16 | T19: 14.34 | U19: 14.52 | V19: 14.7 | W19: 14.88 | X19: 15.06 | Y19: 15.24 | Z19: 15.42 | AA19: 15.6 | AB19: 15.78 | AC19: 15.96 | AD19: 16.14 | AE19: 16.32 | AF19: 16.5 | AG19: 16.68 | AH19: 16.86 | AI19: 17.04 | AJ19: 17.22 | AK19: 17.4 | AL19: 17.58 | AM19: 17.76 | AN19: 17.94 | AO19: 18.12 | AP19: 18.3 | AQ19: =SUM(S19:AD19) | AR19: =SUM(AE19:AP19) | AS19: =SUM(AE19:AP19)
A20: Entity 1 | B20: 1000 | C20: Cash | D20: 1 | E20: USD | F20: Synthetic Pack F | G20: 320 | H20: 326 | I20: 332 | J20: 338 | K20: 344 | L20: 350 | M20: 356 | N20: 362 | O20: 368 | P20: 374 | Q20: 380 | R20: 386 | S20: 392 | T20: 398 | U20: 404 | V20: 410 | W20: 416 | X20: 422 | Y20: 428 | Z20: 434 | AA20: 440 | AB20: 446 | AC20: 452 | AD20: 458 | AE20: 464 | AF20: 470 | AG20: 476 | AH20: 482 | AI20: 488 | AJ20: 494 | AK20: 500 | AL20: 506 | AM20: 512 | AN20: 518 | AO20: 524 | AP20: 530 | AQ20: =AD20 | AR20: =AP20 | AS20: =AP20
A21: Entity 1 | B21: 1100 | C21: Accounts receivable | D21: 1 | E21: USD | F21: Synthetic Pack F | G21: 168 | H21: 170.52 | I21: 173.04 | J21: 175.56 | K21: 178.08 | L21: 180.6 | M21: 183.12 | N21: 185.64 | O21: 188.16 | P21: 190.68 | Q21: 193.2 | R21: 195.72 | S21: 198.24 | T21: 200.76 | U21: 203.28 | V21: 205.8 | W21: 208.32 | X21: 210.84 | Y21: 213.36 | Z21: 215.88 | AA21: 218.4 | AB21: 220.92 | AC21: 223.44 | AD21: 225.96 | AE21: 228.48 | AF21: 231 | AG21: 233.52 | AH21: 236.04 | AI21: 238.56 | AJ21: 241.08 | AK21: 243.6 | AL21: 246.12 | AM21: 248.64 | AN21: 251.16 | AO21: 253.68 | AP21: 256.2 | AQ21: =AD21 | AR21: =AP21 | AS21: =AP21
A22: Entity 1 | B22: 1200 | C22: Inventory | D22: 1 | E22: USD | F22: Synthetic Pack F | G22: 108 | H22: 109.62 | I22: 111.24 | J22: 112.86 | K22: 114.48 | L22: 116.1 | M22: 117.72 | N22: 119.34 | O22: 120.96 | P22: 122.58 | Q22: 124.2 | R22: 125.82 | S22: 127.44 | T22: 129.06 | U22: 130.68 | V22: 132.3 | W22: 133.92 | X22: 135.54 | Y22: 137.16 | Z22: 138.78 | AA22: 140.4 | AB22: 142.02 | AC22: 143.64 | AD22: 145.26 | AE22: 146.88 | AF22: 148.5 | AG22: 150.12 | AH22: 151.74 | AI22: 153.36 | AJ22: 154.98 | AK22: 156.6 | AL22: 158.22 | AM22: 159.84 | AN22: 161.46 | AO22: 163.08 | AP22: 164.7 | AQ22: =AD22 | AR22: =AP22 | AS22: =AP22
A23: Entity 1 | B23: 1300 | C23: Other current assets | D23: 1 | E23: USD | F23: Synthetic Pack F | G23: 48 | H23: 48.72 | I23: 49.44 | J23: 50.16 | K23: 50.88 | L23: 51.6 | M23: 52.32 | N23: 53.04 | O23: 53.76 | P23: 54.48 | Q23: 55.2 | R23: 55.92 | S23: 56.64 | T23: 57.36 | U23: 58.08 | V23: 58.8 | W23: 59.52 | X23: 60.24 | Y23: 60.96 | Z23: 61.68 | AA23: 62.4 | AB23: 63.12 | AC23: 63.84 | AD23: 64.56 | AE23: 65.28 | AF23: 66 | AG23: 66.72 | AH23: 67.44 | AI23: 68.16 | AJ23: 68.88 | AK23: 69.6 | AL23: 70.32 | AM23: 71.04 | AN23: 71.76 | AO23: 72.48 | AP23: 73.2 | AQ23: =AD23 | AR23: =AP23 | AS23: =AP23
A24: Entity 1 | B24: 1500 | C24: PP&E | D24: 1 | E24: USD | F24: Synthetic Pack F | G24: 500 | H24: 504 | I24: 508 | J24: 512 | K24: 516 | L24: 520 | M24: 524 | N24: 528 | O24: 532 | P24: 536 | Q24: 540 | R24: 544 | S24: 548 | T24: 552 | U24: 556 | V24: 560 | W24: 564 | X24: 568 | Y24: 572 | Z24: 576 | AA24: 580 | AB24: 584 | AC24: 588 | AD24: 592 | AE24: 596 | AF24: 600 | AG24: 604 | AH24: 608 | AI24: 612 | AJ24: 616 | AK24: 620 | AL24: 624 | AM24: 628 | AN24: 632 | AO24: 636 | AP24: 640 | AQ24: =AD24 | AR24: =AP24 | AS24: =AP24
A25: Entity 1 | B25: 1600 | C25: Other assets | D25: 1 | E25: USD | F25: Synthetic Pack F | G25: 190 | H25: 192 | I25: 194 | J25: 196 | K25: 198 | L25: 200 | M25: 202 | N25: 204 | O25: 206 | P25: 208 | Q25: 210 | R25: 212 | S25: 214 | T25: 216 | U25: 218 | V25: 220 | W25: 222 | X25: 224 | Y25: 226 | Z25: 228 | AA25: 230 | AB25: 232 | AC25: 234 | AD25: 236 | AE25: 238 | AF25: 240 | AG25: 242 | AH25: 244 | AI25: 246 | AJ25: 248 | AK25: 250 | AL25: 252 | AM25: 254 | AN25: 256 | AO25: 258 | AP25: 260 | AQ25: =AD25 | AR25: =AP25 | AS25: =AP25
A26: Entity 1 | B26: 2000 | C26: Accounts payable | D26: 1 | E26: USD | F26: Synthetic Pack F | G26: 73.92 | H26: 75.03 | I26: 76.14 | J26: 77.25 | K26: 78.36 | L26: 79.46 | M26: 80.57 | N26: 81.68 | O26: 82.79 | P26: 83.9 | Q26: 85.01 | R26: 86.12 | S26: 87.23 | T26: 88.33 | U26: 89.44 | V26: 90.55 | W26: 91.66 | X26: 92.77 | Y26: 93.88 | Z26: 94.99 | AA26: 96.1 | AB26: 97.2 | AC26: 98.31 | AD26: 99.42 | AE26: 100.53 | AF26: 101.64 | AG26: 102.75 | AH26: 103.86 | AI26: 104.97 | AJ26: 106.08 | AK26: 107.18 | AL26: 108.29 | AM26: 109.4 | AN26: 110.51 | AO26: 111.62 | AP26: 112.73 | AQ26: =AD26 | AR26: =AP26 | AS26: =AP26
A27: Entity 1 | B27: 2100 | C27: Accrued liabilities | D27: 1 | E27: USD | F27: Synthetic Pack F | G27: 70 | H27: 71.5 | I27: 73 | J27: 74.5 | K27: 76 | L27: 77.5 | M27: 79 | N27: 80.5 | O27: 82 | P27: 83.5 | Q27: 85 | R27: 86.5 | S27: 88 | T27: 89.5 | U27: 91 | V27: 92.5 | W27: 94 | X27: 95.5 | Y27: 97 | Z27: 98.5 | AA27: 100 | AB27: 101.5 | AC27: 103 | AD27: 104.5 | AE27: 106 | AF27: 107.5 | AG27: 109 | AH27: 110.5 | AI27: 112 | AJ27: 113.5 | AK27: 115 | AL27: 116.5 | AM27: 118 | AN27: 119.5 | AO27: 121 | AP27: 122.5 | AQ27: =AD27 | AR27: =AP27 | AS27: =AP27
A28: Entity 1 | B28: 2200 | C28: Debt | D28: 1 | E28: USD | F28: Synthetic Pack F | G28: 430 | H28: 428.5 | I28: 427 | J28: 425.5 | K28: 424 | L28: 422.5 | M28: 421 | N28: 419.5 | O28: 418 | P28: 416.5 | Q28: 415 | R28: 413.5 | S28: 412 | T28: 410.5 | U28: 409 | V28: 407.5 | W28: 406 | X28: 404.5 | Y28: 403 | Z28: 401.5 | AA28: 400 | AB28: 398.5 | AC28: 397 | AD28: 395.5 | AE28: 394 | AF28: 392.5 | AG28: 391 | AH28: 389.5 | AI28: 388 | AJ28: 386.5 | AK28: 385 | AL28: 383.5 | AM28: 382 | AN28: 380.5 | AO28: 379 | AP28: 377.5 | AQ28: =AD28 | AR28: =AP28 | AS28: =AP28
A29: Entity 1 | B29: 2300 | C29: Other liabilities | D29: 1 | E29: USD | F29: Synthetic Pack F | G29: 55 | H29: 56 | I29: 57 | J29: 58 | K29: 59 | L29: 60 | M29: 61 | N29: 62 | O29: 63 | P29: 64 | Q29: 65 | R29: 66 | S29: 67 | T29: 68 | U29: 69 | V29: 70 | W29: 71 | X29: 72 | Y29: 73 | Z29: 74 | AA29: 75 | AB29: 76 | AC29: 77 | AD29: 78 | AE29: 79 | AF29: 80 | AG29: 81 | AH29: 82 | AI29: 83 | AJ29: 84 | AK29: 85 | AL29: 86 | AM29: 87 | AN29: 88 | AO29: 89 | AP29: 90 | AQ29: =AD29 | AR29: =AP29 | AS29: =AP29
A30: Entity 1 | B30: 3000 | C30: Equity | D30: 1 | E30: USD | F30: Synthetic Pack F | G30: 705.08 | H30: 719.83 | I30: 734.58 | J30: 749.33 | K30: 764.08 | L30: 778.84 | M30: 793.59 | N30: 808.34 | O30: 823.09 | P30: 837.84 | Q30: 852.59 | R30: 867.34 | S30: 882.09 | T30: 896.85 | U30: 911.6 | V30: 926.35 | W30: 941.1 | X30: 955.85 | Y30: 970.6 | Z30: 985.35 | AA30: 1000.1 | AB30: 1014.86 | AC30: 1029.61 | AD30: 1044.36 | AE30: 1059.11 | AF30: 1073.86 | AG30: 1088.61 | AH30: 1103.36 | AI30: 1118.11 | AJ30: 1132.86 | AK30: 1147.62 | AL30: 1162.37 | AM30: 1177.12 | AN30: 1191.87 | AO30: 1206.62 | AP30: 1221.37 | AQ30: =AD30 | AR30: =AP30 | AS30: =AP30
A31: Entity 2 | B31: 4000 | C31: Revenue | D31: 1 | E31: USD | F31: Synthetic Pack F | G31: 984 | H31: 998.76 | I31: 1013.52 | J31: 1028.28 | K31: 1043.04 | L31: 1057.8 | M31: 1072.56 | N31: 1087.32 | O31: 1102.08 | P31: 1116.84 | Q31: 1131.6 | R31: 1146.36 | S31: 1161.12 | T31: 1175.88 | U31: 1190.64 | V31: 1205.4 | W31: 1220.16 | X31: 1234.92 | Y31: 1249.68 | Z31: 1264.44 | AA31: 1279.2 | AB31: 1293.96 | AC31: 1308.72 | AD31: 1323.48 | AE31: 1338.24 | AF31: 1353 | AG31: 1367.76 | AH31: 1382.52 | AI31: 1397.28 | AJ31: 1412.04 | AK31: 1426.8 | AL31: 1441.56 | AM31: 1456.32 | AN31: 1471.08 | AO31: 1485.84 | AP31: 1500.6 | AQ31: =SUM(S31:AD31) | AR31: =SUM(AE31:AP31) | AS31: =SUM(AE31:AP31)
A32: Entity 2 | B32: 5000 | C32: Cost of goods sold | D32: 1 | E32: USD | F32: Synthetic Pack F | G32: -551.04 | H32: -559.31 | I32: -567.57 | J32: -575.84 | K32: -584.1 | L32: -592.37 | M32: -600.63 | N32: -608.9 | O32: -617.16 | P32: -625.43 | Q32: -633.7 | R32: -641.96 | S32: -650.23 | T32: -658.49 | U32: -666.76 | V32: -675.02 | W32: -683.29 | X32: -691.56 | Y32: -699.82 | Z32: -708.09 | AA32: -716.35 | AB32: -724.62 | AC32: -732.88 | AD32: -741.15 | AE32: -749.41 | AF32: -757.68 | AG32: -765.95 | AH32: -774.21 | AI32: -782.48 | AJ32: -790.74 | AK32: -799.01 | AL32: -807.27 | AM32: -815.54 | AN32: -823.8 | AO32: -832.07 | AP32: -840.34 | AQ32: =SUM(S32:AD32) | AR32: =SUM(AE32:AP32) | AS32: =SUM(AE32:AP32)
A33: Entity 2 | B33: 6100 | C33: Operating expenses | D33: 1 | E33: USD | F33: Synthetic Pack F | G33: -216.48 | H33: -219.73 | I33: -222.97 | J33: -226.22 | K33: -229.47 | L33: -232.72 | M33: -235.96 | N33: -239.21 | O33: -242.46 | P33: -245.7 | Q33: -248.95 | R33: -252.2 | S33: -255.45 | T33: -258.69 | U33: -261.94 | V33: -265.19 | W33: -268.44 | X33: -271.68 | Y33: -274.93 | Z33: -278.18 | AA33: -281.42 | AB33: -284.67 | AC33: -287.92 | AD33: -291.17 | AE33: -294.41 | AF33: -297.66 | AG33: -300.91 | AH33: -304.15 | AI33: -307.4 | AJ33: -310.65 | AK33: -313.9 | AL33: -317.14 | AM33: -320.39 | AN33: -323.64 | AO33: -326.88 | AP33: -330.13 | AQ33: =SUM(S33:AD33) | AR33: =SUM(AE33:AP33) | AS33: =SUM(AE33:AP33)
A34: Entity 2 | B34: 7100 | C34: Interest expense | D34: 1 | E34: USD | F34: Synthetic Pack F | G34: -29.52 | H34: -29.96 | I34: -30.41 | J34: -30.85 | K34: -31.29 | L34: -31.73 | M34: -32.18 | N34: -32.62 | O34: -33.06 | P34: -33.51 | Q34: -33.95 | R34: -34.39 | S34: -34.83 | T34: -35.28 | U34: -35.72 | V34: -36.16 | W34: -36.6 | X34: -37.05 | Y34: -37.49 | Z34: -37.93 | AA34: -38.38 | AB34: -38.82 | AC34: -39.26 | AD34: -39.7 | AE34: -40.15 | AF34: -40.59 | AG34: -41.03 | AH34: -41.48 | AI34: -41.92 | AJ34: -42.36 | AK34: -42.8 | AL34: -43.25 | AM34: -43.69 | AN34: -44.13 | AO34: -44.58 | AP34: -45.02 | AQ34: =SUM(S34:AD34) | AR34: =SUM(AE34:AP34) | AS34: =SUM(AE34:AP34)
A35: Entity 2 | B35: 7200 | C35: Taxes | D35: 1 | E35: USD | F35: Synthetic Pack F | G35: -39.36 | H35: -39.95 | I35: -40.54 | J35: -41.13 | K35: -41.72 | L35: -42.31 | M35: -42.9 | N35: -43.49 | O35: -44.08 | P35: -44.67 | Q35: -45.26 | R35: -45.85 | S35: -46.44 | T35: -47.04 | U35: -47.63 | V35: -48.22 | W35: -48.81 | X35: -49.4 | Y35: -49.99 | Z35: -50.58 | AA35: -51.17 | AB35: -51.76 | AC35: -52.35 | AD35: -52.94 | AE35: -53.53 | AF35: -54.12 | AG35: -54.71 | AH35: -55.3 | AI35: -55.89 | AJ35: -56.48 | AK35: -57.07 | AL35: -57.66 | AM35: -58.25 | AN35: -58.84 | AO35: -59.43 | AP35: -60.02 | AQ35: =SUM(S35:AD35) | AR35: =SUM(AE35:AP35) | AS35: =SUM(AE35:AP35)
A36: Entity 2 | B36: 7300 | C36: Depreciation & amortization add-back | D36: 1 | E36: USD | F36: Synthetic Pack F | G36: 59.04 | H36: 59.93 | I36: 60.81 | J36: 61.7 | K36: 62.58 | L36: 63.47 | M36: 64.35 | N36: 65.24 | O36: 66.12 | P36: 67.01 | Q36: 67.9 | R36: 68.78 | S36: 69.67 | T36: 70.55 | U36: 71.44 | V36: 72.32 | W36: 73.21 | X36: 74.1 | Y36: 74.98 | Z36: 75.87 | AA36: 76.75 | AB36: 77.64 | AC36: 78.52 | AD36: 79.41 | AE36: 80.29 | AF36: 81.18 | AG36: 82.07 | AH36: 82.95 | AI36: 83.84 | AJ36: 84.72 | AK36: 85.61 | AL36: 86.49 | AM36: 87.38 | AN36: 88.26 | AO36: 89.15 | AP36: 90.04 | AQ36: =SUM(S36:AD36) | AR36: =SUM(AE36:AP36) | AS36: =SUM(AE36:AP36)
A37: Entity 2 | B37: 7310 | C37: Interest add-back | D37: 1 | E37: USD | F37: Synthetic Pack F | G37: 29.52 | H37: 29.96 | I37: 30.41 | J37: 30.85 | K37: 31.29 | L37: 31.73 | M37: 32.18 | N37: 32.62 | O37: 33.06 | P37: 33.51 | Q37: 33.95 | R37: 34.39 | S37: 34.83 | T37: 35.28 | U37: 35.72 | V37: 36.16 | W37: 36.6 | X37: 37.05 | Y37: 37.49 | Z37: 37.93 | AA37: 38.38 | AB37: 38.82 | AC37: 39.26 | AD37: 39.7 | AE37: 40.15 | AF37: 40.59 | AG37: 41.03 | AH37: 41.48 | AI37: 41.92 | AJ37: 42.36 | AK37: 42.8 | AL37: 43.25 | AM37: 43.69 | AN37: 44.13 | AO37: 44.58 | AP37: 45.02 | AQ37: =SUM(S37:AD37) | AR37: =SUM(AE37:AP37) | AS37: =SUM(AE37:AP37)
A38: Entity 2 | B38: 7320 | C38: Taxes add-back | D38: 1 | E38: USD | F38: Synthetic Pack F | G38: 39.36 | H38: 39.95 | I38: 40.54 | J38: 41.13 | K38: 41.72 | L38: 42.31 | M38: 42.9 | N38: 43.49 | O38: 44.08 | P38: 44.67 | Q38: 45.26 | R38: 45.85 | S38: 46.44 | T38: 47.04 | U38: 47.63 | V38: 48.22 | W38: 48.81 | X38: 49.4 | Y38: 49.99 | Z38: 50.58 | AA38: 51.17 | AB38: 51.76 | AC38: 52.35 | AD38: 52.94 | AE38: 53.53 | AF38: 54.12 | AG38: 54.71 | AH38: 55.3 | AI38: 55.89 | AJ38: 56.48 | AK38: 57.07 | AL38: 57.66 | AM38: 58.25 | AN38: 58.84 | AO38: 59.43 | AP38: 60.02 | AQ38: =SUM(S38:AD38) | AR38: =SUM(AE38:AP38) | AS38: =SUM(AE38:AP38)
A39: Entity 2 | B39: 7400 | C39: Capex | D39: 1 | E39: USD | F39: Synthetic Pack F | G39: -29.52 | H39: -29.96 | I39: -30.41 | J39: -30.85 | K39: -31.29 | L39: -31.73 | M39: -32.18 | N39: -32.62 | O39: -33.06 | P39: -33.51 | Q39: -33.95 | R39: -34.39 | S39: -34.83 | T39: -35.28 | U39: -35.72 | V39: -36.16 | W39: -36.6 | X39: -37.05 | Y39: -37.49 | Z39: -37.93 | AA39: -38.38 | AB39: -38.82 | AC39: -39.26 | AD39: -39.7 | AE39: -40.15 | AF39: -40.59 | AG39: -41.03 | AH39: -41.48 | AI39: -41.92 | AJ39: -42.36 | AK39: -42.8 | AL39: -43.25 | AM39: -43.69 | AN39: -44.13 | AO39: -44.58 | AP39: -45.02 | AQ39: =SUM(S39:AD39) | AR39: =SUM(AE39:AP39) | AS39: =SUM(AE39:AP39)
A40: Entity 2 | B40: 8100 | C40: Change in NWC | D40: 1 | E40: USD | F40: Synthetic Pack F | G40: -14.76 | H40: -14.98 | I40: -15.2 | J40: -15.42 | K40: -15.65 | L40: -15.87 | M40: -16.09 | N40: -16.31 | O40: -16.53 | P40: -16.75 | Q40: -16.97 | R40: -17.2 | S40: -17.42 | T40: -17.64 | U40: -17.86 | V40: -18.08 | W40: -18.3 | X40: -18.52 | Y40: -18.75 | Z40: -18.97 | AA40: -19.19 | AB40: -19.41 | AC40: -19.63 | AD40: -19.85 | AE40: -20.07 | AF40: -20.29 | AG40: -20.52 | AH40: -20.74 | AI40: -20.96 | AJ40: -21.18 | AK40: -21.4 | AL40: -21.62 | AM40: -21.84 | AN40: -22.07 | AO40: -22.29 | AP40: -22.51 | AQ40: =SUM(S40:AD40) | AR40: =SUM(AE40:AP40) | AS40: =SUM(AE40:AP40)
A41: Entity 2 | B41: 8200 | C41: Other cash flow | D41: 1 | E41: USD | F41: Synthetic Pack F | G41: 9.84 | H41: 9.99 | I41: 10.14 | J41: 10.28 | K41: 10.43 | L41: 10.58 | M41: 10.73 | N41: 10.87 | O41: 11.02 | P41: 11.17 | Q41: 11.32 | R41: 11.46 | S41: 11.61 | T41: 11.76 | U41: 11.91 | V41: 12.05 | W41: 12.2 | X41: 12.35 | Y41: 12.5 | Z41: 12.64 | AA41: 12.79 | AB41: 12.94 | AC41: 13.09 | AD41: 13.23 | AE41: 13.38 | AF41: 13.53 | AG41: 13.68 | AH41: 13.83 | AI41: 13.97 | AJ41: 14.12 | AK41: 14.27 | AL41: 14.42 | AM41: 14.56 | AN41: 14.71 | AO41: 14.86 | AP41: 15.01 | AQ41: =SUM(S41:AD41) | AR41: =SUM(AE41:AP41) | AS41: =SUM(AE41:AP41)
A42: Entity 2 | B42: 1000 | C42: Cash | D42: 1 | E42: USD | F42: Synthetic Pack F | G42: 262.4 | H42: 268.4 | I42: 274.4 | J42: 280.4 | K42: 286.4 | L42: 292.4 | M42: 298.4 | N42: 304.4 | O42: 310.4 | P42: 316.4 | Q42: 322.4 | R42: 328.4 | S42: 334.4 | T42: 340.4 | U42: 346.4 | V42: 352.4 | W42: 358.4 | X42: 364.4 | Y42: 370.4 | Z42: 376.4 | AA42: 382.4 | AB42: 388.4 | AC42: 394.4 | AD42: 400.4 | AE42: 406.4 | AF42: 412.4 | AG42: 418.4 | AH42: 424.4 | AI42: 430.4 | AJ42: 436.4 | AK42: 442.4 | AL42: 448.4 | AM42: 454.4 | AN42: 460.4 | AO42: 466.4 | AP42: 472.4 | AQ42: =AD42 | AR42: =AP42 | AS42: =AP42
A43: Entity 2 | B43: 1100 | C43: Accounts receivable | D43: 1 | E43: USD | F43: Synthetic Pack F | G43: 137.76 | H43: 139.83 | I43: 141.89 | J43: 143.96 | K43: 146.03 | L43: 148.09 | M43: 150.16 | N43: 152.22 | O43: 154.29 | P43: 156.36 | Q43: 158.42 | R43: 160.49 | S43: 162.56 | T43: 164.62 | U43: 166.69 | V43: 168.76 | W43: 170.82 | X43: 172.89 | Y43: 174.96 | Z43: 177.02 | AA43: 179.09 | AB43: 181.15 | AC43: 183.22 | AD43: 185.29 | AE43: 187.35 | AF43: 189.42 | AG43: 191.49 | AH43: 193.55 | AI43: 195.62 | AJ43: 197.69 | AK43: 199.75 | AL43: 201.82 | AM43: 203.88 | AN43: 205.95 | AO43: 208.02 | AP43: 210.08 | AQ43: =AD43 | AR43: =AP43 | AS43: =AP43
...
