Workbook
Name ctl_monthly_period_count: '_Sys|Config'!$B$2
Name ctl_month_start: '_Sys|Config'!$B$3
Name ctl_tolerance_abs: '_Sys|Config'!$B$4
Name ctl_tolerance_pct: '_Sys|Config'!$B$5
Name ctl_project_name: '_Sys|Config'!$B$6

Sheet Project North >>>
C4: KPMG
C11: =MID(MID(CELL("filename",C2),FIND("]",CELL("filename",C2))+1,256),1,LEN(MID(CELL("filename",C2),FIND("]",CELL("filename",C2))+1,256))-4)
C16: DRAFT
C17: Financial due diligence assistance
C20: =TODAY()
C23: PRIVATE AND CONFIDENTIAL
N24: VA

Sheet Disclaimer
C1: Notice and disclaimer
C3: Context and scope of work
C5: This Excel workbook is provided to Client Company Payment Services Inc. (“Client” or “You”) on a confidential basis pursuant to our engagement letter dated May 20, 2024 (“Engagement Letter”) and is subject in all respects to the terms and conditions of the Engagement Letter, including restrictions on use of this report by third parties.
C7: If this Excel Workbook is received by any party other than Client, the recipient is placed on notice that this report has been prepared solely for Client’s benefit and its own use. KPMG LLP (“KPMG”) does not authorize recipient or any other party to rely on this report and any such reliance shall be at recipient’s sole risk. Therefore, KPMG shall have no liability or responsibility in respect of the advice, recommendations, or other information in this report to recipient or any other party other than Client. Further, this report and its contents may not be shared with or disclosed by the recipient to any party without the express written consent of Client and KPMG.
C9: KPMG approach
C11: Our Excel workbook makes reference to ‘KPMG Analysis’; this indicates only that we have (where specified) undertaken certain analytical activities on the underlying data to arrive at the information presented; we do not accept responsibility for the underlying data. The analysis of 'normalized'/'underlying‘ earnings and working capital is for indicative purposes only. We have sought to illustrate the effect on EBITDA/working capital of adjusting for those items identified in the course of our work that may be considered to be 'non-recurring' or 'exceptional' using criteria established by the Client. However the selection and quantification of such adjustments are necessarily judgmental. Because there is no authoritative literature or common standard with respect to the calculation of 'normalized'/'underlying' earnings/working capital, there is no basis to state whether all appropriate and comparable adjustments have been made. In addition, while the adjustments may indeed relate to items which are 'non-recurring' or 'exceptional' or otherwise unrepresentative of the trend, it is possible that earnings/working capital for future periods may be affected by such items, which may be different from the historical items.
C13: The trailing twelve months ("TTM") run rate analysis has been prepared for illustrative purposes. There is no authoritative literature or common standard with respect to the calculation of 'run rate' EBITDA, and therefore there is no basis on which to state whether, in the illustrative analysis of 'run rate‘ EBITDA, all appropriate and comparable adjustments have been made. We have set out in our report the basis on which items have been included in or excluded from the run rate calculations for particular years. It is for you to satisfy yourselves as to whether the items included or excluded are appropriate for your purposes. The decision as to what items should be included in or excluded from the calculation of 'run rate' EBITDA is highly judgmental; you may choose to interpret the information presented differently.
C15: The procedures we performed do not constitute an audit, examination or review in accordance with standards established by the Auditing and Assurance Standards Board (“AASB”) in Canada, and we have not otherwise verified the information we obtained or presented in this report. We express no opinion or any other form of assurance on Client’s internal control over financial reporting or on the information presented in our report and make no representations concerning its accuracy or completeness.
C17: We have not compiled, examined, or applied other procedures in accordance with the Assurance and Related Services Guidelines issued by the AASB to prospective information contained in this document and, accordingly, express no opinion or any other form of assurance or representations concerning the accuracy, completeness or presentation format of such prospective information. There will usually be differences between projected and actual results, because events and circumstances frequently do not occur as expected, and those differences may be material.
C19: The data included in this report was received from May 20, 2024 to August 8, 2024. Since many aspects of the prospective transaction have either not been finalized or are not yet documented, changes may occur that materially affect the financial and other information we received and reported to you. We have no obligation to update our report or to revise the information contained herein to reflect events and transactions occurring after August 8, 2024. We have reviewed this report with Management for the purpose of confirming the factual accuracy of the information we presented.
C21: Because of its special nature, this report is not suited for any purpose other than to assist Client in its evaluation of the business and, as such and as agreed in the Engagement Agreement, this report may be provided to any prospective purchaser parties on a non-reliance basis and does not in any way involve advice or recommendations to any prospective purchaser party as to whether to proceed with a transaction. Accordingly, KPMG does not accept any liability or responsibility to any third party who may use or place reliance on our report.

Sheet QofE >>

Sheet QofE | Bridge
B1: Project Name
B2: =C7
B3: Source: TBD
B4: WORKING DRAFT
C7: Quality of earnings | Bridge | AI7: Comments
E8: TTM Apr-24 (As of Apr-24) | K8: Jun-24 roll-forward change | Q8: TTM Jun-24 (YTD Apr-24 run-rate) | W8: YTD Jun-24 run-rate change | AC8: TTM Jun-24 (As of Jun-24)
C9: $'000 | D9: Ref | E9: FY21 | F9: FY22 | G9: FY23 | H9: TTM Apr-24 | I9: TTM Jun-24 | K9: FY21 | L9: FY22 | M9: FY23 | N9: TTM Apr-24 | O9: TTM Jun-24 | Q9: FY21 | R9: FY22 | S9: FY23 | T9: TTM Apr-24 | U9: TTM Jun-24 | W9: FY21 | X9: FY22 | Y9: FY23 | Z9: TTM Apr-24 | AA9: TTM Jun-24 | AC9: FY21 | AD9: FY22 | AE9: FY23 | AF9: TTM Apr-24 | AG9: TTM Jun-24
C10: Revenue, reported
C11: Due diligence adjustments
C12: =C49 | D12: =D49
C13: =C50 | D13: =D50
C14: =C51 | D14: =D51
C15: Due diligence adjustments
C16: Revenue, due diligence adjusted
C17: Pro forma adjustments
C18: =C71 | D18: =D71
C19: =C72 | D19: =D72
C20: =C73 | D20: =D73
C21: =C74 | D21: =D74
C22: =C75 | D22: =D75
C23: =C76 | D23: =D76
C24: =C77 | D24: =D77
C25: =C78 | D25: =D78
C26: =C79 | D26: =D79
C27: =C80 | D27: =D80
C28: =C81 | D28: =D81
C29: =C82 | D29: =D82
... C31: =C84 | D31: =D84
C32: =C87 | D32: =D87
C33: =C89 | D33: =D89
C34: =C90 | D34: =D90
C35: =C91 | D35: =D91
C36: =C92 | D36: =D92
C37: Pro forma adjustments
C38: Revenue, pro forma adjusted
C39: Revenue, pro forma adjusted growth rate
C41: Net income, reported
C42: Add/(deduct)
C43: Interest, net
C44: Depreciation & amortization
...

Sheet QofE | Summary
B1: Project Name
B2: =C7
B3: Source: TBD
B4: WORKING DRAFT
C7: Quality of earnings
C8: $'000 | D8: ='QofE | Detail'!AU8 | E8: ='QofE | Detail'!AV8 | F8: ='QofE | Detail'!AW8 | G8: ='QofE | Detail'!AX8 | H8: ='QofE | Detail'!AY8
C9: Revenue, reported | D9: ='QofE | Detail'!AU9 | E9: ='QofE | Detail'!AV9 | F9: ='QofE | Detail'!AW9 | G9: ='QofE | Detail'!AX9 | H9: ='QofE | Detail'!AY9
C10: Due diligence adjustments | D10: ='QofE | Detail'!AU14
C11: Pro forma adjustments | D11: ='QofE | Detail'!AU36
C12: Revenue, pro forma adjusted | D12: =SUM(D9:D11)
C13: Revenue, pro forma adjusted growth rate
C15: Net income, reported | D15: ='QofE | Detail'!AU40
C16: Add/(deduct)
C17: Interest, net | D17: ='QofE | Detail'!AU42
C18: Depreciation & amortization | D18: ='QofE | Detail'!AU43
C19: Other comprehensive income | D19: ='QofE | Detail'!AU44
C20: Income taxes | D20: ='QofE | Detail'!AU45
C21: EBITDA, reported | D21: =SUM(D15:D20)
C22: Due diligence adjustments | D22: ='QofE | Detail'!AU67
C23: Pro forma adjustments | D23: ='QofE | Detail'!AU93
C24: EBITDA, pro forma adjusted | D24: =SUM(D21:D23)
C25: EBITDA margin, pro forma adjusted | D25: =IFERROR(D24/D12,0)
C27: Check | D27: ='QofE | Detail'!AU94-D24 | E27: ='QofE | Detail'!AV94-E24 | F27: ='QofE | Detail'!AW94-F24 | G27: ='QofE | Detail'!AX94-G24 | H27: ='QofE | Detail'!AY94-H24

Sheet QofE | Detail
B1: Project Name
B2: =C7
B3: Source: TBD
B4: WORKING DRAFT
C7: Quality of earnings | BA7: Comments
C8: $'000 | D8: Ref | E8: =ctl_month_start | F8: =EDATE(ctl_month_start,1) | G8: =EDATE(ctl_month_start,2) | H8: =EDATE(ctl_month_start,3) | I8: =EDATE(ctl_month_start,4) | J8: =EDATE(ctl_month_start,5) | K8: =EDATE(ctl_month_start,6) | L8: =EDATE(ctl_month_start,7) | M8: =EDATE(ctl_month_start,8) | N8: =EDATE(ctl_month_start,9) | O8: =EDATE(ctl_month_start,10) | P8: =EDATE(ctl_month_start,11) | Q8: =EDATE(ctl_month_start,12) | R8: =EDATE(ctl_month_start,13) | S8: =EDATE(ctl_month_start,14) | T8: =EDATE(ctl_month_start,15) | U8: =EDATE(ctl_month_start,16) | V8: =EDATE(ctl_month_start,17) | W8: =EDATE(ctl_month_start,18) | X8: =EDATE(ctl_month_start,19) | Y8: =EDATE(ctl_month_start,20) | Z8: =EDATE(ctl_month_start,21) | AA8: =EDATE(ctl_month_start,22) | AB8: =EDATE(ctl_month_start,23) | AC8: =EDATE(ctl_month_start,24) | AD8: =EDATE(ctl_month_start,25) | AE8: =EDATE(ctl_month_start,26) | AF8: =EDATE(ctl_month_start,27) | AG8: =EDATE(ctl_month_start,28) | AH8: =EDATE(ctl_month_start,29) | AI8: =EDATE(ctl_month_start,30) | AJ8: =EDATE(ctl_month_start,31) | AK8: =EDATE(ctl_month_start,32) | AL8: =EDATE(ctl_month_start,33) | AM8: =EDATE(ctl_month_start,34) | AN8: =EDATE(ctl_month_start,35)
C9: Revenue, reported | AO9: ='Income statement'!AP117 | AP9: ='Income statement'!AQ117 | AQ9: ='Income statement'!AR117 | AR9: ='Income statement'!AS117 | AS9: ='Income statement'!AT117 | AT9: ='Income statement'!AU117 | AU9: =SUM(E9:P9) | AV9: =SUM(Q9:AB9) | AW9: =SUM(AC9:AN9) | AX9: =SUM(AG9:AR9) | AY9: =SUM(AI9:AT9)
C10: Due diligence adjustments
C11: =C48 | D11: =D48 | AO11: =AO48 | AP11: =AP48 | AQ11: =AQ48 | AR11: =AR48 | AS11: =AS48 | AT11: =AT48 | AU11: =SUM(E11:P11) | AV11: =SUM(Q11:AB11) | AW11: =SUM(AC11:AN11) | AX11: =SUM(AG11:AR11) | AY11: =SUM(AI11:AT11)
C12: =C49 | D12: =D49 | AU12: =SUM(E12:P12) | AV12: =SUM(Q12:AB12) | AW12: =SUM(AC12:AN12) | AX12: =SUM(AG12:AR12) | AY12: =SUM(AI12:AT12)
C13: =C50 | D13: =D50 | AO13: =AO50 | AP13: =AP50 | AQ13: =AQ50 | AR13: =AR50 | AS13: =AS50 | AT13: =AT50 | AU13: =SUM(E13:P13) | AV13: =SUM(Q13:AB13) | AW13: =SUM(AC13:AN13) | AX13: =SUM(AG13:AR13) | AY13: =SUM(AI13:AT13)
C14: Due diligence adjustments | AO14: =SUM(AO11:AO13) | AP14: =SUM(AP11:AP13) | AQ14: =SUM(AQ11:AQ13) | AR14: =SUM(AR11:AR13) | AS14: =SUM(AS11:AS13) | AT14: =SUM(AT11:AT13) | AU14: =SUM(AU11:AU13) | AV14: =SUM(AV11:AV13) | ... AY14: =SUM(AY11:AY13)
C15: Revenue, due diligence adjusted | AO15: =SUM(AO14,AO9) | AP15: =SUM(AP14,AP9) | AQ15: =SUM(AQ14,AQ9) | AR15: =SUM(AR14,AR9) | AS15: =SUM(AS14,AS9) | AT15: =SUM(AT14,AT9) | AU15: =SUM(AU14,AU9) | AV15: =SUM(AV14,AV9) | ... AY15: =SUM(AY14,AY9)
C16: Pro forma adjustments
C17: =C70 | D17: =D70 | AU17: =SUM(E17:P17) | AV17: =SUM(Q17:AB17) | AW17: =SUM(AC17:AN17) | AX17: =SUM(AG17:AR17) | AY17: =SUM(AI17:AT17)
C18: =C71 | D18: =D71 | AU18: =SUM(E18:P18) | AV18: =SUM(Q18:AB18) | AW18: =SUM(AC18:AN18) | AX18: =SUM(AG18:AR18) | AY18: =SUM(AI18:AT18)
C19: =C72 | D19: =D72 | AO19: =SUM(AO17:AO18) | AP19: =SUM(AP17:AP18) | AQ19: =SUM(AQ17:AQ18) | AR19: =SUM(AR17:AR18) | AS19: =SUM(AS17:AS18) | AT19: =SUM(AT17:AT18) | AU19: =SUM(AU17:AU18) | AV19: =SUM(AV17:AV18) | ... AY19: =SUM(AY17:AY18)
C20: =C73 | D20: =D73 | AU20: =SUM(E20:P20) | AV20: =SUM(Q20:AB20) | AW20: =SUM(AC20:AN20) | AX20: =SUM(AG20:AR20) | AY20: =SUM(AI20:AT20)
C21: =C74 | D21: =D74 | AU21: =SUM(E21:P21) | AV21: =SUM(Q21:AB21) | AW21: =SUM(AC21:AN21) | AX21: =SUM(AG21:AR21) | AY21: =SUM(AI21:AT21)
C22: =C75 | D22: =D75 | AU22: =SUM(E22:P22) | AV22: =SUM(Q22:AB22) | AW22: =SUM(AC22:AN22) | AX22: =SUM(AG22:AR22) | AY22: =SUM(AI22:AT22)
C23: =C76 | D23: =D76 | AU23: =SUM(E23:P23) | AV23: =SUM(Q23:AB23) | AW23: =SUM(AC23:AN23) | AX23: =SUM(AG23:AR23) | AY23: =SUM(AI23:AT23)
C24: =C77 | D24: =D77 | AU24: =SUM(E24:P24) | AV24: =SUM(Q24:AB24) | AW24: =SUM(AC24:AN24) | AX24: =SUM(AG24:AR24) | AY24: =SUM(AI24:AT24)
C25: =C78 | D25: =D78 | AU25: =SUM(E25:P25) | AV25: =SUM(Q25:AB25) | AW25: =SUM(AC25:AN25) | AX25: =SUM(AG25:AR25) | AY25: =SUM(AI25:AT25)
C26: =C79 | D26: =D79 | AU26: =SUM(E26:P26) | AV26: =SUM(Q26:AB26) | AW26: =SUM(AC26:AN26) | AX26: =SUM(AG26:AR26) | AY26: =SUM(AI26:AT26)
C27: =C80 | D27: =D80 | AU27: =SUM(E27:P27) | AV27: =SUM(Q27:AB27) | AW27: =SUM(AC27:AN27) | AX27: =SUM(AG27:AR27) | AY27: =SUM(AI27:AT27)
C28: =C81 | D28: =D81 | AU28: =SUM(E28:P28) | AV28: =SUM(Q28:AB28) | AW28: =SUM(AC28:AN28) | AX28: =SUM(AG28:AR28) | AY28: =SUM(AI28:AT28)
C29: =C82 | D29: =D82 | AU29: =SUM(E29:P29) | AV29: =SUM(Q29:AB29) | AW29: =SUM(AC29:AN29) | AX29: =SUM(AG29:AR29) | AY29: =SUM(AI29:AT29)
C30: =C83 | D30: =D83 | AO30: =SUM(AO20:AO29) | AP30: =SUM(AP20:AP29) | AQ30: =SUM(AQ20:AQ29) | AR30: =SUM(AR20:AR29) | AS30: =SUM(AS20:AS29) | AT30: =SUM(AT20:AT29) | AU30: =SUM(AU20:AU29) | AV30: =SUM(AV20:AV29) | ... AY30: =SUM(AY20:AY29)
C31: =C86 | D31: =D86 | AU31: =SUM(E31:P31) | AV31: =SUM(Q31:AB31) | AW31: =SUM(AC31:AN31) | AX31: =SUM(AG31:AR31) | AY31: =SUM(AI31:AT31)
C32: =C88 | D32: =D88 | AU32: =SUM(E32:P32) | AV32: =SUM(Q32:AB32) | AW32: =SUM(AC32:AN32) | AX32: =SUM(AG32:AR32) | AY32: =SUM(AI32:AT32)
C33: =C89 | D33: =D89 | AU33: =SUM(E33:P33) | AV33: =SUM(Q33:AB33) | AW33: =SUM(AC33:AN33) | AX33: =SUM(AG33:AR33) | AY33: =SUM(AI33:AT33)
C34: =C90 | D34: =D90 | AO34: =AO90 | AP34: =AP90 | AQ34: =AQ90 | AR34: =AR90 | AS34: =AS90 | AT34: =AT90 | AU34: =SUM(E34:P34) | AV34: =SUM(Q34:AB34) | AW34: =SUM(AC34:AN34) | AX34: =SUM(AG34:AR34) | AY34: =SUM(AI34:AT34)
C35: =C91 | D35: =D91 | AU35: =SUM(E35:P35) | AV35: =SUM(Q35:AB35) | AW35: =SUM(AC35:AN35) | AX35: =SUM(AG35:AR35) | AY35: =SUM(AI35:AT35)
C36: Pro forma adjustments | AO36: =SUM(AO30:AO35,AO19) | AP36: =SUM(AP30:AP35,AP19) | AQ36: =SUM(AQ30:AQ35,AQ19) | AR36: =SUM(AR30:AR35,AR19) | AS36: =SUM(AS30:AS35,AS19) | AT36: =SUM(AT30:AT35,AT19) | AU36: =SUM(AU30:AU35,AU19) | AV36: =SUM(AV30:AV35,AV19) | ... AY36: =SUM(AY30:AY35,AY19)
C37: Revenue, pro forma adjusted | AO37: =SUM(AO36,AO15) | AP37: =SUM(AP36,AP15) | AQ37: =SUM(AQ36,AQ15) | AR37: =SUM(AR36,AR15) | AS37: =SUM(AS36,AS15) | AT37: =SUM(AT36,AT15) | AU37: =SUM(AU36,AU15) | AV37: =SUM(AV36,AV15) | ... AY37: =SUM(AY36,AY15)
C38: Revenue, pro forma adjusted growth rate | AO38: =(AO37/AN37)-1 | AP38: =(AP37/AO37)-1 | AQ38: =(AQ37/AP37)-1 | AR38: =(AR37/AQ37)-1 | AS38: =(AS37/AR37)-1 | AT38: =(AT37/AS37)-1 | AV38: =(AV37/AU37)-1 | AW38: =(AW37/AV37)-1 | AX38: =(AX37/AW37)-1 | AY38: =(AY37/AW37)-1
C40: Net income, reported | AO40: ='Income statement'!AP353 | AP40: ='Income statement'!AQ353 | AQ40: ='Income statement'!AR353 | AR40: ='Income statement'!AS353 | AS40: ='Income statement'!AT353 | AT40: ='Income statement'!AU353 | AU40: =SUM(E40:P40) | AV40: =SUM(Q40:AB40) | AW40: =SUM(AC40:AN40) | AX40: =SUM(AG40:AR40) | AY40: =SUM(AI40:AT40)
C41: Add/(deduct)
C42: Interest, net | AO42: ='Income statement'!AP356 | AP42: ='Income statement'!AQ356 | AQ42: ='Income statement'!AR356 | AR42: ='Income statement'!AS356 | AS42: ='Income statement'!AT356 | AT42: ='Income statement'!AU356 | AU42: =SUM(E42:P42) | AV42: =SUM(Q42:AB42) | AW42: =SUM(AC42:AN42) | AX42: =SUM(AG42:AR42) | AY42: =SUM(AI42:AT42)
C43: Depreciation & amortization | AO43: ='Income statement'!AP354 | AP43: ='Income statement'!AQ354 | AQ43: ='Income statement'!AR354 | AR43: ='Income statement'!AS354 | AS43: ='Income statement'!AT354 | AT43: ='Income statement'!AU354 | AU43: =SUM(E43:P43) | AV43: =SUM(Q43:AB43) | AW43: =SUM(AC43:AN43) | AX43: =SUM(AG43:AR43) | AY43: =SUM(AI43:AT43)
...

Sheet Net debt>>

Sheet Net debt
B1: Project Name
B2: =C7
B3: Source: TBD
B4: WORKING DRAFT
C7: Net cash/(debt) | M7: Comments
E8: As at
C9: $'000 | D9: Ref | E9: =ctl_month_start | F9: =EDATE(ctl_month_start,1) | G9: =EDATE(ctl_month_start,2) | H9: =EDATE(ctl_month_start,3) | I9: =EDATE(ctl_month_start,4) | J9: =EDATE(ctl_month_start,5) | K9: =EDATE(ctl_month_start,6) | L9: =EDATE(ctl_month_start,7) | N9: =EDATE(ctl_month_start,9) | O9: =EDATE(ctl_month_start,10) | P9: =EDATE(ctl_month_start,11) | Q9: =EDATE(ctl_month_start,12) | R9: =EDATE(ctl_month_start,13) | S9: =EDATE(ctl_month_start,14) | T9: =EDATE(ctl_month_start,15) | U9: =EDATE(ctl_month_start,16) | V9: =EDATE(ctl_month_start,17) | W9: =EDATE(ctl_month_start,18) | X9: =EDATE(ctl_month_start,19) | Y9: =EDATE(ctl_month_start,20) | Z9: =EDATE(ctl_month_start,21) | AA9: =EDATE(ctl_month_start,22) | AB9: =EDATE(ctl_month_start,23) | AC9: =EDATE(ctl_month_start,24) | AD9: =EDATE(ctl_month_start,25) | AE9: =EDATE(ctl_month_start,26) | AF9: =EDATE(ctl_month_start,27) | AG9: =EDATE(ctl_month_start,28) | AH9: =EDATE(ctl_month_start,29) | AI9: =EDATE(ctl_month_start,30) | AJ9: =EDATE(ctl_month_start,31) | AK9: =EDATE(ctl_month_start,32) | AL9: =EDATE(ctl_month_start,33) | AM9: =EDATE(ctl_month_start,34) | AN9: =EDATE(ctl_month_start,35)
C10: Cash-CAD - operating | K10: ✓
C11: Cash - operating CAD | K11: ✓
C12: Cash USD - 079 | K12: ✓
C13: Cash USD - BMO harris 137 | K13: ✓
C14: Cash CAD - 095 | K14: ✓
C15: Cash and cash equivalents | D15: 1 | K15: ✓
C16: Finance lease obligations | D16: =+D15+1 | K16: ✓
C17: Current income tax liability-federal and prov | D17: a | K17: ✓
C18: Curr income tax liab IFRS adj- IFRS15 | D18: b | K18: ✓
C19: Income tax payable | D19: =D16+1 | K19: ✓
C20: Deferred compensation payable (SERP) | D20: =+D19+1 | K20: ✓
C21: Return of cap - co-op payable | D21: =+D20+1 | K21: ✓
C22: Return of cap payable - celero | D22: =+D21+1 | K22: ✓
C23: Shareholder return of capital payable | D23: =+D20+1 | K23: ✓
C24: Net cash/(debt), reported
C25: Adjustments
C26: Current maturity - prop lease | D26: i | K26: ✓
C27: Long term - property lease | D27: ii | K27: ✓
C28: Finance lease obligation - property lease | D28: b | K28: ✓
C29: Current maturities - finance lease | D29: i | K29: ✓
C30: Long term - finance lease obligations | D30: ii | K30: ✓
C31: Finance lease obligation - leased equipment | D31: a | K31: ✓
C32: Non-resident witholding tax payable | D32: =D23+1 | K32: ✓
C33: Adjustments
C34: Net cash/(debt), adjusted
C36: Check - Stratified BS
C37: Variance

Sheet Financials>>

Sheet Income statement
B1: Project Name
B2: =C7
B3: Source: TBD
B4: WORKING DRAFT
C7: Income statement
BB8: As a % of Revenue | BN8: As a % of Revenue | BZ8: As a % of Revenue | CL8: As a % of Revenue | CR8: As a % of Revenue
C9: $'000 | D9: Code | E9: Concatenate | F9: =ctl_month_start | G9: =EDATE(ctl_month_start,1) | H9: =EDATE(ctl_month_start,2) | I9: =EDATE(ctl_month_start,3) | J9: =EDATE(ctl_month_start,4) | K9: =EDATE(ctl_month_start,5) | L9: =EDATE(ctl_month_start,6) | M9: =EDATE(ctl_month_start,7) | N9: =EDATE(ctl_month_start,8) | O9: =EDATE(ctl_month_start,9) | P9: =EDATE(ctl_month_start,10) | Q9: =EDATE(ctl_month_start,11) | R9: =EDATE(ctl_month_start,12) | S9: =EDATE(ctl_month_start,13) | T9: =EDATE(ctl_month_start,14) | U9: =EDATE(ctl_month_start,15) | V9: =EDATE(ctl_month_start,16) | W9: =EDATE(ctl_month_start,17) | X9: =EDATE(ctl_month_start,18) | Y9: =EDATE(ctl_month_start,19) | Z9: =EDATE(ctl_month_start,20) | AA9: =EDATE(ctl_month_start,21) | AB9: =EDATE(ctl_month_start,22) | AC9: =EDATE(ctl_month_start,23) | AD9: =EDATE(ctl_month_start,24) | AE9: =EDATE(ctl_month_start,25) | AF9: =EDATE(ctl_month_start,26) | AG9: =EDATE(ctl_month_start,27) | AH9: =EDATE(ctl_month_start,28) | AI9: =EDATE(ctl_month_start,29) | AJ9: =EDATE(ctl_month_start,30) | AK9: =EDATE(ctl_month_start,31) | AL9: =EDATE(ctl_month_start,32) | AM9: =EDATE(ctl_month_start,33) | AN9: =EDATE(ctl_month_start,34) | AO9: =EDATE(ctl_month_start,35)
C10: Mobile tsp transactions pos- | D10: 411110 | E10: =CONCATENATE(D10," - ",C10) | AP10: 1180.3076 | AQ10: 1205.4039 | AR10: 1317.5891 | AS10: 1379.2225 | AT10: 1529.493 | AU10: 1505.7267 | AV10: =SUM(F10:Q10) | AW10: =SUM(R10:AC10) | AX10: =SUM(AD10:AO10) | AY10: =SUM(AH10:AS10) | AZ10: =SUM(AJ10:AU10) | BB10: =IFERROR(F10/F$117,0) | BC10: =IFERROR(G10/G$117,0) | BD10: =IFERROR(H10/H$117,0) | BE10: =IFERROR(I10/I$117,0) | BF10: =IFERROR(J10/J$117,0) | BG10: =IFERROR(K10/K$117,0) | BH10: =IFERROR(L10/L$117,0) | BI10: =IFERROR(M10/M$117,0) | ... CV10: =IFERROR(AZ10/AZ$117,0) | CX10: 5877.6973
C11: Png transactions revenue - pos | D11: 411101 | E11: =CONCATENATE(D11," - ",C11) | AP11: 728.33166 | AQ11: 725.70095 | AR11: 803.04041 | AS11: 809.89996 | AT11: 937.54038 | AU11: 912.18298 | AV11: =SUM(F11:Q11) | AW11: =SUM(R11:AC11) | AX11: =SUM(AD11:AO11) | AY11: =SUM(AH11:AS11) | AZ11: =SUM(AJ11:AU11) | BB11: =IFERROR(F11/F$117,0) | BC11: =IFERROR(G11/G$117,0) | BD11: =IFERROR(H11/H$117,0) | BE11: =IFERROR(I11/I$117,0) | BF11: =IFERROR(J11/J$117,0) | BG11: =IFERROR(K11/K$117,0) | BH11: =IFERROR(L11/L$117,0) | BI11: =IFERROR(M11/M$117,0) | ... CV11: =IFERROR(AZ11/AZ$117,0) | CX11: 8174.7092
C12: Merchant services debit transaction revenue | D12: 411103 | E12: =CONCATENATE(D12," - ",C12) | AP12: 281.37015 | AQ12: 305.48489 | AR12: 352.35083 | AS12: 354.12246 | AT12: 403.47647 | AU12: 412.9241 | AV12: =SUM(F12:Q12) | AW12: =SUM(R12:AC12) | AX12: =SUM(AD12:AO12) | AY12: =SUM(AH12:AS12) | AZ12: =SUM(AJ12:AU12) | BB12: =IFERROR(F12/F$117,0) | BC12: =IFERROR(G12/G$117,0) | BD12: =IFERROR(H12/H$117,0) | BE12: =IFERROR(I12/I$117,0) | BF12: =IFERROR(J12/J$117,0) | BG12: =IFERROR(K12/K$117,0) | BH12: =IFERROR(L12/L$117,0) | BI12: =IFERROR(M12/M$117,0) | ... CV12: =IFERROR(AZ12/AZ$117,0) | CX12: 1201.2717
C13: Ifrs 15 adj to processing | D13: 411119 | E13: =CONCATENATE(D13," - ",C13) | AP13: 154 | AQ13: 148 | AR13: 165 | AS13: -6 | AT13: -5 | AU13: -6 | AV13: =SUM(F13:Q13) | AW13: =SUM(R13:AC13) | AX13: =SUM(AD13:AO13) | AY13: =SUM(AH13:AS13) | AZ13: =SUM(AJ13:AU13) | BB13: =IFERROR(F13/F$117,0) | BC13: =IFERROR(G13/G$117,0) | BD13: =IFERROR(H13/H$117,0) | BE13: =IFERROR(I13/I$117,0) | BF13: =IFERROR(J13/J$117,0) | BG13: =IFERROR(K13/K$117,0) | BH13: =IFERROR(L13/L$117,0) | BI13: =IFERROR(M13/M$117,0) | ... CV13: =IFERROR(AZ13/AZ$117,0) | CX13: -1165.6463
C14: Mobile provisioning & lcm-transaction fees | D14: 411116 | E14: =CONCATENATE(D14," - ",C14) | AP14: 115.33668 | AQ14: 149.83268 | AR14: 119.67113 | AS14: 139.75918 | AT14: 125.22612 | AU14: 128.09291 | AV14: =SUM(F14:Q14) | AW14: =SUM(R14:AC14) | AX14: =SUM(AD14:AO14) | AY14: =SUM(AH14:AS14) | AZ14: =SUM(AJ14:AU14) | BB14: =IFERROR(F14/F$117,0) | BC14: =IFERROR(G14/G$117,0) | BD14: =IFERROR(H14/H$117,0) | BE14: =IFERROR(I14/I$117,0) | BF14: =IFERROR(J14/J$117,0) | BG14: =IFERROR(K14/K$117,0) | BH14: =IFERROR(L14/L$117,0) | BI14: =IFERROR(M14/M$117,0) | ... CV14: =IFERROR(AZ14/AZ$117,0) | CX14: 893.60288
C15: Interest income-other | D15: ADJ | E15: =CONCATENATE(D15," - ",C15) | AP15: 0 | AQ15: 0 | AR15: 0 | AS15: 0 | AT15: 0 | AU15: 0 | AV15: =SUM(F15:Q15) | AW15: =SUM(R15:AC15) | AX15: =SUM(AD15:AO15) | AY15: =SUM(AH15:AS15) | AZ15: =SUM(AJ15:AU15) | BB15: =IFERROR(F15/F$117,0) | BC15: =IFERROR(G15/G$117,0) | BD15: =IFERROR(H15/H$117,0) | BE15: =IFERROR(I15/I$117,0) | BF15: =IFERROR(J15/J$117,0) | BG15: =IFERROR(K15/K$117,0) | BH15: =IFERROR(L15/L$117,0) | BI15: =IFERROR(M15/M$117,0) | ... CV15: =IFERROR(AZ15/AZ$117,0) | CX15: 0
C16: Png transactions revenue - scd | D16: 411102 | E16: =CONCATENATE(D16," - ",C16) | AP16: 88.06383 | AQ16: 86.56468 | AR16: 95.66202 | AS16: 98.0696 | AT16: 106.39485 | AU16: 102.30183 | AV16: =SUM(F16:Q16) | AW16: =SUM(R16:AC16) | AX16: =SUM(AD16:AO16) | AY16: =SUM(AH16:AS16) | AZ16: =SUM(AJ16:AU16) | BB16: =IFERROR(F16/F$117,0) | BC16: =IFERROR(G16/G$117,0) | BD16: =IFERROR(H16/H$117,0) | BE16: =IFERROR(I16/I$117,0) | BF16: =IFERROR(J16/J$117,0) | BG16: =IFERROR(K16/K$117,0) | BH16: =IFERROR(L16/L$117,0) | BI16: =IFERROR(M16/M$117,0) | ... CV16: =IFERROR(AZ16/AZ$117,0) | CX16: 1224.1593
C17: Caf revenue | D17: 411106 | E17: =CONCATENATE(D17," - ",C17) | AP17: 69.43003 | AQ17: 67.88132 | AR17: 68.78232 | AS17: 69.37502 | AT17: 76.40918 | AU17: 74.28575 | AV17: =SUM(F17:Q17) | AW17: =SUM(R17:AC17) | AX17: =SUM(AD17:AO17) | AY17: =SUM(AH17:AS17) | AZ17: =SUM(AJ17:AU17) | BB17: =IFERROR(F17/F$117,0) | BC17: =IFERROR(G17/G$117,0) | BD17: =IFERROR(H17/H$117,0) | BE17: =IFERROR(I17/I$117,0) | BF17: =IFERROR(J17/J$117,0) | BG17: =IFERROR(K17/K$117,0) | BH17: =IFERROR(L17/L$117,0) | BI17: =IFERROR(M17/M$117,0) | ... CV17: =IFERROR(AZ17/AZ$117,0) | CX17: 755.79962
C18: Reporting & other fees | D18: 411107 | E18: =CONCATENATE(D18," - ",C18) | AP18: 51.54635 | AQ18: 69.06635 | AR18: 58.06635 | AS18: 58.06635 | AT18: 70.04335 | AU18: 71.83735 | AV18: =SUM(F18:Q18) | AW18: =SUM(R18:AC18) | AX18: =SUM(AD18:AO18) | AY18: =SUM(AH18:AS18) | AZ18: =SUM(AJ18:AU18) | BB18: =IFERROR(F18/F$117,0) | BC18: =IFERROR(G18/G$117,0) | BD18: =IFERROR(H18/H$117,0) | BE18: =IFERROR(I18/I$117,0) | BF18: =IFERROR(J18/J$117,0) | BG18: =IFERROR(K18/K$117,0) | BH18: =IFERROR(L18/L$117,0) | BI18: =IFERROR(M18/M$117,0) | ... CV18: =IFERROR(AZ18/AZ$117,0) | CX18: 426.52635
C19: Host connection revenue | D19: 411114 | E19: =CONCATENATE(D19," - ",C19) | AP19: 35.4445 | AQ19: 35.4445 | AR19: 36.3445 | AS19: 35.4445 | AT19: 42.8945 | AU19: 42.8945 | AV19: =SUM(F19:Q19) | AW19: =SUM(R19:AC19) | AX19: =SUM(AD19:AO19) | AY19: =SUM(AH19:AS19) | AZ19: =SUM(AJ19:AU19) | BB19: =IFERROR(F19/F$117,0) | BC19: =IFERROR(G19/G$117,0) | BD19: =IFERROR(H19/H$117,0) | BE19: =IFERROR(I19/I$117,0) | BF19: =IFERROR(J19/J$117,0) | BG19: =IFERROR(K19/K$117,0) | BH19: =IFERROR(L19/L$117,0) | BI19: =IFERROR(M19/M$117,0) | ... CV19: =IFERROR(AZ19/AZ$117,0) | CX19: 489.934
C20: Merchant services credit transaction revenue | D20: 411104 | E20: =CONCATENATE(D20," - ",C20) | AP20: 28.96289 | AQ20: 31.63188 | AR20: 33.07393 | AS20: 31.66428 | AT20: 34.05895 | AU20: 31.34656 | AV20: =SUM(F20:Q20) | AW20: =SUM(R20:AC20) | AX20: =SUM(AD20:AO20) | AY20: =SUM(AH20:AS20) | AZ20: =SUM(AJ20:AU20) | BB20: =IFERROR(F20/F$117,0) | BC20: =IFERROR(G20/G$117,0) | BD20: =IFERROR(H20/H$117,0) | BE20: =IFERROR(I20/I$117,0) | BF20: =IFERROR(J20/J$117,0) | BG20: =IFERROR(K20/K$117,0) | BH20: =IFERROR(L20/L$117,0) | BI20: =IFERROR(M20/M$117,0) | ... CV20: =IFERROR(AZ20/AZ$117,0) | CX20: 124.66668
C21: E hub money transfer | D21: 411102 | E21: =CONCATENATE(D21," - ",C21) | AP21: 51.26563 | AQ21: 56.11116 | AR21: 70.15838 | AS21: 53.22705 | AT21: 102.35467 | AU21: 93.21207 | AV21: =SUM(F21:Q21) | AW21: =SUM(R21:AC21) | AX21: =SUM(AD21:AO21) | AY21: =SUM(AH21:AS21) | AZ21: =SUM(AJ21:AU21) | BB21: =IFERROR(F21/F$117,0) | BC21: =IFERROR(G21/G$117,0) | BD21: =IFERROR(H21/H$117,0) | BE21: =IFERROR(I21/I$117,0) | BF21: =IFERROR(J21/J$117,0) | BG21: =IFERROR(K21/K$117,0) | BH21: =IFERROR(L21/L$117,0) | BI21: =IFERROR(M21/M$117,0) | ... CV21: =IFERROR(AZ21/AZ$117,0) | CX21: 0
C22: Switch fee - in-app transactions | D22: 411110 | E22: =CONCATENATE(D22," - ",C22) | AP22: 10.31596 | AQ22: 9.119 | AR22: 9.98405 | AS22: 9.83068 | AT22: 9.77906 | AU22: 9.80628 | AV22: =SUM(F22:Q22) | AW22: =SUM(R22:AC22) | AX22: =SUM(AD22:AO22) | AY22: =SUM(AH22:AS22) | AZ22: =SUM(AJ22:AU22) | BB22: =IFERROR(F22/F$117,0) | BC22: =IFERROR(G22/G$117,0) | BD22: =IFERROR(H22/H$117,0) | BE22: =IFERROR(I22/I$117,0) | BF22: =IFERROR(J22/J$117,0) | BG22: =IFERROR(K22/K$117,0) | BH22: =IFERROR(L22/L$117,0) | BI22: =IFERROR(M22/M$117,0) | ... CV22: =IFERROR(AZ22/AZ$117,0) | CX22: 57.49521
C23: White-label atm transaction revenue (2018-) | D23: 411102 | E23: =CONCATENATE(D23," - ",C23) | AP23: 3.23509 | AQ23: 3.12583 | AR23: 3.44118 | AS23: 3.34088 | AT23: 3.55673 | AU23: 3.37948 | AV23: =SUM(F23:Q23) | AW23: =SUM(R23:AC23) | AX23: =SUM(AD23:AO23) | AY23: =SUM(AH23:AS23) | AZ23: =SUM(AJ23:AU23) | BB23: =IFERROR(F23/F$117,0) | BC23: =IFERROR(G23/G$117,0) | BD23: =IFERROR(H23/H$117,0) | BE23: =IFERROR(I23/I$117,0) | BF23: =IFERROR(J23/J$117,0) | BG23: =IFERROR(K23/K$117,0) | BH23: =IFERROR(L23/L$117,0) | BI23: =IFERROR(M23/M$117,0) | ... CV23: =IFERROR(AZ23/AZ$117,0) | CX23: 148.01661
C24: Other transaction related revenue | D24: 411105 | E24: =CONCATENATE(D24," - ",C24) | AP24: 1.99202 | AQ24: 2.75449 | AR24: 2.73307 | AS24: 2.06804 | AT24: 1.12552 | AU24: 2.11906 | AV24: =SUM(F24:Q24) | AW24: =SUM(R24:AC24) | AX24: =SUM(AD24:AO24) | AY24: =SUM(AH24:AS24) | AZ24: =SUM(AJ24:AU24) | BB24: =IFERROR(F24/F$117,0) | BC24: =IFERROR(G24/G$117,0) | BD24: =IFERROR(H24/H$117,0) | BE24: =IFERROR(I24/I$117,0) | BF24: =IFERROR(J24/J$117,0) | BG24: =IFERROR(K24/K$117,0) | BH24: =IFERROR(L24/L$117,0) | BI24: =IFERROR(M24/M$117,0) | ... CV24: =IFERROR(AZ24/AZ$117,0) | CX24: 116.4272
C25: Contractual minimum fees | D25: 411109 | E25: =CONCATENATE(D25," - ",C25) | AP25: 4.41285 | AQ25: 5.89969 | AR25: 3.73611 | AS25: 4.04702 | AT25: 7.12328 | AU25: 7.85363 | AV25: =SUM(F25:Q25) | AW25: =SUM(R25:AC25) | AX25: =SUM(AD25:AO25) | AY25: =SUM(AH25:AS25) | AZ25: =SUM(AJ25:AU25) | BB25: =IFERROR(F25/F$117,0) | BC25: =IFERROR(G25/G$117,0) | BD25: =IFERROR(H25/H$117,0) | BE25: =IFERROR(I25/I$117,0) | BF25: =IFERROR(J25/J$117,0) | BG25: =IFERROR(K25/K$117,0) | BH25: =IFERROR(L25/L$117,0) | BI25: =IFERROR(M25/M$117,0) | ... CV25: =IFERROR(AZ25/AZ$117,0) | CX25: 39.8584
C26: Merchant batch close fees | D26: 411111 | E26: =CONCATENATE(D26," - ",C26) | AP26: 0.0005 | AQ26: -5e-05 | AR26: 0 | AS26: 0 | AT26: 0 | AU26: 0 | AV26: =SUM(F26:Q26) | AW26: =SUM(R26:AC26) | AX26: =SUM(AD26:AO26) | AY26: =SUM(AH26:AS26) | AZ26: =SUM(AJ26:AU26) | BB26: =IFERROR(F26/F$117,0) | BC26: =IFERROR(G26/G$117,0) | BD26: =IFERROR(H26/H$117,0) | BE26: =IFERROR(I26/I$117,0) | BF26: =IFERROR(J26/J$117,0) | BG26: =IFERROR(K26/K$117,0) | BH26: =IFERROR(L26/L$117,0) | BI26: =IFERROR(M26/M$117,0) | ... CV26: =IFERROR(AZ26/AZ$117,0) | CX26: 6.70943
C27: Merchant residual revenue - square | D27: 411138 | E27: =CONCATENATE(D27," - ",C27) | AP27: 0 | AQ27: 0 | AR27: 0 | AS27: 0 | AT27: 0 | AU27: 0 | AV27: =SUM(F27:Q27) | AW27: =SUM(R27:AC27) | AX27: =SUM(AD27:AO27) | AY27: =SUM(AH27:AS27) | AZ27: =SUM(AJ27:AU27) | BB27: =IFERROR(F27/F$117,0) | BC27: =IFERROR(G27/G$117,0) | BD27: =IFERROR(H27/H$117,0) | BE27: =IFERROR(I27/I$117,0) | BF27: =IFERROR(J27/J$117,0) | BG27: =IFERROR(K27/K$117,0) | BH27: =IFERROR(L27/L$117,0) | BI27: =IFERROR(M27/M$117,0) | ... CV27: =IFERROR(AZ27/AZ$117,0) | CX27: 0.77818
... C29: Settlement services | D29: 411112 | E29: =CONCATENATE(D29," - ",C29) | AP29: 24.475 | AQ29: 24.2375 | AR29: 24.3125 | AS29: 24.3125 | AT29: 24.425 | AU29: 24.6125 | AV29: =SUM(F29:Q29) | AW29: =SUM(R29:AC29) | AX29: =SUM(AD29:AO29) | AY29: =SUM(AH29:AS29) | AZ29: =SUM(AJ29:AU29) | BB29: =IFERROR(F29/F$117,0) | BC29: =IFERROR(G29/G$117,0) | BD29: =IFERROR(H29/H$117,0) | BE29: =IFERROR(I29/I$117,0) | BF29: =IFERROR(J29/J$117,0) | BG29: =IFERROR(K29/K$117,0) | BH29: =IFERROR(L29/L$117,0) | BI29: =IFERROR(M29/M$117,0) | ... CV29: =IFERROR(AZ29/AZ$117,0) | CX29: 195.76774
C30: Processing services revenue | AP30: =SUM(AP10:AP29) | AQ30: =SUM(AQ10:AQ29) | AR30: =SUM(AR10:AR29) | AS30: =SUM(AS10:AS29) | AT30: =SUM(AT10:AT29) | AU30: =SUM(AU10:AU29) | AV30: =SUM(AV10:AV29) | AW30: =SUM(AW10:AW29) | ... AZ30: =SUM(AZ10:AZ29) | BB30: =IFERROR(F30/F$117,0) | BC30: =IFERROR(G30/G$117,0) | BD30: =IFERROR(H30/H$117,0) | BE30: =IFERROR(I30/I$117,0) | BF30: =IFERROR(J30/J$117,0) | BG30: =IFERROR(K30/K$117,0) | BH30: =IFERROR(L30/L$117,0) | BI30: =IFERROR(M30/M$117,0) | ... CV30: =IFERROR(AZ30/AZ$117,0) | CX30: =SUM(CX10:CX29)
C31: Card manufacture for fi - cci | D31: 411229 | E31: =CONCATENATE(D31," - ",C31) | AP31: 646.50429 | AQ31: 1201.2549 | AR31: 189.04252 | AS31: 369.16721 | AT31: 215.71517 | AU31: 278.77138 | AV31: =SUM(F31:Q31) | AW31: =SUM(R31:AC31) | AX31: =SUM(AD31:AO31) | AY31: =SUM(AH31:AS31) | AZ31: =SUM(AJ31:AU31) | BB31: =IFERROR(F31/F$117,0) | BC31: =IFERROR(G31/G$117,0) | BD31: =IFERROR(H31/H$117,0) | BE31: =IFERROR(I31/I$117,0) | BF31: =IFERROR(J31/J$117,0) | BG31: =IFERROR(K31/K$117,0) | BH31: =IFERROR(L31/L$117,0) | BI31: =IFERROR(M31/M$117,0) | ... CV31: =IFERROR(AZ31/AZ$117,0) | CX31: 2892.7684
C32: Card personalization revenue | D32: 411228 | E32: =CONCATENATE(D32," - ",C32) | AP32: 102.58528 | AQ32: 145.02828 | AR32: 76.33061 | AS32: 128.66676 | AT32: 188.5095 | AU32: 109.32997 | AV32: =SUM(F32:Q32) | AW32: =SUM(R32:AC32) | AX32: =SUM(AD32:AO32) | AY32: =SUM(AH32:AS32) | AZ32: =SUM(AJ32:AU32) | BB32: =IFERROR(F32/F$117,0) | BC32: =IFERROR(G32/G$117,0) | BD32: =IFERROR(H32/H$117,0) | BE32: =IFERROR(I32/I$117,0) | BF32: =IFERROR(J32/J$117,0) | BG32: =IFERROR(K32/K$117,0) | BH32: =IFERROR(L32/L$117,0) | BI32: =IFERROR(M32/M$117,0) | ... CV32: =IFERROR(AZ32/AZ$117,0) | CX32: 528.75455
C33: Card collateral & pin mailer | D33: 411227 | E33: =CONCATENATE(D33," - ",C33) | AP33: 51.5036 | AQ33: 50.89901 | AR33: 40.20927 | AS33: 66.18783 | AT33: 128.89512 | AU33: 57.44058 | AV33: =SUM(F33:Q33) | AW33: =SUM(R33:AC33) | AX33: =SUM(AD33:AO33) | AY33: =SUM(AH33:AS33) | AZ33: =SUM(AJ33:AU33) | BB33: =IFERROR(F33/F$117,0) | BC33: =IFERROR(G33/G$117,0) | BD33: =IFERROR(H33/H$117,0) | BE33: =IFERROR(I33/I$117,0) | BF33: =IFERROR(J33/J$117,0) | BG33: =IFERROR(K33/K$117,0) | BH33: =IFERROR(L33/L$117,0) | BI33: =IFERROR(M33/M$117,0) | ... CV33: =IFERROR(AZ33/AZ$117,0) | CX33: 374.82141
C34: Cards order processing & report fee | D34: 411226 | E34: =CONCATENATE(D34," - ",C34) | AP34: 1.29789 | AQ34: 12.29592 | AR34: 12.29592 | AS34: 12.29592 | AT34: 12.29592 | AU34: 12.29592 | AV34: =SUM(F34:Q34) | AW34: =SUM(R34:AC34) | AX34: =SUM(AD34:AO34) | AY34: =SUM(AH34:AS34) | AZ34: =SUM(AJ34:AU34) | BB34: =IFERROR(F34/F$117,0) | BC34: =IFERROR(G34/G$117,0) | BD34: =IFERROR(H34/H$117,0) | BE34: =IFERROR(I34/I$117,0) | BF34: =IFERROR(J34/J$117,0) | BG34: =IFERROR(K34/K$117,0) | BH34: =IFERROR(L34/L$117,0) | BI34: =IFERROR(M34/M$117,0) | ... CV34: =IFERROR(AZ34/AZ$117,0) | CX34: 175.94402
C35: Cards ancillary services | D35: 411224 | E35: =CONCATENATE(D35," - ",C35) | AP35: 10.03042 | AQ35: 4.39082 | AR35: 3.19735 | AS35: 5.70818 | AT35: 2.38351 | AU35: 4.62558 | AV35: =SUM(F35:Q35) | AW35: =SUM(R35:AC35) | AX35: =SUM(AD35:AO35) | AY35: =SUM(AH35:AS35) | AZ35: =SUM(AJ35:AU35) | BB35: =IFERROR(F35/F$117,0) | BC35: =IFERROR(G35/G$117,0) | BD35: =IFERROR(H35/H$117,0) | BE35: =IFERROR(I35/I$117,0) | BF35: =IFERROR(J35/J$117,0) | BG35: =IFERROR(K35/K$117,0) | BH35: =IFERROR(L35/L$117,0) | BI35: =IFERROR(M35/M$117,0) | ... CV35: =IFERROR(AZ35/AZ$117,0) | CX35: 2.715
C36: Dma - program fee | D36: 411222 | E36: =CONCATENATE(D36," - ",C36) | AP36: 31.24389 | AQ36: 4.99909 | AR36: 4.99983 | AS36: 6.66465 | AT36: 5.83225 | AU36: 6.24882 | AV36: =SUM(F36:Q36) | AW36: =SUM(R36:AC36) | AX36: =SUM(AD36:AO36) | AY36: =SUM(AH36:AS36) | AZ36: =SUM(AJ36:AU36) | BB36: =IFERROR(F36/F$117,0) | BC36: =IFERROR(G36/G$117,0) | BD36: =IFERROR(H36/H$117,0) | BE36: =IFERROR(I36/I$117,0) | BF36: =IFERROR(J36/J$117,0) | BG36: =IFERROR(K36/K$117,0) | BH36: =IFERROR(L36/L$117,0) | BI36: =IFERROR(M36/M$117,0) | ... CV36: =IFERROR(AZ36/AZ$117,0) | CX36: 0
C37: Card services ifrs15 py adj- cards | D37: 411217 | E37: =CONCATENATE(D37," - ",C37) | AP37: 0 | AQ37: 0 | AR37: 0 | AS37: 0 | AT37: 0 | AU37: 0 | AV37: =SUM(F37:Q37) | AW37: =SUM(R37:AC37) | AX37: =SUM(AD37:AO37) | AY37: =SUM(AH37:AS37) | AZ37: =SUM(AJ37:AU37) | BB37: =IFERROR(F37/F$117,0) | BC37: =IFERROR(G37/G$117,0) | BD37: =IFERROR(H37/H$117,0) | BE37: =IFERROR(I37/I$117,0) | BF37: =IFERROR(J37/J$117,0) | BG37: =IFERROR(K37/K$117,0) | BH37: =IFERROR(L37/L$117,0) | BI37: =IFERROR(M37/M$117,0) | ... CV37: =IFERROR(AZ37/AZ$117,0) | CX37: 30.54996
C38: Card issuance revenue - cards | AP38: =SUM(AP31:AP37) | AQ38: =SUM(AQ31:AQ37) | AR38: =SUM(AR31:AR37) | AS38: =SUM(AS31:AS37) | AT38: =SUM(AT31:AT37) | AU38: =SUM(AU31:AU37) | AV38: =SUM(AV31:AV37) | AW38: =SUM(AW31:AW37) | ... AZ38: =SUM(AZ31:AZ37) | BB38: =IFERROR(F38/F$117,0) | BC38: =IFERROR(G38/G$117,0) | BD38: =IFERROR(H38/H$117,0) | BE38: =IFERROR(I38/I$117,0) | BF38: =IFERROR(J38/J$117,0) | BG38: =IFERROR(K38/K$117,0) | BH38: =IFERROR(L38/L$117,0) | BI38: =IFERROR(M38/M$117,0) | ... CV38: =IFERROR(AZ38/AZ$117,0) | CX38: =SUM(CX31:CX37)
C39: Dma - mastercard network interchange & switch fees | D39: 483122 | E39: =CONCATENATE(D39," - ",C39) | AP39: 194.23424 | AQ39: 285.20116 | AR39: 147.54237 | AS39: 154.83058 | AT39: 147.54907 | AU39: 175.47059 | AV39: =SUM(F39:Q39) | AW39: =SUM(R39:AC39) | AX39: =SUM(AD39:AO39) | AY39: =SUM(AH39:AS39) | AZ39: =SUM(AJ39:AU39) | BB39: =IFERROR(F39/F$117,0) | BC39: =IFERROR(G39/G$117,0) | BD39: =IFERROR(H39/H$117,0) | BE39: =IFERROR(I39/I$117,0) | BF39: =IFERROR(J39/J$117,0) | BG39: =IFERROR(K39/K$117,0) | BH39: =IFERROR(L39/L$117,0) | BI39: =IFERROR(M39/M$117,0) | ... CV39: =IFERROR(AZ39/AZ$117,0) | CX39: 0
C40: Reimbursed exp - mastercard interchg & switch fees | D40: 483106 | E40: =CONCATENATE(D40," - ",C40) | AP40: 103.22214 | AQ40: 111.2833 | AR40: 108.69878 | AS40: 86.98942 | AT40: 80.81704 | AU40: 73.01641 | AV40: =SUM(F40:Q40) | AW40: =SUM(R40:AC40) | AX40: =SUM(AD40:AO40) | AY40: =SUM(AH40:AS40) | AZ40: =SUM(AJ40:AU40) | BB40: =IFERROR(F40/F$117,0) | BC40: =IFERROR(G40/G$117,0) | BD40: =IFERROR(H40/H$117,0) | BE40: =IFERROR(I40/I$117,0) | BF40: =IFERROR(J40/J$117,0) | BG40: =IFERROR(K40/K$117,0) | BH40: =IFERROR(L40/L$117,0) | BI40: =IFERROR(M40/M$117,0) | ... CV40: =IFERROR(AZ40/AZ$117,0) | CX40: 717.68944
C41: Reimbursed expenses - postage | D41: 483102 | E41: =CONCATENATE(D41," - ",C41) | AP41: 62.19036 | AQ41: 41.49228 | AR41: 42.53087 | AS41: 53.98862 | AT41: 49.99818 | AU41: 66.60064 | AV41: =SUM(F41:Q41) | AW41: =SUM(R41:AC41) | AX41: =SUM(AD41:AO41) | AY41: =SUM(AH41:AS41) | AZ41: =SUM(AJ41:AU41) | BB41: =IFERROR(F41/F$117,0) | BC41: =IFERROR(G41/G$117,0) | BD41: =IFERROR(H41/H$117,0) | BE41: =IFERROR(I41/I$117,0) | BF41: =IFERROR(J41/J$117,0) | BG41: =IFERROR(K41/K$117,0) | BH41: =IFERROR(L41/L$117,0) | BI41: =IFERROR(M41/M$117,0) | ... CV41: =IFERROR(AZ41/AZ$117,0) | CX41: 403.81841
C42: Reimbursed expenses - freight | D42: 483103 | E42: =CONCATENATE(D42," - ",C42) | AP42: 51.96329 | AQ42: 39.69755 | AR42: 63.51417 | AS42: 42.43311 | AT42: 43.62154 | AU42: 41.46473 | AV42: =SUM(F42:Q42) | AW42: =SUM(R42:AC42) | AX42: =SUM(AD42:AO42) | AY42: =SUM(AH42:AS42) | AZ42: =SUM(AJ42:AU42) | BB42: =IFERROR(F42/F$117,0) | BC42: =IFERROR(G42/G$117,0) | BD42: =IFERROR(H42/H$117,0) | BE42: =IFERROR(I42/I$117,0) | BF42: =IFERROR(J42/J$117,0) | BG42: =IFERROR(K42/K$117,0) | BH42: =IFERROR(L42/L$117,0) | BI42: =IFERROR(M42/M$117,0) | ... CV42: =IFERROR(AZ42/AZ$117,0) | CX42: 254.74278
C43: Reimbursed exp - network interchg & swich fees | D43: 483106 | E43: =CONCATENATE(D43," - ",C43) | AP43: 68.69943 | AQ43: 67.85021 | AR43: 81.48068 | AS43: 84.52141 | AT43: 123.10139 | AU43: 121.53339 | AV43: =SUM(F43:Q43) | AW43: =SUM(R43:AC43) | AX43: =SUM(AD43:AO43) | AY43: =SUM(AH43:AS43) | AZ43: =SUM(AJ43:AU43) | BB43: =IFERROR(F43/F$117,0) | BC43: =IFERROR(G43/G$117,0) | BD43: =IFERROR(H43/H$117,0) | BE43: =IFERROR(I43/I$117,0) | BF43: =IFERROR(J43/J$117,0) | BG43: =IFERROR(K43/K$117,0) | BH43: =IFERROR(L43/L$117,0) | BI43: =IFERROR(M43/M$117,0) | ... CV43: =IFERROR(AZ43/AZ$117,0) | CX43: 90.31485
...

Sheet Balance sheet
B1: Project Name
B2: =C7
B3: Source: TBD
B4: WORKING DRAFT
C7: Balance sheet
AV8: As at | BA8: Average
C9: $'000 | D9: Code | E9: Concatenate | F9: =ctl_month_start | G9: =EDATE(ctl_month_start,1) | H9: =EDATE(ctl_month_start,2) | I9: =EDATE(ctl_month_start,3) | J9: =EDATE(ctl_month_start,4) | K9: =EDATE(ctl_month_start,5) | L9: =EDATE(ctl_month_start,6) | M9: =EDATE(ctl_month_start,7) | N9: =EDATE(ctl_month_start,8) | O9: =EDATE(ctl_month_start,9) | P9: =EDATE(ctl_month_start,10) | Q9: =EDATE(ctl_month_start,11) | R9: =EDATE(ctl_month_start,12) | S9: =EDATE(ctl_month_start,13) | T9: =EDATE(ctl_month_start,14) | U9: =EDATE(ctl_month_start,15) | V9: =EDATE(ctl_month_start,16) | W9: =EDATE(ctl_month_start,17) | X9: =EDATE(ctl_month_start,18) | Y9: =EDATE(ctl_month_start,19) | Z9: =EDATE(ctl_month_start,20) | AA9: =EDATE(ctl_month_start,21) | AB9: =EDATE(ctl_month_start,22) | AC9: =EDATE(ctl_month_start,23) | AD9: =EDATE(ctl_month_start,24) | AE9: =EDATE(ctl_month_start,25) | AF9: =EDATE(ctl_month_start,26) | AG9: =EDATE(ctl_month_start,27) | AH9: =EDATE(ctl_month_start,28) | AI9: =EDATE(ctl_month_start,29) | AJ9: =EDATE(ctl_month_start,30) | AK9: =EDATE(ctl_month_start,31) | AL9: =EDATE(ctl_month_start,32) | AM9: =EDATE(ctl_month_start,33) | AN9: =EDATE(ctl_month_start,34) | AO9: =EDATE(ctl_month_start,35)
C10: Assets
C11: Cash-CAD - operating | D11: 100210 | E11: 100210 - Cash-CAD - Operating | AP11: 13156.221 | AQ11: 6914.205 | AR11: 6163.993 | AS11: 8149.643 | AT11: 7522.4572 | AU11: 11960.892 | AV11: =Q11 | AW11: =AC11 | AX11: =AO11 | AY11: =AS11 | AZ11: =AU11 | BA11: =AVERAGE(F11:Q11) | BB11: =AVERAGE(R11:AC11) | BC11: =AVERAGE(AD11:AO11) | BD11: =AVERAGE(AH11:AS11) | BE11: =AVERAGE(AJ11:AU11) | BG11: 12220.529
C12: Cash - operating CAD | D12: 100215 | E12: 100215 - CASH - Operating CAD | AP12: 437.838 | AQ12: 187.216 | AR12: 131.674 | AS12: 285.295 | AT12: 246.89383 | AU12: 46.82403 | AV12: =Q12 | AW12: =AC12 | AX12: =AO12 | AY12: =AS12 | AZ12: =AU12 | BA12: =AVERAGE(F12:Q12) | BB12: =AVERAGE(R12:AC12) | BC12: =AVERAGE(AD12:AO12) | BD12: =AVERAGE(AH12:AS12) | BE12: =AVERAGE(AJ12:AU12) | BG12: 0
C13: Cash USD - 079 | D13: 100416 | E13: 100416 - Cash USD - 079 | AP13: 212.855 | AQ13: 8.819 | AR13: 273.321 | AS13: 277.491 | AT13: 19.16881 | AU13: 306.60843 | AV13: =Q13 | AW13: =AC13 | AX13: =AO13 | AY13: =AS13 | AZ13: =AU13 | BA13: =AVERAGE(F13:Q13) | BB13: =AVERAGE(R13:AC13) | BC13: =AVERAGE(AD13:AO13) | BD13: =AVERAGE(AH13:AS13) | BE13: =AVERAGE(AJ13:AU13) | BG13: 390.447
C14: Cash USD - BMO harris 137 | D14: 100417 | E14: 100417 - Cash USD - BMO Harris 137 | AP14: 41.355 | AQ14: 329.688 | AR14: 75.617 | AS14: 206.174 | AT14: 304.29252 | AU14: 114.4629 | AV14: =Q14 | AW14: =AC14 | AX14: =AO14 | AY14: =AS14 | AZ14: =AU14 | BA14: =AVERAGE(F14:Q14) | BB14: =AVERAGE(R14:AC14) | BC14: =AVERAGE(AD14:AO14) | BD14: =AVERAGE(AH14:AS14) | BE14: =AVERAGE(AJ14:AU14) | BG14: 178.012
C15: Cash CAD - 095 | D15: 100211 | E15: 100211 - Cash CAD - 095 | AP15: 15.981 | AQ15: 11.6 | AR15: 12.58 | AS15: 5.686 | AT15: 10.55675 | AU15: 13.90124 | AV15: =Q15 | AW15: =AC15 | AX15: =AO15 | AY15: =AS15 | AZ15: =AU15 | BA15: =AVERAGE(F15:Q15) | BB15: =AVERAGE(R15:AC15) | BC15: =AVERAGE(AD15:AO15) | BD15: =AVERAGE(AH15:AS15) | BE15: =AVERAGE(AJ15:AU15) | BG15: 6.858
C16: Cash and cash equivalents | AP16: =SUM(AP11:AP15) | AQ16: =SUM(AQ11:AQ15) | AR16: =SUM(AR11:AR15) | AS16: =SUM(AS11:AS15) | AT16: =SUM(AT11:AT15) | AU16: =SUM(AU11:AU15) | AV16: =SUM(AV11:AV15) | AW16: =SUM(AW11:AW15) | ... BE16: =SUM(BE11:BE15) | BG16: =SUM(BG11:BG15)
C17: Cash settlement - pos desjardin 147 | D17: 100370 | E17: 100370 - Cash Settlement - POS Desjardin 147 | AP17: 20013.443 | AQ17: 23209.703 | AR17: 33328.156 | AS17: 27168.531 | AT17: 38601.277 | AU17: 43082.789 | AV17: =Q17 | AW17: =AC17 | AX17: =AO17 | AY17: =AS17 | AZ17: =AU17 | BA17: =AVERAGE(F17:Q17) | BB17: =AVERAGE(R17:AC17) | BC17: =AVERAGE(AD17:AO17) | BD17: =AVERAGE(AH17:AS17) | BE17: =AVERAGE(AJ17:AU17) | BG17: 3594.054
C18: Cash settlement scd desjardin 139 | D18: 100488 | E18: 100488 - Cash Settlement SCD Desjardin 139 | AP18: 48.28 | AQ18: -871.374 | AR18: 1075.313 | AS18: 7857.143 | AT18: -1151.1836 | AU18: -1134.4438 | AV18: =Q18 | AW18: =AC18 | AX18: =AO18 | AY18: =AS18 | AZ18: =AU18 | BA18: =AVERAGE(F18:Q18) | BB18: =AVERAGE(R18:AC18) | BC18: =AVERAGE(AD18:AO18) | BD18: =AVERAGE(AH18:AS18) | BE18: =AVERAGE(AJ18:AU18) | BG18: 2914.632
C19: Icici bank settlement CAD6932- for visa debit | D19: 100350 | E19: 100350 - ICICI Bank Settlement CAD6932- For Visa Debit | AP19: 538.144 | AQ19: 558.762 | AR19: 615.808 | AS19: 660.633 | AT19: 685.99913 | AU19: 685.99913 | AV19: =Q19 | AW19: =AC19 | AX19: =AO19 | AY19: =AS19 | AZ19: =AU19 | BA19: =AVERAGE(F19:Q19) | BB19: =AVERAGE(R19:AC19) | BC19: =AVERAGE(AD19:AO19) | BD19: =AVERAGE(AH19:AS19) | BE19: =AVERAGE(AJ19:AU19) | BG19: 0
C20: Cash settlement e-transfer desj suspense 067 | D20: 100367 | E20: 100367 - Cash Settlement E-Transfer Desj Suspense 067 | AP20: 62.262 | AQ20: 71.183 | AR20: 116.118 | AS20: 69.606 | AT20: 158.82134 | AU20: 132.76535 | AV20: =Q20 | AW20: =AC20 | AX20: =AO20 | AY20: =AS20 | AZ20: =AU20 | BA20: =AVERAGE(F20:Q20) | BB20: =AVERAGE(R20:AC20) | BC20: =AVERAGE(AD20:AO20) | BD20: =AVERAGE(AH20:AS20) | BE20: =AVERAGE(AJ20:AU20) | BG20: 0
C21: Cash settlement 178 | D21: 100489 | E21: 100489 - Cash Settlement 178 | AP21: 26.706 | AQ21: 26.845 | AR21: 25.794 | AS21: 29.618 | AT21: -148.32566 | AU21: 121.90942 | AV21: =Q21 | AW21: =AC21 | AX21: =AO21 | AY21: =AS21 | AZ21: =AU21 | BA21: =AVERAGE(F21:Q21) | BB21: =AVERAGE(R21:AC21) | BC21: =AVERAGE(AD21:AO21) | BD21: =AVERAGE(AH21:AS21) | BE21: =AVERAGE(AJ21:AU21) | BG21: 32.511
C22: Cash settlement - pos 10403- 1154 | D22: 100373 | E22: TBD | AP22: 2.123 | AQ22: 1.635 | AR22: 2.445 | AS22: 1.636 | AT22: 2.63766 | AU22: 2.3727 | AV22: =Q22 | AW22: =AC22 | AX22: =AO22 | AY22: =AS22 | AZ22: =AU22 | BA22: =AVERAGE(F22:Q22) | BB22: =AVERAGE(R22:AC22) | BC22: =AVERAGE(AD22:AO22) | BD22: =AVERAGE(AH22:AS22) | BE22: =AVERAGE(AJ22:AU22) | BG22: 0
C23: Cash settlement desj etransf 1162 | D23: 100380 | E23: 100380 - Cash Settlement Desj Etransf 1162 | AP23: 0.015 | AQ23: 0.015 | AR23: 0.015 | AS23: 0.015 | AT23: 0.01483 | AU23: 0.01483 | AV23: =Q23 | AW23: =AC23 | AX23: =AO23 | AY23: =AS23 | AZ23: =AU23 | BA23: =AVERAGE(F23:Q23) | BB23: =AVERAGE(R23:AC23) | BC23: =AVERAGE(AD23:AO23) | BD23: =AVERAGE(AH23:AS23) | BE23: =AVERAGE(AJ23:AU23) | BG23: 0
C24: Cash USD - settlement td bank, n.a 154 | D24: 100418 | E24: 100418 - Cash USD - Settlement TD Bank, N.A 154 | AP24: 0 | AQ24: 0 | AR24: 0 | AS24: 0 | AT24: 0 | AU24: 1e-05 | AV24: =Q24 | AW24: =AC24 | AX24: =AO24 | AY24: =AS24 | AZ24: =AU24 | BA24: =AVERAGE(F24:Q24) | BB24: =AVERAGE(R24:AC24) | BC24: =AVERAGE(AD24:AO24) | BD24: =AVERAGE(AH24:AS24) | BE24: =AVERAGE(AJ24:AU24) | BG24: 0
C25: Cash settlement e-transfer 059 | D25: 100359 | E25: TBD | AP25: 0.549 | AQ25: 0 | AR25: 0 | AS25: 0 | AT25: 1e-05 | AU25: 0 | AV25: =Q25 | AW25: =AC25 | AX25: =AO25 | AY25: =AS25 | AZ25: =AU25 | BA25: =AVERAGE(F25:Q25) | BB25: =AVERAGE(R25:AC25) | BC25: =AVERAGE(AD25:AO25) | BD25: =AVERAGE(AH25:AS25) | BE25: =AVERAGE(AJ25:AU25) | BG25: 0
C26: Items in transit | AP26: =SUM(AP17:AP25) | AQ26: =SUM(AQ17:AQ25) | AR26: =SUM(AR17:AR25) | AS26: =SUM(AS17:AS25) | AT26: =SUM(AT17:AT25) | AU26: =SUM(AU17:AU25) | AV26: =SUM(AV17:AV25) | AW26: =SUM(AW17:AW25) | ... BE26: =SUM(BE17:BE25) | BG26: =SUM(BG17:BG25)
C27: A/R billings-subledger | D27: 120101 | E27: 120101 - A/R Billings-Subledger | AP27: 10153.072 | AQ27: 5012.974 | AR27: 7273.266 | AS27: 6359.375 | AT27: 8141.7196 | AU27: 5418.3691 | AV27: =Q27 | AW27: =AC27 | AX27: =AO27 | AY27: =AS27 | AZ27: =AU27 | BA27: =AVERAGE(F27:Q27) | BB27: =AVERAGE(R27:AC27) | BC27: =AVERAGE(AD27:AO27) | BD27: =AVERAGE(AH27:AS27) | BE27: =AVERAGE(AJ27:AU27) | BG27: 3616.041
C28: A/R-trade accrual | D28: 120201 | E28: 120201 - A/R-Trade Accrual | AP28: 4970.669 | AQ28: 5970.482 | AR28: 5259.959 | AS28: 5730.494 | AT28: 5723.6653 | AU28: 5814.5333 | AV28: =Q28 | AW28: =AC28 | AX28: =AO28 | AY28: =AS28 | AZ28: =AU28 | BA28: =AVERAGE(F28:Q28) | BB28: =AVERAGE(R28:AC28) | BC28: =AVERAGE(AD28:AO28) | BD28: =AVERAGE(AH28:AS28) | BE28: =AVERAGE(AJ28:AU28) | BG28: 3261.941
C29: Accrued merchant services fees | D29: 120301 | E29: 120301 - Accrued Merchant Services Fees | AP29: 340.102 | AQ29: 371.563 | AR29: 422.474 | AS29: 422.408 | AT29: 474.22416 | AU29: 481.02878 | AV29: =Q29 | AW29: =AC29 | AX29: =AO29 | AY29: =AS29 | AZ29: =AU29 | BA29: =AVERAGE(F29:Q29) | BB29: =AVERAGE(R29:AC29) | BC29: =AVERAGE(AD29:AO29) | BD29: =AVERAGE(AH29:AS29) | BE29: =AVERAGE(AJ29:AU29) | BG29: 200.524
C30: Accrued other receivable | D30: 120401 | E30: 120401 - Accrued Other Receivable | AP30: 236.533 | AQ30: 219.783 | AR30: 235.088 | AS30: 235.286 | AT30: 234.59109 | AU30: 234.49109 | AV30: =Q30 | AW30: =AC30 | AX30: =AO30 | AY30: =AS30 | AZ30: =AU30 | BA30: =AVERAGE(F30:Q30) | BB30: =AVERAGE(R30:AC30) | BC30: =AVERAGE(AD30:AO30) | BD30: =AVERAGE(AH30:AS30) | BE30: =AVERAGE(AJ30:AU30) | BG30: 155.917
C31: Sales tax receivables - HST/GST | D31: 130301 | E31: 130301 - Sales Tax Receivables - HST/GST | AP31: 166.579 | AQ31: 304.994 | AR31: 288.599 | AS31: 193.459 | AT31: 151.69733 | AU31: 175.55522 | AV31: =Q31 | AW31: =AC31 | AX31: =AO31 | AY31: =AS31 | AZ31: =AU31 | BA31: =AVERAGE(F31:Q31) | BB31: =AVERAGE(R31:AC31) | BC31: =AVERAGE(AD31:AO31) | BD31: =AVERAGE(AH31:AS31) | BE31: =AVERAGE(AJ31:AU31) | BG31: 99.07
C32: Interest receivables | D32: 130101 | E32: 130101 - Interest Receivables | AP32: 92.015 | AQ32: 88.057 | AR32: 115.707 | AS32: 120.436 | AT32: 138.18024 | AU32: 137.03295 | AV32: =Q32 | AW32: =AC32 | AX32: =AO32 | AY32: =AS32 | AZ32: =AU32 | BA32: =AVERAGE(F32:Q32) | BB32: =AVERAGE(R32:AC32) | BC32: =AVERAGE(AD32:AO32) | BD32: =AVERAGE(AH32:AS32) | BE32: =AVERAGE(AJ32:AU32) | BG32: 0
C33: Sales tax receivables - QST | D33: 130300 | E33: 130300 - Sales Tax Receivables - QST | AP33: 0.827 | AQ33: 0.827 | AR33: 1.334 | AS33: 0.533 | AT33: 0.53267 | AU33: 0.53267 | AV33: =Q33 | AW33: =AC33 | AX33: =AO33 | AY33: =AS33 | AZ33: =AU33 | BA33: =AVERAGE(F33:Q33) | BB33: =AVERAGE(R33:AC33) | BC33: =AVERAGE(AD33:AO33) | BD33: =AVERAGE(AH33:AS33) | BE33: =AVERAGE(AJ33:AU33) | BG33: 0.037
C34: IFRS15 adjustment to accr A/R | D34: 120215 | E34: 120215 - -IFRS15 Adjustment to Accr AR- | AP34: 0 | AQ34: 0 | AR34: 0 | AS34: 0 | AT34: 0 | AU34: 0 | AV34: =Q34 | AW34: =AC34 | AX34: =AO34 | AY34: =AS34 | AZ34: =AU34 | BA34: =AVERAGE(F34:Q34) | BB34: =AVERAGE(R34:AC34) | BC34: =AVERAGE(AD34:AO34) | BD34: =AVERAGE(AH34:AS34) | BE34: =AVERAGE(AJ34:AU34) | BG34: 0
C35: Corporate card payments suspense | D35: 143102 | E35: 143102 - Corporate Card Payments Suspense | AP35: 0 | AQ35: 0 | AR35: 0 | AS35: 0 | AT35: -0.00515 | AU35: 9.69549 | AV35: =Q35 | AW35: =AC35 | AX35: =AO35 | AY35: =AS35 | AZ35: =AU35 | BA35: =AVERAGE(F35:Q35) | BB35: =AVERAGE(R35:AC35) | BC35: =AVERAGE(AD35:AO35) | BD35: =AVERAGE(AH35:AS35) | BE35: =AVERAGE(AJ35:AU35) | BG35: 0
C36: Allowances for customers A/R | D36: 125101 | E36: 125101 - Allowances for Customers A/R | AP36: -62.419 | AQ36: -62.419 | AR36: -62.419 | AS36: -62.419 | AT36: -62.41876 | AU36: -62.41876 | AV36: =Q36 | AW36: =AC36 | AX36: =AO36 | AY36: =AS36 | AZ36: =AU36 | BA36: =AVERAGE(F36:Q36) | BB36: =AVERAGE(R36:AC36) | BC36: =AVERAGE(AD36:AO36) | BD36: =AVERAGE(AH36:AS36) | BE36: =AVERAGE(AJ36:AU36) | BG36: -116.407
C37: Accounts receivable and other receivables | AP37: =SUM(AP27:AP36) | AQ37: =SUM(AQ27:AQ36) | AR37: =SUM(AR27:AR36) | AS37: =SUM(AS27:AS36) | AT37: =SUM(AT27:AT36) | AU37: =SUM(AU27:AU36) | AV37: =SUM(AV27:AV36) | AW37: =SUM(AW27:AW36) | ... BE37: =SUM(BE27:BE36) | BG37: =SUM(BG27:BG36)
C38: Inventory - prepaid COGS | D38: 142113 | E38: 142113 - Inventory - Prepaid COGS | AP38: 624.985 | AQ38: 635.789 | AR38: 780.971 | AS38: 809.919 | AT38: 733.1211 | AU38: 678.26014 | AV38: =Q38 | AW38: =AC38 | AX38: =AO38 | AY38: =AS38 | AZ38: =AU38 | BA38: =AVERAGE(F38:Q38) | BB38: =AVERAGE(R38:AC38) | BC38: =AVERAGE(AD38:AO38) | BD38: =AVERAGE(AH38:AS38) | BE38: =AVERAGE(AJ38:AU38) | BG38: 321.696
C39: Inventory | D39: 142101 | E39: 142101 - Inventory | AP39: 428.38 | AQ39: 428.38 | AR39: 428.38 | AS39: 433.789 | AT39: 433.83963 | AU39: 422.28133 | AV39: =Q39 | AW39: =AC39 | AX39: =AO39 | AY39: =AS39 | AZ39: =AU39 | BA39: =AVERAGE(F39:Q39) | BB39: =AVERAGE(R39:AC39) | BC39: =AVERAGE(AD39:AO39) | BD39: =AVERAGE(AH39:AS39) | BE39: =AVERAGE(AJ39:AU39) | BG39: 122.314
C40: Inventory - rental units | D40: 142112 | E40: 142112 - Inventory - Rental Units | AP40: -282.064 | AQ40: -292.064 | AR40: -302.064 | AS40: -312.064 | AT40: -322.06411 | AU40: -332.06411 | AV40: =Q40 | AW40: =AC40 | AX40: =AO40 | AY40: =AS40 | AZ40: =AU40 | BA40: =AVERAGE(F40:Q40) | BB40: =AVERAGE(R40:AC40) | BC40: =AVERAGE(AD40:AO40) | BD40: =AVERAGE(AH40:AS40) | BE40: =AVERAGE(AJ40:AU40) | BG40: -67.064
C41: Inventory | AP41: =SUM(AP38:AP40) | AQ41: =SUM(AQ38:AQ40) | AR41: =SUM(AR38:AR40) | AS41: =SUM(AS38:AS40) | AT41: =SUM(AT38:AT40) | AU41: =SUM(AU38:AU40) | AV41: =SUM(AV38:AV40) | AW41: =SUM(AW38:AW40) | ... BE41: =SUM(BE38:BE40) | BG41: =SUM(BG38:BG40)
C42: Prepaid SW license fees | D42: 141511 | E42: 141511 - Prepaid SW License Fees | AP42: 1991.456 | AQ42: 2127.768 | AR42: 1851.546 | AS42: 1692.646 | AT42: 1558.5565 | AU42: 1298.7882 | AV42: =Q42 | AW42: =AC42 | AX42: =AO42 | AY42: =AS42 | AZ42: =AU42 | BA42: =AVERAGE(F42:Q42) | BB42: =AVERAGE(R42:AC42) | BC42: =AVERAGE(AD42:AO42) | BD42: =AVERAGE(AH42:AS42) | BE42: =AVERAGE(AJ42:AU42) | BG42: 1321.887
...

Sheet Cash flow
B1: Project Name
B2: =C7
B3: Source: TBD
B4: WORKING DRAFT
C7: Cash flow
C8: $'000 | D8: Code | E8: Concatenate | F8: 44197 | G8: =EOMONTH(F8,1) | H8: =EOMONTH(G8,1) | I8: =EOMONTH(H8,1) | J8: =EOMONTH(I8,1) | K8: =EOMONTH(J8,1) | L8: =EOMONTH(K8,1) | M8: =EOMONTH(L8,1) | N8: =EOMONTH(M8,1) | ... AU8: =EOMONTH(AT8,1) | AV8: FY21 | AW8: FY22 | AX8: FY23 | AY8: TTM Apr-24 | AZ8: TTM Jun-24 | BB8: FY21
C9: Operating
C10: Net income
C11: Depreciation - software | D11: 707101 | E11: 707101 - Depreciation - software
C12: Depreciation - system software- infrastructure | D12: 707121 | E12: 707121 - Depreciation - system software- infrastructure
C13: Amortization expense-software
C14: Amortization expense - idsw | D14: 708201 | E14: 708201 - Amortization expense - idsw
C15: Amortization expense - internal development
C16: Depreciation - leasehold imp | D16: 705401 | E16: 705401 - Depreciation - leasehold imp
C17: Depreciation - furniture and fixtures | D17: 705501 | E17: 705501 - Depreciation - furniture and fixtures
C18: Depreciation - office equipment | D18: 705601 | E18: 705601 - Depreciation - office equipment
C19: Depreciation - data processing equipment | D19: 705701 | E19: 705701 - Depreciation - data processing equipment
C20: Depreciation - network equipment | D20: 705820 | E20: 705820 - Depreciation - network equipment
C21: Depreciation - capitalized hw implementation | D21: 705901 | E21: 705901 - Depreciation - capitalized hw implementation
C22: Depreciation - leased asset | D22: 705920 | E22: 705920 - Depreciation - leased asset
C23: Depreciation expense
C24: Depreciation - building rou asset | D24: 705301 | E24: 705301 - Depreciation - building rou asset
C25: Depreciation expense - property right of use
C26: Depreciation and amortization expense
C27: Deferred tax liability | D27: 260101 | E27: 260101 - Deferred Tax Liability
C28: Deferred tax liability IFRS- IFRS adjusted | D28: 260115 | E28: 260115 - Deferred Tax Liability IFRS- IFRS Adjusted
C29: Deferred tax liabilities
C30: Non cash items
C31: Change in working capital
C32: Cash settlement - pos desjardin 147
C33: Cash settlement scd desjardin 139
C34: Icici bank settlement CAD6932- for visa debit
C35: Cash settlement e-transfer desj suspense 067
C36: Cash settlement 178
C37: Cash settlement - pos 10403- 1154
C38: Cash settlement desj etransf 1162
C39: Cash USD - settlement td bank, n.a 154
C40: Cash settlement e-transfer 059
C41: Items in transit
C42: A/R billings-subledger | D42: 120101 | E42: 120101 - A/R Billings-Subledger
...

Sheet Personnel>>

Sheet IS | Payroll costs
B1: Project Name
B2: =C7
B3: Source: TBD
B4: WORKING DRAFT
C7: Personnel analysis | Reported
C8: $'000 | D8: Code | E8: Mapping | F8: 44197 | G8: =EOMONTH(F8,1) | H8: =EOMONTH(G8,1) | I8: =EOMONTH(H8,1) | J8: =EOMONTH(I8,1) | K8: =EOMONTH(J8,1) | L8: =EOMONTH(K8,1) | M8: =EOMONTH(L8,1) | N8: =EOMONTH(M8,1) | ... AU8: =EOMONTH(AT8,1) | AV8: FY21 | AW8: FY22 | AX8: FY23 | AY8: TTM Apr-24 | AZ8: TTM Jun-24
C9: Salaries & benefits per Income statement
C10: Salaries - general | D10: 531101 | E10: Salaries
C11: Salaries - ncsc | D11: 531101 | E11: Salaries
C12: Salaries - overtime & on-call | D12: 531102 | E12: Salaries
C13: Vacation pay | D13: 531104 | E13: Salaries
C14: Salary compensation
C15: Bonus - short term | D15: 531204 | E15: Bonus
C16: Bonus - long term incentive- corp | D16: 531209 | E16: Bonus
C17: Bonus compensation
C18: Canada pension plan(cpp)expe | D18: 533203 | E18: Taxes
C19: Canadian employer health tax | D19: 533205 | E19: Taxes
C20: Canadian employment ins (ei) | D20: 533204 | E20: Taxes
C21: Worker's compensation | D21: 533401 | E21: Taxes
C22: Employer taxes
C23: Disability and life insurance | D23: 532104 | E23: Benefits
C24: Cooperative employee css pension | D24: 532303 | E24: Benefits
C25: Medical insurance | D25: 532101 | E25: Benefits
C26: Dental insurance | D26: 532102 | E26: Benefits
C27: Health spending account | D27: 532103 | E27: Benefits
C28: Supplement exec retire plan- exec office | D28: 532304 | E28: Benefits
C29: Employee miscellaneous incentives | D29: 532306 | E29: Benefits
C30: Employee benefits - gas allowances | D30: 532308 | E30: Benefits
C31: Employee - other compensation | D31: 532309 | E31: Benefits
C32: Benefits
C33: Salaries - severance | D33: 531105 | E33: Salaries
C34: Severance & related costs
C35: Other payroll tax | D35: 533501 | E35: Salaries
C36: Canada emergency wage subsidy
C37: Compensation
C38: Summary
C39: Salaries
C40: Benefits
C41: Taxes
C42: Bonus
...

Sheet Headcount census
B1: Project Name
B2: =C8
B3: Source: TBD
B4: WORKING DRAFT
C8: Payroll and headcount analysis
J9: Annualized salary | P9: FTE | V9: Headcount FTE | AH9: =V9 | AT9: =AH9 | BF9: =AT9 | BL9: =BF9
C10: # | D10: Employee ID | E10: Hire Date | F10: Service Date | G10: Term. Date | H10: Birth date | I10: Gender | J10: FY21 | K10: FY22 | L10: FY23 | P10: FY21 | Q10: FY22 | R10: FY23 | BL10: FY21 | BM10: FY22 | BN10: FY23 | BO10: TTM Apr-24 | BP10: TTM Jun-24
C11: [Redacted] | D11: 11086 | I11: M
C12: [Redacted] | D12: 11319 | I12: M
C13: [Redacted] | D13: 11027 | I13: M
C14: [Redacted] | D14: 11253 | I14: M
C15: [Redacted] | D15: 11064 | I15: M
C16: [Redacted] | D16: 11352 | I16: M
C17: [Redacted] | D17: 11231 | I17: F
C18: [Redacted] | D18: 11338 | I18: M
C19: [Redacted] | D19: 11323 | I19: M
C20: [Redacted] | D20: 11351 | I20: F
C21: [Redacted] | D21: 11058 | I21: M
C22: [Redacted] | D22: 11123 | I22: F
... C107: [Redacted] | D107: 11296 | I107: M
C108: [Redacted] | D108: 11381 | I108: F | BR108: >>This employee is terminated in Feb-24 but included in May-24 headcount source.
C109: [Redacted] | D109: 11335 | I109: F
C110: [Redacted] | D110: 11256 | I110: F
C111: [Redacted] | D111: 11160 | I111: M
C112: [Redacted] | D112: 11223 | I112: M
C113: [Redacted] | D113: 11349 | I113: M
C114: [Redacted] | D114: 11235 | I114: M
C115: [Redacted] | D115: 11383 | I115: M
C116: [Redacted] | D116: 11364 | I116: M
C117: [Redacted] | D117: 11369 | I117: M
C118: [Redacted] | D118: 11380 | I118: F
C119: [Redacted] | D119: 11343 | I119: F
C120: [Redacted] | D120: 11255 | I120: F
... C127: [Redacted] | D127: 11372 | I127: F
C128: [Redacted] | D128: 11243 | I128: M | BR128: >>This employee is terminated in Jan-24 but included in May-24 headcount source.
C129: [Redacted] | D129: 11387 | I129: M
C130: [Redacted] | D130: 11377 | I130: M
C131: [Redacted] | D131: 11382 | I131: M
