Workbook
Name Button_429: "LeaseCalc_Lease_Data_List"
Name CellAbove: INDIRECT(ADDRESS(ROW()-1,COLUMN()))
Name CIT: #N/A
Name IQ_CH: 110000
Name IQ_CQ: 5000
Name IQ_CY: 10000
Name IQ_DAILY: 500000
Name IQ_FH: 100000
Name IQ_FQ: 500
Name IQ_FY: 1000
Name IQ_LTM: 2000
Name IQ_MONTH: 15000
Name IQ_NTM: 6000
Name IQ_WEEK: 50000
Name IQ_YTD: 3000
Name TM1REBUILDOPTION: 1

Sheet Stratified BS
B1: Project North
B2: =C7
B3: Source:Everlink Balance Sheet 13 month trend (2021),Everlink Balance Sheet 13 month trend (2022),Everlink Balance Sheet 13 month trend (2023),Everlink Balance Sheet 13 month trend (to April 2024)
B4: WORKING DRAFT
C7: Stratified balance sheet
F8: As at | K8: Stratification as at 30-Apr-24 | O8: Stratification as at 30-Jun-24
C9: $'000 | D9: Code | E9: Concatenate | F9: ='Balance sheet'!AV9 | G9: ='Balance sheet'!AW9 | H9: ='Balance sheet'!AX9 | I9: ='Balance sheet'!AY9 | J9: ='Balance sheet'!AZ9 | K9: NWC | L9: PPE | M9: Net debt | N9: Others | O9: NWC | P9: PPE | Q9: Net cash | R9: Others | T9: Check | U9: Check
C10: Assets | T10: =I10-SUM(K10:N10) | U10: =J10-SUM(O10:R10)
C11: Cash-CAD - CUCA operating | D11: 100210 | E11: 100210 - Cash-CAD - CUCA Operating | F11: ='Balance sheet'!AV11 | G11: ='Balance sheet'!AW11 | H11: ='Balance sheet'!AX11 | I11: ='Balance sheet'!AY11 | J11: ='Balance sheet'!AZ11 | K11: 0 | L11: 0 | M11: =I11 | N11: 0 | O11: 0 | P11: 0 | Q11: =J11 | R11: 0 | T11: =I11-SUM(K11:N11) | U11: =J11-SUM(O11:R11)
C12: Cash -desjardins operating CAD | D12: 100215 | E12: 100215 - CASH -Desjardins Operating CAD | F12: ='Balance sheet'!AV12 | G12: ='Balance sheet'!AW12 | H12: ='Balance sheet'!AX12 | I12: ='Balance sheet'!AY12 | J12: ='Balance sheet'!AZ12 | K12: 0 | L12: 0 | M12: =I12 | N12: 0 | O12: 0 | P12: 0 | Q12: =J12 | R12: 0 | T12: =I12-SUM(K12:N12) | U12: =J12-SUM(O12:R12)
C13: Cash USD - CUCA 079 | D13: 100416 | E13: 100416 - Cash USD - CUCA 079 | F13: ='Balance sheet'!AV13 | G13: ='Balance sheet'!AW13 | H13: ='Balance sheet'!AX13 | I13: ='Balance sheet'!AY13 | J13: ='Balance sheet'!AZ13 | K13: 0 | L13: 0 | M13: =I13 | N13: 0 | O13: 0 | P13: 0 | Q13: =J13 | R13: 0 | T13: =I13-SUM(K13:N13) | U13: =J13-SUM(O13:R13)
C14: Cash USD - BMO harris 137 | D14: 100417 | E14: 100417 - Cash USD - BMO Harris 137 | F14: ='Balance sheet'!AV14 | G14: ='Balance sheet'!AW14 | H14: ='Balance sheet'!AX14 | I14: ='Balance sheet'!AY14 | J14: ='Balance sheet'!AZ14 | K14: 0 | L14: 0 | M14: =I14 | N14: 0 | O14: 0 | P14: 0 | Q14: =J14 | R14: 0 | T14: =I14-SUM(K14:N14) | U14: =J14-SUM(O14:R14)
C15: Cash CAD - CUCA 095 | D15: 100211 | E15: 100211 - Cash CAD - CUCA 095 | F15: ='Balance sheet'!AV15 | G15: ='Balance sheet'!AW15 | H15: ='Balance sheet'!AX15 | I15: ='Balance sheet'!AY15 | J15: ='Balance sheet'!AZ15 | K15: 0 | L15: 0 | M15: =I15 | N15: 0 | O15: 0 | P15: 0 | Q15: =J15 | R15: 0 | T15: =I15-SUM(K15:N15) | U15: =J15-SUM(O15:R15)
C16: Cash and cash equivalents | F16: =SUM(F11:F15) | G16: =SUM(G11:G15) | H16: =SUM(H11:H15) | I16: =SUM(I11:I15) | J16: =SUM(J11:J15) | K16: =SUM(K11:K15) | L16: =SUM(L11:L15) | M16: =SUM(M11:M15) | ... R16: =SUM(R11:R15) | T16: =I16-SUM(K16:N16) | U16: =J16-SUM(O16:R16)
C17: Cash settlement - pos desjardin 147 | D17: 100370 | E17: 100370 - Cash Settlement - POS Desjardin 147 | F17: ='Balance sheet'!AV17 | G17: ='Balance sheet'!AW17 | H17: ='Balance sheet'!AX17 | I17: ='Balance sheet'!AY17 | J17: ='Balance sheet'!AZ17 | K17: =I17 | L17: 0 | M17: 0 | N17: 0 | O17: =J17 | P17: 0 | Q17: 0 | R17: 0 | T17: =I17-SUM(K17:N17) | U17: =J17-SUM(O17:R17)
C18: Cash settlement scd desjardin 139 | D18: 100488 | E18: 100488 - Cash Settlement SCD Desjardin 139 | F18: ='Balance sheet'!AV18 | G18: ='Balance sheet'!AW18 | H18: ='Balance sheet'!AX18 | I18: ='Balance sheet'!AY18 | J18: ='Balance sheet'!AZ18 | K18: =I18 | L18: 0 | M18: 0 | N18: 0 | O18: =J18 | P18: 0 | Q18: 0 | R18: 0 | T18: =I18-SUM(K18:N18) | U18: =J18-SUM(O18:R18)
C19: Icici bank settlement CAD6932- for visa debit | D19: 100350 | E19: 100350 - ICICI Bank Settlement CAD6932- For Visa Debit | F19: ='Balance sheet'!AV19 | G19: ='Balance sheet'!AW19 | H19: ='Balance sheet'!AX19 | I19: ='Balance sheet'!AY19 | J19: ='Balance sheet'!AZ19 | K19: =I19 | L19: 0 | M19: 0 | N19: 0 | O19: =J19 | P19: 0 | Q19: 0 | R19: 0 | T19: =I19-SUM(K19:N19) | U19: =J19-SUM(O19:R19)
C20: Cash settlement e-transfer desj suspense 067 | D20: 100367 | E20: 100367 - Cash Settlement E-Transfer Desj Suspense 067 | F20: ='Balance sheet'!AV20 | G20: ='Balance sheet'!AW20 | H20: ='Balance sheet'!AX20 | I20: ='Balance sheet'!AY20 | J20: ='Balance sheet'!AZ20 | K20: =I20 | L20: 0 | M20: 0 | N20: 0 | O20: =J20 | P20: 0 | Q20: 0 | R20: 0 | T20: =I20-SUM(K20:N20) | U20: =J20-SUM(O20:R20)
C21: Cash settlement CUCA 178 | D21: 100489 | E21: 100489 - Cash Settlement CUCA 178 | F21: ='Balance sheet'!AV21 | G21: ='Balance sheet'!AW21 | H21: ='Balance sheet'!AX21 | I21: ='Balance sheet'!AY21 | J21: ='Balance sheet'!AZ21 | K21: =I21 | L21: 0 | M21: 0 | N21: 0 | O21: =J21 | P21: 0 | Q21: 0 | R21: 0 | T21: =I21-SUM(K21:N21) | U21: =J21-SUM(O21:R21)
C22: Cash settlement - pos 10403- desjardins 1154 | D22: 100373 | E22: 100373 - Cash Settlement - POS 10403- Desjardins 1154 | F22: ='Balance sheet'!AV22 | G22: ='Balance sheet'!AW22 | H22: ='Balance sheet'!AX22 | I22: ='Balance sheet'!AY22 | J22: ='Balance sheet'!AZ22 | K22: =I22 | L22: 0 | M22: 0 | N22: 0 | O22: =J22 | P22: 0 | Q22: 0 | R22: 0 | T22: =I22-SUM(K22:N22) | U22: =J22-SUM(O22:R22)
C23: Cash settlement desj etransf 1162 | D23: 100380 | E23: 100380 - Cash Settlement Desj Etransf 1162 | F23: ='Balance sheet'!AV23 | G23: ='Balance sheet'!AW23 | H23: ='Balance sheet'!AX23 | I23: ='Balance sheet'!AY23 | J23: ='Balance sheet'!AZ23 | K23: =I23 | L23: 0 | M23: 0 | N23: 0 | O23: =J23 | P23: 0 | Q23: 0 | R23: 0 | T23: =I23-SUM(K23:N23) | U23: =J23-SUM(O23:R23)
C24: Cash USD - settlement td bank, n.a 154 | D24: 100418 | E24: 100418 - Cash USD - Settlement TD Bank, N.A 154 | F24: ='Balance sheet'!AV24 | G24: ='Balance sheet'!AW24 | H24: ='Balance sheet'!AX24 | I24: ='Balance sheet'!AY24 | J24: ='Balance sheet'!AZ24 | K24: =I24 | L24: 0 | M24: 0 | N24: 0 | O24: =J24 | P24: 0 | Q24: 0 | R24: 0 | T24: =I24-SUM(K24:N24) | U24: =J24-SUM(O24:R24)
C25: Cash settlement e-transfer desjardins 059 | D25: 100359 | E25: 100359 - Cash Settlement E-Transfer Desjardins 059 | F25: ='Balance sheet'!AV25 | G25: ='Balance sheet'!AW25 | H25: ='Balance sheet'!AX25 | I25: ='Balance sheet'!AY25 | J25: ='Balance sheet'!AZ25 | K25: =I25 | L25: 0 | M25: 0 | N25: 0 | O25: =J25 | P25: 0 | Q25: 0 | R25: 0 | T25: =I25-SUM(K25:N25) | U25: =J25-SUM(O25:R25)
C26: Items in transit | F26: =SUM(F17:F25) | G26: =SUM(G17:G25) | H26: =SUM(H17:H25) | I26: =SUM(I17:I25) | J26: =SUM(J17:J25) | K26: =SUM(K17:K25) | L26: =SUM(L17:L25) | M26: =SUM(M17:M25) | ... R26: =SUM(R17:R25) | T26: =I26-SUM(K26:N26) | U26: =J26-SUM(O26:R26)
C27: A/R billings-subledger | D27: 120101 | E27: 120101 - A/R Billings-Subledger | F27: ='Balance sheet'!AV27 | G27: ='Balance sheet'!AW27 | H27: ='Balance sheet'!AX27 | I27: ='Balance sheet'!AY27 | J27: ='Balance sheet'!AZ27 | K27: =I27 | L27: 0 | M27: 0 | N27: 0 | O27: =J27 | P27: 0 | Q27: 0 | R27: 0 | T27: =I27-SUM(K27:N27) | U27: =J27-SUM(O27:R27)
C28: A/R-trade accrual | D28: 120201 | E28: 120201 - A/R-Trade Accrual | F28: ='Balance sheet'!AV28 | G28: ='Balance sheet'!AW28 | H28: ='Balance sheet'!AX28 | I28: ='Balance sheet'!AY28 | J28: ='Balance sheet'!AZ28 | K28: =I28 | L28: 0 | M28: 0 | N28: 0 | O28: =J28 | P28: 0 | Q28: 0 | R28: 0 | T28: =I28-SUM(K28:N28) | U28: =J28-SUM(O28:R28)
C29: Accrued merchant services fees | D29: 120301 | E29: 120301 - Accrued Merchant Services Fees | F29: ='Balance sheet'!AV29 | G29: ='Balance sheet'!AW29 | H29: ='Balance sheet'!AX29 | I29: ='Balance sheet'!AY29 | J29: ='Balance sheet'!AZ29 | K29: =I29 | L29: 0 | M29: 0 | N29: 0 | O29: =J29 | P29: 0 | Q29: 0 | R29: 0 | T29: =I29-SUM(K29:N29) | U29: =J29-SUM(O29:R29)
C30: Accrued other receivable | D30: 120401 | E30: 120401 - Accrued Other Receivable | F30: ='Balance sheet'!AV30 | G30: ='Balance sheet'!AW30 | H30: ='Balance sheet'!AX30 | I30: ='Balance sheet'!AY30 | J30: ='Balance sheet'!AZ30 | K30: =I30 | L30: 0 | M30: 0 | N30: 0 | O30: =J30 | P30: 0 | Q30: 0 | R30: 0 | T30: =I30-SUM(K30:N30) | U30: =J30-SUM(O30:R30)
C31: Sales tax receivables - HST/GST | D31: 130301 | E31: 130301 - Sales Tax Receivables - HST/GST | F31: ='Balance sheet'!AV31 | G31: ='Balance sheet'!AW31 | H31: ='Balance sheet'!AX31 | I31: ='Balance sheet'!AY31 | J31: ='Balance sheet'!AZ31 | K31: =I31 | L31: 0 | M31: 0 | N31: 0 | O31: =J31 | P31: 0 | Q31: 0 | R31: 0 | T31: =I31-SUM(K31:N31) | U31: =J31-SUM(O31:R31)
C32: Interest receivables | D32: 130101 | E32: 130101 - Interest Receivables | F32: ='Balance sheet'!AV32 | G32: ='Balance sheet'!AW32 | H32: ='Balance sheet'!AX32 | I32: ='Balance sheet'!AY32 | J32: ='Balance sheet'!AZ32 | K32: =I32 | L32: 0 | M32: 0 | N32: 0 | O32: =J32 | P32: 0 | Q32: 0 | R32: 0 | T32: =I32-SUM(K32:N32) | U32: =J32-SUM(O32:R32)
C33: Sales tax receivables - QST | D33: 130300 | E33: 130300 - Sales Tax Receivables - QST | F33: ='Balance sheet'!AV33 | G33: ='Balance sheet'!AW33 | H33: ='Balance sheet'!AX33 | I33: ='Balance sheet'!AY33 | J33: ='Balance sheet'!AZ33 | K33: =I33 | L33: 0 | M33: 0 | N33: 0 | O33: =J33 | P33: 0 | Q33: 0 | R33: 0 | T33: =I33-SUM(K33:N33) | U33: =J33-SUM(O33:R33)
C34: IFRS15 adjustment to accr A/R | D34: 120215 | E34: 120215 - -IFRS15 Adjustment to Accr AR- | F34: ='Balance sheet'!AV34 | G34: ='Balance sheet'!AW34 | H34: ='Balance sheet'!AX34 | I34: ='Balance sheet'!AY34 | J34: ='Balance sheet'!AZ34 | K34: =I34 | L34: 0 | M34: 0 | N34: 0 | O34: =J34 | P34: 0 | Q34: 0 | R34: 0 | T34: =I34-SUM(K34:N34) | U34: =J34-SUM(O34:R34)
C35: Corporate card payments suspense | D35: 143102 | E35: 143102 - Corporate Card Payments Suspense | F35: ='Balance sheet'!AV35 | G35: ='Balance sheet'!AW35 | H35: ='Balance sheet'!AX35 | I35: ='Balance sheet'!AY35 | J35: ='Balance sheet'!AZ35 | K35: =I35 | L35: 0 | M35: 0 | N35: 0 | O35: =J35 | P35: 0 | Q35: 0 | R35: 0 | T35: =I35-SUM(K35:N35) | U35: =J35-SUM(O35:R35)
C36: Allowances for customers A/R | D36: 125101 | E36: 125101 - Allowances for Customers A/R | F36: ='Balance sheet'!AV36 | G36: ='Balance sheet'!AW36 | H36: ='Balance sheet'!AX36 | I36: ='Balance sheet'!AY36 | J36: ='Balance sheet'!AZ36 | K36: =I36 | L36: 0 | M36: 0 | N36: 0 | O36: =J36 | P36: 0 | Q36: 0 | R36: 0 | T36: =I36-SUM(K36:N36) | U36: =J36-SUM(O36:R36)
C37: Accounts receivable and other receivables | F37: =SUM(F27:F36) | G37: =SUM(G27:G36) | H37: =SUM(H27:H36) | I37: =SUM(I27:I36) | J37: =SUM(J27:J36) | K37: =SUM(K27:K36) | L37: =SUM(L27:L36) | M37: =SUM(M27:M36) | ... R37: =SUM(R27:R36) | T37: =I37-SUM(K37:N37) | U37: =J37-SUM(O37:R37)
C38: Inventory - prepaid COGS | D38: 142113 | E38: 142113 - Inventory - Prepaid COGS | F38: ='Balance sheet'!AV38 | G38: ='Balance sheet'!AW38 | H38: ='Balance sheet'!AX38 | I38: ='Balance sheet'!AY38 | J38: ='Balance sheet'!AZ38 | K38: =I38 | L38: 0 | M38: 0 | N38: 0 | O38: =J38 | P38: 0 | Q38: 0 | R38: 0 | T38: =I38-SUM(K38:N38) | U38: =J38-SUM(O38:R38)
C39: Inventory | D39: 142101 | E39: 142101 - Inventory | F39: ='Balance sheet'!AV39 | G39: ='Balance sheet'!AW39 | H39: ='Balance sheet'!AX39 | I39: ='Balance sheet'!AY39 | J39: ='Balance sheet'!AZ39 | K39: =I39 | L39: 0 | M39: 0 | N39: 0 | O39: =J39 | P39: 0 | Q39: 0 | R39: 0 | T39: =I39-SUM(K39:N39) | U39: =J39-SUM(O39:R39)
C40: Inventory - rental units | D40: 142112 | E40: 142112 - Inventory - Rental Units | F40: ='Balance sheet'!AV40 | G40: ='Balance sheet'!AW40 | H40: ='Balance sheet'!AX40 | I40: ='Balance sheet'!AY40 | J40: ='Balance sheet'!AZ40 | K40: =I40 | L40: 0 | M40: 0 | N40: 0 | O40: =J40 | P40: 0 | Q40: 0 | R40: 0 | T40: =I40-SUM(K40:N40) | U40: =J40-SUM(O40:R40)
C41: Inventory | F41: =SUM(F38:F40) | G41: =SUM(G38:G40) | H41: =SUM(H38:H40) | I41: =SUM(I38:I40) | J41: =SUM(J38:J40) | K41: =SUM(K38:K40) | L41: =SUM(L38:L40) | M41: =SUM(M38:M40) | ... R41: =SUM(R38:R40) | T41: =I41-SUM(K41:N41) | U41: =J41-SUM(O41:R41)
C42: Prepaid SW license fees | D42: 141511 | E42: 141511 - Prepaid SW License Fees | F42: ='Balance sheet'!AV42 | G42: ='Balance sheet'!AW42 | H42: ='Balance sheet'!AX42 | I42: ='Balance sheet'!AY42 | J42: ='Balance sheet'!AZ42 | K42: =I42 | L42: 0 | M42: 0 | N42: 0 | O42: =J42 | P42: 0 | Q42: 0 | R42: 0 | T42: =I42-SUM(K42:N42) | U42: =J42-SUM(O42:R42)
...
