Workbook
Name Button_429: "LeaseCalc_Lease_Data_List"
Name CellAbove: INDIRECT(ADDRESS(ROW()-1,COLUMN()))
Name CIT: #N/A
Name IQ_CH: 110000
Name IQ_CQ: 5000
Name IQ_CY: 10000
Name IQ_DAILY: 500000
Name IQ_FH: 100000
Name IQ_FQ: 500
Name IQ_FY: 1000
Name IQ_LTM: 2000
Name IQ_MONTH: 15000
Name IQ_NTM: 6000
Name IQ_WEEK: 50000
Name IQ_YTD: 3000
Name TM1REBUILDOPTION: 1

Sheet Adjusted IS
B1: Project North
B2: =C7
B3: Source:Everlink P&L IFRS1516 All Months Statements
B4: WORKING DRAFT
C7: Adjusted income statement
F8: Reported | R8: =F8 | AD8: =R8 | AP8: =AD8 | AV8: =AP8 | BB8: Definitional adjustments | BN8: =BB8 | BZ8: =BN8 | CL8: =BZ8 | CR8: =CL8 | CX8: EBITDA | DJ8: =CX8 | DV8: =DJ8 | EH8: =DV8 | EN8: =EH8 | ET8: Due diligence adjustments | FF8: =ET8 | FR8: =FF8 | GD8: =FR8 | GJ8: =GD8 | GP8: Diligence adjusted EBITDA | HB8: =GP8 | HN8: =HB8 | HZ8: =HN8 | IF8: =HZ8 | IL8: Pro forma adjustments | IX8: =IL8 | JJ8: =IX8 | JV8: =JJ8 | KB8: =JV8 | KH8: Pro forma adjusted EBITDA | KT8: =KH8 | LF8: =KT8 | LR8: =LF8 | LX8: =LR8 | MD8: As a % of Revenue | MP8: As a % of Revenue | NB8: As a % of Revenue | NN8: As a % of Revenue | NT8: As a % of Revenue | NZ8: Change | OE8: Adjusted IS Mapping
C9: $'000 | D9: Code | E9: Concatenate | F9: 44197 | G9: =EOMONTH(F9,1) | H9: =EOMONTH(G9,1) | I9: =EOMONTH(H9,1) | J9: =EOMONTH(I9,1) | K9: =EOMONTH(J9,1) | L9: =EOMONTH(K9,1) | M9: =EOMONTH(L9,1) | N9: =EOMONTH(M9,1) | ... AU9: =EOMONTH(AT9,1) | AV9: FY21 | AW9: FY22 | AX9: FY23 | AY9: TTM Apr-24 | AZ9: TTM Jun-24 | BB9: 44197 | BC9: =EOMONTH(BB9,1) | BD9: =EOMONTH(BC9,1) | BE9: =EOMONTH(BD9,1) | BF9: =EOMONTH(BE9,1) | BG9: =EOMONTH(BF9,1) | BH9: =EOMONTH(BG9,1) | BI9: =EOMONTH(BH9,1) | BJ9: =EOMONTH(BI9,1) | ... CQ9: =EOMONTH(CP9,1) | CR9: FY21 | CS9: FY22 | CT9: FY23 | CU9: TTM Apr-24 | CV9: TTM Jun-24 | CX9: 44197 | CY9: =EOMONTH(CX9,1) | CZ9: =EOMONTH(CY9,1) | DA9: =EOMONTH(CZ9,1) | DB9: =EOMONTH(DA9,1) | DC9: =EOMONTH(DB9,1) | DD9: =EOMONTH(DC9,1) | DE9: =EOMONTH(DD9,1) | DF9: =EOMONTH(DE9,1) | ... EM9: =EOMONTH(EL9,1) | EN9: FY21 | EO9: FY22 | EP9: FY23 | EQ9: TTM Apr-24 | ER9: TTM Jun-24 | ET9: 44197 | EU9: =EOMONTH(ET9,1) | EV9: =EOMONTH(EU9,1) | EW9: =EOMONTH(EV9,1) | EX9: =EOMONTH(EW9,1) | EY9: =EOMONTH(EX9,1) | EZ9: =EOMONTH(EY9,1) | FA9: =EOMONTH(EZ9,1) | FB9: =EOMONTH(FA9,1) | ... GI9: =EOMONTH(GH9,1) | GJ9: FY21 | GK9: FY22 | GL9: FY23 | GM9: TTM Apr-24 | GN9: TTM Jun-24 | GP9: 44197 | GQ9: =EOMONTH(GP9,1) | GR9: =EOMONTH(GQ9,1) | GS9: =EOMONTH(GR9,1) | GT9: =EOMONTH(GS9,1) | GU9: =EOMONTH(GT9,1) | GV9: =EOMONTH(GU9,1) | GW9: =EOMONTH(GV9,1) | GX9: =EOMONTH(GW9,1) | ... IE9: =EOMONTH(ID9,1) | IF9: FY21 | IG9: FY22 | IH9: FY23 | II9: TTM Apr-24 | IJ9: TTM Jun-24 | IL9: 44197 | IM9: =EOMONTH(IL9,1) | IN9: =EOMONTH(IM9,1) | IO9: =EOMONTH(IN9,1) | IP9: =EOMONTH(IO9,1) | IQ9: =EOMONTH(IP9,1) | IR9: =EOMONTH(IQ9,1) | IS9: =EOMONTH(IR9,1) | IT9: =EOMONTH(IS9,1) | ... KA9: =EOMONTH(JZ9,1) | KB9: FY21 | KC9: FY22 | KD9: FY23 | KE9: TTM Apr-24 | KF9: TTM Jun-24 | KH9: 44197 | KI9: =EOMONTH(KH9,1) | KJ9: =EOMONTH(KI9,1) | KK9: =EOMONTH(KJ9,1) | KL9: =EOMONTH(KK9,1) | KM9: =EOMONTH(KL9,1) | KN9: =EOMONTH(KM9,1) | KO9: =EOMONTH(KN9,1) | KP9: =EOMONTH(KO9,1) | ... LW9: =EOMONTH(LV9,1) | LX9: FY21 | LY9: FY22 | LZ9: FY23 | MA9: TTM Apr-24 | MB9: TTM Jun-24 | MD9: 44197 | ME9: =EOMONTH(MD9,1) | MF9: =EOMONTH(ME9,1) | MG9: =EOMONTH(MF9,1) | MH9: =EOMONTH(MG9,1) | MI9: =EOMONTH(MH9,1) | MJ9: =EOMONTH(MI9,1) | MK9: =EOMONTH(MJ9,1) | ML9: =EOMONTH(MK9,1) | ... NS9: =EOMONTH(NR9,1) | NT9: FY21 | NU9: FY22 | NV9: FY23 | NW9: TTM Apr-24 | NX9: TTM Jun-24 | NZ9: FY22 vs FY21 | OA9: FY23 vs FY22 | OB9: TTM Apr-24 vs FY23 | OC9: TTM Jun-24 vs FY23 | OE9: FY22 vs FY21 | OF9: FY23 vs FY22 | OG9: TTM Apr-24 vs FY23
C10: Mobile tsp transactions pos- | D10: 411110 | E10: =CONCATENATE(D10," - ",C10) | F10: ='Income statement'!F10 | G10: ='Income statement'!G10 | H10: ='Income statement'!H10 | I10: ='Income statement'!I10 | J10: ='Income statement'!J10 | K10: ='Income statement'!K10 | L10: ='Income statement'!L10 | M10: ='Income statement'!M10 | ... AU10: ='Income statement'!AU10 | AV10: =SUM(F10:Q10) | AW10: =SUM(R10:AC10) | AX10: =SUM(AD10:AO10) | AY10: =SUM(AH10:AS10) | AZ10: =SUM(AJ10:AU10) | BB10: =SUMIFS('QofE Def adjustments'!F:F,'QofE Def adjustments'!$E:$E,'Adjusted IS'!$E10) | BC10: =SUMIFS('QofE Def adjustments'!G:G,'QofE Def adjustments'!$E:$E,'Adjusted IS'!$E10) | BD10: =SUMIFS('QofE Def adjustments'!H:H,'QofE Def adjustments'!$E:$E,'Adjusted IS'!$E10) | BE10: =SUMIFS('QofE Def adjustments'!I:I,'QofE Def adjustments'!$E:$E,'Adjusted IS'!$E10) | BF10: =SUMIFS('QofE Def adjustments'!J:J,'QofE Def adjustments'!$E:$E,'Adjusted IS'!$E10) | BG10: =SUMIFS('QofE Def adjustments'!K:K,'QofE Def adjustments'!$E:$E,'Adjusted IS'!$E10) | BH10: =SUMIFS('QofE Def adjustments'!L:L,'QofE Def adjustments'!$E:$E,'Adjusted IS'!$E10) | BI10: =SUMIFS('QofE Def adjustments'!M:M,'QofE Def adjustments'!$E:$E,'Adjusted IS'!$E10) | BJ10: =SUMIFS('QofE Def adjustments'!N:N,'QofE Def adjustments'!$E:$E,'Adjusted IS'!$E10) | BK10: =SUMIFS('QofE Def adjustments'!O:O,'QofE Def adjustments'!$E:$E,'Adjusted IS'!$E10) | BL10: =SUMIFS('QofE Def adjustments'!P:P,'QofE Def adjustments'!$E:$E,'Adjusted IS'!$E10) | BM10: =SUMIFS('QofE Def adjustments'!Q:Q,'QofE Def adjustments'!$E:$E,'Adjusted IS'!$E10) | BN10: =SUMIFS('QofE Def adjustments'!R:R,'QofE Def adjustments'!$E:$E,'Adjusted IS'!$E10) | BO10: =SUMIFS('QofE Def adjustments'!S:S,'QofE Def adjustments'!$E:$E,'Adjusted IS'!$E10) | BP10: =SUMIFS('QofE Def adjustments'!T:T,'QofE Def adjustments'!$E:$E,'Adjusted IS'!$E10) | BQ10: =SUMIFS('QofE Def adjustments'!U:U,'QofE Def adjustments'!$E:$E,'Adjusted IS'!$E10) | BR10: =SUMIFS('QofE Def adjustments'!V:V,'QofE Def adjustments'!$E:$E,'Adjusted IS'!$E10) | BS10: =SUMIFS('QofE Def adjustments'!W:W,'QofE Def adjustments'!$E:$E,'Adjusted IS'!$E10) | BT10: =SUMIFS('QofE Def adjustments'!X:X,'QofE Def adjustments'!$E:$E,'Adjusted IS'!$E10) | BU10: =SUMIFS('QofE Def adjustments'!Y:Y,'QofE Def adjustments'!$E:$E,'Adjusted IS'!$E10) | BV10: =SUMIFS('QofE Def adjustments'!Z:Z,'QofE Def adjustments'!$E:$E,'Adjusted IS'!$E10) | BW10: =SUMIFS('QofE Def adjustments'!AA:AA,'QofE Def adjustments'!$E:$E,'Adjusted IS'!$E10) | BX10: =SUMIFS('QofE Def adjustments'!AB:AB,'QofE Def adjustments'!$E:$E,'Adjusted IS'!$E10) | BY10: =SUMIFS('QofE Def adjustments'!AC:AC,'QofE Def adjustments'!$E:$E,'Adjusted IS'!$E10) | BZ10: =SUMIFS('QofE Def adjustments'!AD:AD,'QofE Def adjustments'!$E:$E,'Adjusted IS'!$E10) | CA10: =SUMIFS('QofE Def adjustments'!AE:AE,'QofE Def adjustments'!$E:$E,'Adjusted IS'!$E10) | CB10: =SUMIFS('QofE Def adjustments'!AF:AF,'QofE Def adjustments'!$E:$E,'Adjusted IS'!$E10) | CC10: =SUMIFS('QofE Def adjustments'!AG:AG,'QofE Def adjustments'!$E:$E,'Adjusted IS'!$E10) | CD10: =SUMIFS('QofE Def adjustments'!AH:AH,'QofE Def adjustments'!$E:$E,'Adjusted IS'!$E10) | CE10: =SUMIFS('QofE Def adjustments'!AI:AI,'QofE Def adjustments'!$E:$E,'Adjusted IS'!$E10) | CF10: =SUMIFS('QofE Def adjustments'!AJ:AJ,'QofE Def adjustments'!$E:$E,'Adjusted IS'!$E10) | CG10: =SUMIFS('QofE Def adjustments'!AK:AK,'QofE Def adjustments'!$E:$E,'Adjusted IS'!$E10) | CH10: =SUMIFS('QofE Def adjustments'!AL:AL,'QofE Def adjustments'!$E:$E,'Adjusted IS'!$E10) | CI10: =SUMIFS('QofE Def adjustments'!AM:AM,'QofE Def adjustments'!$E:$E,'Adjusted IS'!$E10) | CJ10: =SUMIFS('QofE Def adjustments'!AN:AN,'QofE Def adjustments'!$E:$E,'Adjusted IS'!$E10) | CK10: =SUMIFS('QofE Def adjustments'!AO:AO,'QofE Def adjustments'!$E:$E,'Adjusted IS'!$E10) | CL10: =SUMIFS('QofE Def adjustments'!AP:AP,'QofE Def adjustments'!$E:$E,'Adjusted IS'!$E10) | CM10: =SUMIFS('QofE Def adjustments'!AQ:AQ,'QofE Def adjustments'!$E:$E,'Adjusted IS'!$E10) | CN10: =SUMIFS('QofE Def adjustments'!AR:AR,'QofE Def adjustments'!$E:$E,'Adjusted IS'!$E10) | CO10: =SUMIFS('QofE Def adjustments'!AS:AS,'QofE Def adjustments'!$E:$E,'Adjusted IS'!$E10) | CP10: =SUMIFS('QofE Def adjustments'!AT:AT,'QofE Def adjustments'!$E:$E,'Adjusted IS'!$E10) | CQ10: =SUMIFS('QofE Def adjustments'!AU:AU,'QofE Def adjustments'!$E:$E,'Adjusted IS'!$E10) | CR10: =SUM(BB10:BM10) | CS10: =SUM(BN10:BY10) | CT10: =SUM(BZ10:CK10) | CU10: =SUM(CD10:CO10) | CV10: =SUM(CF10:CQ10) | CX10: =SUM(BB10,F10) | CY10: =SUM(BC10,G10) | CZ10: =SUM(BD10,H10) | DA10: =SUM(BE10,I10) | DB10: =SUM(BF10,J10) | DC10: =SUM(BG10,K10) | DD10: =SUM(BH10,L10) | DE10: =SUM(BI10,M10) | ... EM10: =SUM(CQ10,AU10) | EN10: =SUM(CX10:DI10) | EO10: =SUM(DJ10:DU10) | EP10: =SUM(DV10:EG10) | EQ10: =SUM(DZ10:EK10) | ER10: =SUM(EB10:EM10) | ET10: =SUMIFS('QofE DD adjustments'!F:F,'QofE DD adjustments'!$E:$E,'Adjusted IS'!$E10) | EU10: =SUMIFS('QofE DD adjustments'!G:G,'QofE DD adjustments'!$E:$E,'Adjusted IS'!$E10) | EV10: =SUMIFS('QofE DD adjustments'!H:H,'QofE DD adjustments'!$E:$E,'Adjusted IS'!$E10) | EW10: =SUMIFS('QofE DD adjustments'!I:I,'QofE DD adjustments'!$E:$E,'Adjusted IS'!$E10) | EX10: =SUMIFS('QofE DD adjustments'!J:J,'QofE DD adjustments'!$E:$E,'Adjusted IS'!$E10) | EY10: =SUMIFS('QofE DD adjustments'!K:K,'QofE DD adjustments'!$E:$E,'Adjusted IS'!$E10) | EZ10: =SUMIFS('QofE DD adjustments'!L:L,'QofE DD adjustments'!$E:$E,'Adjusted IS'!$E10) | FA10: =SUMIFS('QofE DD adjustments'!M:M,'QofE DD adjustments'!$E:$E,'Adjusted IS'!$E10) | FB10: =SUMIFS('QofE DD adjustments'!N:N,'QofE DD adjustments'!$E:$E,'Adjusted IS'!$E10) | FC10: =SUMIFS('QofE DD adjustments'!O:O,'QofE DD adjustments'!$E:$E,'Adjusted IS'!$E10) | FD10: =SUMIFS('QofE DD adjustments'!P:P,'QofE DD adjustments'!$E:$E,'Adjusted IS'!$E10) | FE10: =SUMIFS('QofE DD adjustments'!Q:Q,'QofE DD adjustments'!$E:$E,'Adjusted IS'!$E10) | FF10: =SUMIFS('QofE DD adjustments'!R:R,'QofE DD adjustments'!$E:$E,'Adjusted IS'!$E10) | FG10: =SUMIFS('QofE DD adjustments'!S:S,'QofE DD adjustments'!$E:$E,'Adjusted IS'!$E10) | FH10: =SUMIFS('QofE DD adjustments'!T:T,'QofE DD adjustments'!$E:$E,'Adjusted IS'!$E10) | FI10: =SUMIFS('QofE DD adjustments'!U:U,'QofE DD adjustments'!$E:$E,'Adjusted IS'!$E10) | FJ10: =SUMIFS('QofE DD adjustments'!V:V,'QofE DD adjustments'!$E:$E,'Adjusted IS'!$E10) | FK10: =SUMIFS('QofE DD adjustments'!W:W,'QofE DD adjustments'!$E:$E,'Adjusted IS'!$E10) | FL10: =SUMIFS('QofE DD adjustments'!X:X,'QofE DD adjustments'!$E:$E,'Adjusted IS'!$E10) | FM10: =SUMIFS('QofE DD adjustments'!Y:Y,'QofE DD adjustments'!$E:$E,'Adjusted IS'!$E10) | FN10: =SUMIFS('QofE DD adjustments'!Z:Z,'QofE DD adjustments'!$E:$E,'Adjusted IS'!$E10) | FO10: =SUMIFS('QofE DD adjustments'!AA:AA,'QofE DD adjustments'!$E:$E,'Adjusted IS'!$E10) | FP10: =SUMIFS('QofE DD adjustments'!AB:AB,'QofE DD adjustments'!$E:$E,'Adjusted IS'!$E10) | FQ10: =SUMIFS('QofE DD adjustments'!AC:AC,'QofE DD adjustments'!$E:$E,'Adjusted IS'!$E10) | FR10: =SUMIFS('QofE DD adjustments'!AD:AD,'QofE DD adjustments'!$E:$E,'Adjusted IS'!$E10) | FS10: =SUMIFS('QofE DD adjustments'!AE:AE,'QofE DD adjustments'!$E:$E,'Adjusted IS'!$E10) | FT10: =SUMIFS('QofE DD adjustments'!AF:AF,'QofE DD adjustments'!$E:$E,'Adjusted IS'!$E10) | FU10: =SUMIFS('QofE DD adjustments'!AG:AG,'QofE DD adjustments'!$E:$E,'Adjusted IS'!$E10) | FV10: =SUMIFS('QofE DD adjustments'!AH:AH,'QofE DD adjustments'!$E:$E,'Adjusted IS'!$E10) | FW10: =SUMIFS('QofE DD adjustments'!AI:AI,'QofE DD adjustments'!$E:$E,'Adjusted IS'!$E10) | FX10: =SUMIFS('QofE DD adjustments'!AJ:AJ,'QofE DD adjustments'!$E:$E,'Adjusted IS'!$E10) | FY10: =SUMIFS('QofE DD adjustments'!AK:AK,'QofE DD adjustments'!$E:$E,'Adjusted IS'!$E10) | FZ10: =SUMIFS('QofE DD adjustments'!AL:AL,'QofE DD adjustments'!$E:$E,'Adjusted IS'!$E10) | GA10: =SUMIFS('QofE DD adjustments'!AM:AM,'QofE DD adjustments'!$E:$E,'Adjusted IS'!$E10) | GB10: =SUMIFS('QofE DD adjustments'!AN:AN,'QofE DD adjustments'!$E:$E,'Adjusted IS'!$E10) | GC10: =SUMIFS('QofE DD adjustments'!AO:AO,'QofE DD adjustments'!$E:$E,'Adjusted IS'!$E10) | GD10: =SUMIFS('QofE DD adjustments'!AP:AP,'QofE DD adjustments'!$E:$E,'Adjusted IS'!$E10) | GE10: =SUMIFS('QofE DD adjustments'!AQ:AQ,'QofE DD adjustments'!$E:$E,'Adjusted IS'!$E10) | GF10: =SUMIFS('QofE DD adjustments'!AR:AR,'QofE DD adjustments'!$E:$E,'Adjusted IS'!$E10) | GG10: =SUMIFS('QofE DD adjustments'!AS:AS,'QofE DD adjustments'!$E:$E,'Adjusted IS'!$E10) | GH10: =SUMIFS('QofE DD adjustments'!AT:AT,'QofE DD adjustments'!$E:$E,'Adjusted IS'!$E10) | GI10: =SUMIFS('QofE DD adjustments'!AU:AU,'QofE DD adjustments'!$E:$E,'Adjusted IS'!$E10) | GJ10: =SUM(ET10:FE10) | GK10: =SUM(FF10:FQ10) | GL10: =SUM(FR10:GC10) | GM10: =SUM(FV10:GG10) | GN10: =SUM(FX10:GI10) | GP10: =SUM(ET10,CX10) | GQ10: =SUM(EU10,CY10) | GR10: =SUM(EV10,CZ10) | GS10: =SUM(EW10,DA10) | GT10: =SUM(EX10,DB10) | GU10: =SUM(EY10,DC10) | GV10: =SUM(EZ10,DD10) | GW10: =SUM(FA10,DE10) | ... IE10: =SUM(GI10,EM10) | IF10: =SUM(GP10:HA10) | IG10: =SUM(HB10:HM10) | IH10: =SUM(HN10:HY10) | II10: =SUM(HR10:IC10) | IJ10: =SUM(HT10:IE10) | IL10: =SUMIFS('QofE PF adjustments'!F:F,'QofE PF adjustments'!$E:$E,'Adjusted IS'!$E10) | IM10: =SUMIFS('QofE PF adjustments'!G:G,'QofE PF adjustments'!$E:$E,'Adjusted IS'!$E10) | IN10: =SUMIFS('QofE PF adjustments'!H:H,'QofE PF adjustments'!$E:$E,'Adjusted IS'!$E10) | IO10: =SUMIFS('QofE PF adjustments'!I:I,'QofE PF adjustments'!$E:$E,'Adjusted IS'!$E10) | IP10: =SUMIFS('QofE PF adjustments'!J:J,'QofE PF adjustments'!$E:$E,'Adjusted IS'!$E10) | IQ10: =SUMIFS('QofE PF adjustments'!K:K,'QofE PF adjustments'!$E:$E,'Adjusted IS'!$E10) | IR10: =SUMIFS('QofE PF adjustments'!L:L,'QofE PF adjustments'!$E:$E,'Adjusted IS'!$E10) | IS10: =SUMIFS('QofE PF adjustments'!M:M,'QofE PF adjustments'!$E:$E,'Adjusted IS'!$E10) | IT10: =SUMIFS('QofE PF adjustments'!N:N,'QofE PF adjustments'!$E:$E,'Adjusted IS'!$E10) | IU10: =SUMIFS('QofE PF adjustments'!O:O,'QofE PF adjustments'!$E:$E,'Adjusted IS'!$E10) | IV10: =SUMIFS('QofE PF adjustments'!P:P,'QofE PF adjustments'!$E:$E,'Adjusted IS'!$E10) | IW10: =SUMIFS('QofE PF adjustments'!Q:Q,'QofE PF adjustments'!$E:$E,'Adjusted IS'!$E10) | IX10: =SUMIFS('QofE PF adjustments'!R:R,'QofE PF adjustments'!$E:$E,'Adjusted IS'!$E10) | IY10: =SUMIFS('QofE PF adjustments'!S:S,'QofE PF adjustments'!$E:$E,'Adjusted IS'!$E10) | IZ10: =SUMIFS('QofE PF adjustments'!T:T,'QofE PF adjustments'!$E:$E,'Adjusted IS'!$E10) | JA10: =SUMIFS('QofE PF adjustments'!U:U,'QofE PF adjustments'!$E:$E,'Adjusted IS'!$E10) | JB10: =SUMIFS('QofE PF adjustments'!V:V,'QofE PF adjustments'!$E:$E,'Adjusted IS'!$E10) | JC10: =SUMIFS('QofE PF adjustments'!W:W,'QofE PF adjustments'!$E:$E,'Adjusted IS'!$E10) | JD10: =SUMIFS('QofE PF adjustments'!X:X,'QofE PF adjustments'!$E:$E,'Adjusted IS'!$E10) | JE10: =SUMIFS('QofE PF adjustments'!Y:Y,'QofE PF adjustments'!$E:$E,'Adjusted IS'!$E10) | JF10: =SUMIFS('QofE PF adjustments'!Z:Z,'QofE PF adjustments'!$E:$E,'Adjusted IS'!$E10) | JG10: =SUMIFS('QofE PF adjustments'!AA:AA,'QofE PF adjustments'!$E:$E,'Adjusted IS'!$E10) | JH10: =SUMIFS('QofE PF adjustments'!AB:AB,'QofE PF adjustments'!$E:$E,'Adjusted IS'!$E10) | JI10: =SUMIFS('QofE PF adjustments'!AC:AC,'QofE PF adjustments'!$E:$E,'Adjusted IS'!$E10) | JJ10: =SUMIFS('QofE PF adjustments'!AD:AD,'QofE PF adjustments'!$E:$E,'Adjusted IS'!$E10) | JK10: =SUMIFS('QofE PF adjustments'!AE:AE,'QofE PF adjustments'!$E:$E,'Adjusted IS'!$E10) | JL10: =SUMIFS('QofE PF adjustments'!AF:AF,'QofE PF adjustments'!$E:$E,'Adjusted IS'!$E10) | JM10: =SUMIFS('QofE PF adjustments'!AG:AG,'QofE PF adjustments'!$E:$E,'Adjusted IS'!$E10) | JN10: =SUMIFS('QofE PF adjustments'!AH:AH,'QofE PF adjustments'!$E:$E,'Adjusted IS'!$E10) | JO10: =SUMIFS('QofE PF adjustments'!AI:AI,'QofE PF adjustments'!$E:$E,'Adjusted IS'!$E10) | JP10: =SUMIFS('QofE PF adjustments'!AJ:AJ,'QofE PF adjustments'!$E:$E,'Adjusted IS'!$E10) | JQ10: =SUMIFS('QofE PF adjustments'!AK:AK,'QofE PF adjustments'!$E:$E,'Adjusted IS'!$E10) | JR10: =SUMIFS('QofE PF adjustments'!AL:AL,'QofE PF adjustments'!$E:$E,'Adjusted IS'!$E10) | JS10: =SUMIFS('QofE PF adjustments'!AM:AM,'QofE PF adjustments'!$E:$E,'Adjusted IS'!$E10) | JT10: =SUMIFS('QofE PF adjustments'!AN:AN,'QofE PF adjustments'!$E:$E,'Adjusted IS'!$E10) | JU10: =SUMIFS('QofE PF adjustments'!AO:AO,'QofE PF adjustments'!$E:$E,'Adjusted IS'!$E10) | JV10: =SUMIFS('QofE PF adjustments'!AP:AP,'QofE PF adjustments'!$E:$E,'Adjusted IS'!$E10) | JW10: =SUMIFS('QofE PF adjustments'!AQ:AQ,'QofE PF adjustments'!$E:$E,'Adjusted IS'!$E10) | JX10: =SUMIFS('QofE PF adjustments'!AR:AR,'QofE PF adjustments'!$E:$E,'Adjusted IS'!$E10) | JY10: =SUMIFS('QofE PF adjustments'!AS:AS,'QofE PF adjustments'!$E:$E,'Adjusted IS'!$E10) | JZ10: =SUMIFS('QofE PF adjustments'!AT:AT,'QofE PF adjustments'!$E:$E,'Adjusted IS'!$E10) | KA10: =SUMIFS('QofE PF adjustments'!AU:AU,'QofE PF adjustments'!$E:$E,'Adjusted IS'!$E10) | KB10: =SUM(IL10:IW10) | KC10: =SUM(IX10:JI10) | KD10: =SUM(JJ10:JU10) | KE10: =SUM(JN10:JY10) | KF10: =SUM(JP10:KA10) | KH10: =SUM(IL10,GP10) | KI10: =SUM(IM10,GQ10) | KJ10: =SUM(IN10,GR10) | KK10: =SUM(IO10,GS10) | KL10: =SUM(IP10,GT10) | KM10: =SUM(IQ10,GU10) | KN10: =SUM(IR10,GV10) | KO10: =SUM(IS10,GW10) | ... LW10: =SUM(KA10,IE10) | LX10: =SUM(KH10:KS10) | LY10: =SUM(KT10:LE10) | LZ10: =SUM(LF10:LQ10) | MA10: =SUM(LJ10:LU10) | MB10: =SUM(LL10:LW10) | MD10: =IFERROR(KH10/KH$117,0) | ME10: =IFERROR(KI10/KI$117,0) | MF10: =IFERROR(KJ10/KJ$117,0) | MG10: =IFERROR(KK10/KK$117,0) | MH10: =IFERROR(KL10/KL$117,0) | MI10: =IFERROR(KM10/KM$117,0) | MJ10: =IFERROR(KN10/KN$117,0) | MK10: =IFERROR(KO10/KO$117,0) | ... NX10: =IFERROR(MB10/MB$117,0) | NZ10: =LY10-LX10 | OA10: =LZ10-LY10 | OB10: =MA10-LZ10 | OC10: =MB10-LZ10 | OE10: Processing services revenue | OF10: Processing services revenue | OG10: Processing services revenue
C11: Png transactions revenue - pos | D11: 411101 | E11: =CONCATENATE(D11," - ",C11) | F11: ='Income statement'!F11 | G11: ='Income statement'!G11 | H11: ='Income statement'!H11 | I11: ='Income statement'!I11 | J11: ='Income statement'!J11 | K11: ='Income statement'!K11 | L11: ='Income statement'!L11 | M11: ='Income statement'!M11 | ... AU11: ='Income statement'!AU11 | AV11: =SUM(F11:Q11) | AW11: =SUM(R11:AC11) | AX11: =SUM(AD11:AO11) | AY11: =SUM(AH11:AS11) | AZ11: =SUM(AJ11:AU11) | BB11: =SUMIFS('QofE Def adjustments'!F:F,'QofE Def adjustments'!$E:$E,'Adjusted IS'!$E11) | BC11: =SUMIFS('QofE Def adjustments'!G:G,'QofE Def adjustments'!$E:$E,'Adjusted IS'!$E11) | BD11: =SUMIFS('QofE Def adjustments'!H:H,'QofE Def adjustments'!$E:$E,'Adjusted IS'!$E11) | BE11: =SUMIFS('QofE Def adjustments'!I:I,'QofE Def adjustments'!$E:$E,'Adjusted IS'!$E11) | BF11: =SUMIFS('QofE Def adjustments'!J:J,'QofE Def adjustments'!$E:$E,'Adjusted IS'!$E11) | BG11: =SUMIFS('QofE Def adjustments'!K:K,'QofE Def adjustments'!$E:$E,'Adjusted IS'!$E11) | BH11: =SUMIFS('QofE Def adjustments'!L:L,'QofE Def adjustments'!$E:$E,'Adjusted IS'!$E11) | BI11: =SUMIFS('QofE Def adjustments'!M:M,'QofE Def adjustments'!$E:$E,'Adjusted IS'!$E11) | BJ11: =SUMIFS('QofE Def adjustments'!N:N,'QofE Def adjustments'!$E:$E,'Adjusted IS'!$E11) | BK11: =SUMIFS('QofE Def adjustments'!O:O,'QofE Def adjustments'!$E:$E,'Adjusted IS'!$E11) | BL11: =SUMIFS('QofE Def adjustments'!P:P,'QofE Def adjustments'!$E:$E,'Adjusted IS'!$E11) | BM11: =SUMIFS('QofE Def adjustments'!Q:Q,'QofE Def adjustments'!$E:$E,'Adjusted IS'!$E11) | BN11: =SUMIFS('QofE Def adjustments'!R:R,'QofE Def adjustments'!$E:$E,'Adjusted IS'!$E11) | BO11: =SUMIFS('QofE Def adjustments'!S:S,'QofE Def adjustments'!$E:$E,'Adjusted IS'!$E11) | BP11: =SUMIFS('QofE Def adjustments'!T:T,'QofE Def adjustments'!$E:$E,'Adjusted IS'!$E11) | BQ11: =SUMIFS('QofE Def adjustments'!U:U,'QofE Def adjustments'!$E:$E,'Adjusted IS'!$E11) | BR11: =SUMIFS('QofE Def adjustments'!V:V,'QofE Def adjustments'!$E:$E,'Adjusted IS'!$E11) | BS11: =SUMIFS('QofE Def adjustments'!W:W,'QofE Def adjustments'!$E:$E,'Adjusted IS'!$E11) | BT11: =SUMIFS('QofE Def adjustments'!X:X,'QofE Def adjustments'!$E:$E,'Adjusted IS'!$E11) | BU11: =SUMIFS('QofE Def adjustments'!Y:Y,'QofE Def adjustments'!$E:$E,'Adjusted IS'!$E11) | BV11: =SUMIFS('QofE Def adjustments'!Z:Z,'QofE Def adjustments'!$E:$E,'Adjusted IS'!$E11) | BW11: =SUMIFS('QofE Def adjustments'!AA:AA,'QofE Def adjustments'!$E:$E,'Adjusted IS'!$E11) | BX11: =SUMIFS('QofE Def adjustments'!AB:AB,'QofE Def adjustments'!$E:$E,'Adjusted IS'!$E11) | BY11: =SUMIFS('QofE Def adjustments'!AC:AC,'QofE Def adjustments'!$E:$E,'Adjusted IS'!$E11) | BZ11: =SUMIFS('QofE Def adjustments'!AD:AD,'QofE Def adjustments'!$E:$E,'Adjusted IS'!$E11) | CA11: =SUMIFS('QofE Def adjustments'!AE:AE,'QofE Def adjustments'!$E:$E,'Adjusted IS'!$E11) | CB11: =SUMIFS('QofE Def adjustments'!AF:AF,'QofE Def adjustments'!$E:$E,'Adjusted IS'!$E11) | CC11: =SUMIFS('QofE Def adjustments'!AG:AG,'QofE Def adjustments'!$E:$E,'Adjusted IS'!$E11) | CD11: =SUMIFS('QofE Def adjustments'!AH:AH,'QofE Def adjustments'!$E:$E,'Adjusted IS'!$E11) | CE11: =SUMIFS('QofE Def adjustments'!AI:AI,'QofE Def adjustments'!$E:$E,'Adjusted IS'!$E11) | CF11: =SUMIFS('QofE Def adjustments'!AJ:AJ,'QofE Def adjustments'!$E:$E,'Adjusted IS'!$E11) | CG11: =SUMIFS('QofE Def adjustments'!AK:AK,'QofE Def adjustments'!$E:$E,'Adjusted IS'!$E11) | CH11: =SUMIFS('QofE Def adjustments'!AL:AL,'QofE Def adjustments'!$E:$E,'Adjusted IS'!$E11) | CI11: =SUMIFS('QofE Def adjustments'!AM:AM,'QofE Def adjustments'!$E:$E,'Adjusted IS'!$E11) | CJ11: =SUMIFS('QofE Def adjustments'!AN:AN,'QofE Def adjustments'!$E:$E,'Adjusted IS'!$E11) | CK11: =SUMIFS('QofE Def adjustments'!AO:AO,'QofE Def adjustments'!$E:$E,'Adjusted IS'!$E11) | CL11: =SUMIFS('QofE Def adjustments'!AP:AP,'QofE Def adjustments'!$E:$E,'Adjusted IS'!$E11) | CM11: =SUMIFS('QofE Def adjustments'!AQ:AQ,'QofE Def adjustments'!$E:$E,'Adjusted IS'!$E11) | CN11: =SUMIFS('QofE Def adjustments'!AR:AR,'QofE Def adjustments'!$E:$E,'Adjusted IS'!$E11) | CO11: =SUMIFS('QofE Def adjustments'!AS:AS,'QofE Def adjustments'!$E:$E,'Adjusted IS'!$E11) | CP11: =SUMIFS('QofE Def adjustments'!AT:AT,'QofE Def adjustments'!$E:$E,'Adjusted IS'!$E11) | CQ11: =SUMIFS('QofE Def adjustments'!AU:AU,'QofE Def adjustments'!$E:$E,'Adjusted IS'!$E11) | CR11: =SUM(BB11:BM11) | CS11: =SUM(BN11:BY11) | CT11: =SUM(BZ11:CK11) | CU11: =SUM(CD11:CO11) | CV11: =SUM(CF11:CQ11) | CX11: =SUM(BB11,F11) | CY11: =SUM(BC11,G11) | CZ11: =SUM(BD11,H11) | DA11: =SUM(BE11,I11) | DB11: =SUM(BF11,J11) | DC11: =SUM(BG11,K11) | DD11: =SUM(BH11,L11) | DE11: =SUM(BI11,M11) | ... EM11: =SUM(CQ11,AU11) | EN11: =SUM(CX11:DI11) | EO11: =SUM(DJ11:DU11) | EP11: =SUM(DV11:EG11) | EQ11: =SUM(DZ11:EK11) | ER11: =SUM(EB11:EM11) | ET11: =SUMIFS('QofE DD adjustments'!F:F,'QofE DD adjustments'!$E:$E,'Adjusted IS'!$E11) | EU11: =SUMIFS('QofE DD adjustments'!G:G,'QofE DD adjustments'!$E:$E,'Adjusted IS'!$E11) | EV11: =SUMIFS('QofE DD adjustments'!H:H,'QofE DD adjustments'!$E:$E,'Adjusted IS'!$E11) | EW11: =SUMIFS('QofE DD adjustments'!I:I,'QofE DD adjustments'!$E:$E,'Adjusted IS'!$E11) | EX11: =SUMIFS('QofE DD adjustments'!J:J,'QofE DD adjustments'!$E:$E,'Adjusted IS'!$E11) | EY11: =SUMIFS('QofE DD adjustments'!K:K,'QofE DD adjustments'!$E:$E,'Adjusted IS'!$E11) | EZ11: =SUMIFS('QofE DD adjustments'!L:L,'QofE DD adjustments'!$E:$E,'Adjusted IS'!$E11) | FA11: =SUMIFS('QofE DD adjustments'!M:M,'QofE DD adjustments'!$E:$E,'Adjusted IS'!$E11) | FB11: =SUMIFS('QofE DD adjustments'!N:N,'QofE DD adjustments'!$E:$E,'Adjusted IS'!$E11) | FC11: =SUMIFS('QofE DD adjustments'!O:O,'QofE DD adjustments'!$E:$E,'Adjusted IS'!$E11) | FD11: =SUMIFS('QofE DD adjustments'!P:P,'QofE DD adjustments'!$E:$E,'Adjusted IS'!$E11) | FE11: =SUMIFS('QofE DD adjustments'!Q:Q,'QofE DD adjustments'!$E:$E,'Adjusted IS'!$E11) | FF11: =SUMIFS('QofE DD adjustments'!R:R,'QofE DD adjustments'!$E:$E,'Adjusted IS'!$E11) | FG11: =SUMIFS('QofE DD adjustments'!S:S,'QofE DD adjustments'!$E:$E,'Adjusted IS'!$E11) | FH11: =SUMIFS('QofE DD adjustments'!T:T,'QofE DD adjustments'!$E:$E,'Adjusted IS'!$E11) | FI11: =SUMIFS('QofE DD adjustments'!U:U,'QofE DD adjustments'!$E:$E,'Adjusted IS'!$E11) | FJ11: =SUMIFS('QofE DD adjustments'!V:V,'QofE DD adjustments'!$E:$E,'Adjusted IS'!$E11) | FK11: =SUMIFS('QofE DD adjustments'!W:W,'QofE DD adjustments'!$E:$E,'Adjusted IS'!$E11) | FL11: =SUMIFS('QofE DD adjustments'!X:X,'QofE DD adjustments'!$E:$E,'Adjusted IS'!$E11) | FM11: =SUMIFS('QofE DD adjustments'!Y:Y,'QofE DD adjustments'!$E:$E,'Adjusted IS'!$E11) | FN11: =SUMIFS('QofE DD adjustments'!Z:Z,'QofE DD adjustments'!$E:$E,'Adjusted IS'!$E11) | FO11: =SUMIFS('QofE DD adjustments'!AA:AA,'QofE DD adjustments'!$E:$E,'Adjusted IS'!$E11) | FP11: =SUMIFS('QofE DD adjustments'!AB:AB,'QofE DD adjustments'!$E:$E,'Adjusted IS'!$E11) | FQ11: =SUMIFS('QofE DD adjustments'!AC:AC,'QofE DD adjustments'!$E:$E,'Adjusted IS'!$E11) | FR11: =SUMIFS('QofE DD adjustments'!AD:AD,'QofE DD adjustments'!$E:$E,'Adjusted IS'!$E11) | FS11: =SUMIFS('QofE DD adjustments'!AE:AE,'QofE DD adjustments'!$E:$E,'Adjusted IS'!$E11) | FT11: =SUMIFS('QofE DD adjustments'!AF:AF,'QofE DD adjustments'!$E:$E,'Adjusted IS'!$E11) | FU11: =SUMIFS('QofE DD adjustments'!AG:AG,'QofE DD adjustments'!$E:$E,'Adjusted IS'!$E11) | FV11: =SUMIFS('QofE DD adjustments'!AH:AH,'QofE DD adjustments'!$E:$E,'Adjusted IS'!$E11) | FW11: =SUMIFS('QofE DD adjustments'!AI:AI,'QofE DD adjustments'!$E:$E,'Adjusted IS'!$E11) | FX11: =SUMIFS('QofE DD adjustments'!AJ:AJ,'QofE DD adjustments'!$E:$E,'Adjusted IS'!$E11) | FY11: =SUMIFS('QofE DD adjustments'!AK:AK,'QofE DD adjustments'!$E:$E,'Adjusted IS'!$E11) | FZ11: =SUMIFS('QofE DD adjustments'!AL:AL,'QofE DD adjustments'!$E:$E,'Adjusted IS'!$E11) | GA11: =SUMIFS('QofE DD adjustments'!AM:AM,'QofE DD adjustments'!$E:$E,'Adjusted IS'!$E11) | GB11: =SUMIFS('QofE DD adjustments'!AN:AN,'QofE DD adjustments'!$E:$E,'Adjusted IS'!$E11) | GC11: =SUMIFS('QofE DD adjustments'!AO:AO,'QofE DD adjustments'!$E:$E,'Adjusted IS'!$E11) | GD11: =SUMIFS('QofE DD adjustments'!AP:AP,'QofE DD adjustments'!$E:$E,'Adjusted IS'!$E11) | GE11: =SUMIFS('QofE DD adjustments'!AQ:AQ,'QofE DD adjustments'!$E:$E,'Adjusted IS'!$E11) | GF11: =SUMIFS('QofE DD adjustments'!AR:AR,'QofE DD adjustments'!$E:$E,'Adjusted IS'!$E11) | GG11: =SUMIFS('QofE DD adjustments'!AS:AS,'QofE DD adjustments'!$E:$E,'Adjusted IS'!$E11) | GH11: =SUMIFS('QofE DD adjustments'!AT:AT,'QofE DD adjustments'!$E:$E,'Adjusted IS'!$E11) | GI11: =SUMIFS('QofE DD adjustments'!AU:AU,'QofE DD adjustments'!$E:$E,'Adjusted IS'!$E11) | GJ11: =SUM(ET11:FE11) | GK11: =SUM(FF11:FQ11) | GL11: =SUM(FR11:GC11) | GM11: =SUM(FV11:GG11) | GN11: =SUM(FX11:GI11) | GP11: =SUM(ET11,CX11) | GQ11: =SUM(EU11,CY11) | GR11: =SUM(EV11,CZ11) | GS11: =SUM(EW11,DA11) | GT11: =SUM(EX11,DB11) | GU11: =SUM(EY11,DC11) | GV11: =SUM(EZ11,DD11) | GW11: =SUM(FA11,DE11) | ... IE11: =SUM(GI11,EM11) | IF11: =SUM(GP11:HA11) | IG11: =SUM(HB11:HM11) | IH11: =SUM(HN11:HY11) | II11: =SUM(HR11:IC11) | IJ11: =SUM(HT11:IE11) | IL11: =SUMIFS('QofE PF adjustments'!F:F,'QofE PF adjustments'!$E:$E,'Adjusted IS'!$E11) | IM11: =SUMIFS('QofE PF adjustments'!G:G,'QofE PF adjustments'!$E:$E,'Adjusted IS'!$E11) | IN11: =SUMIFS('QofE PF adjustments'!H:H,'QofE PF adjustments'!$E:$E,'Adjusted IS'!$E11) | IO11: =SUMIFS('QofE PF adjustments'!I:I,'QofE PF adjustments'!$E:$E,'Adjusted IS'!$E11) | IP11: =SUMIFS('QofE PF adjustments'!J:J,'QofE PF adjustments'!$E:$E,'Adjusted IS'!$E11) | IQ11: =SUMIFS('QofE PF adjustments'!K:K,'QofE PF adjustments'!$E:$E,'Adjusted IS'!$E11) | IR11: =SUMIFS('QofE PF adjustments'!L:L,'QofE PF adjustments'!$E:$E,'Adjusted IS'!$E11) | IS11: =SUMIFS('QofE PF adjustments'!M:M,'QofE PF adjustments'!$E:$E,'Adjusted IS'!$E11) | IT11: =SUMIFS('QofE PF adjustments'!N:N,'QofE PF adjustments'!$E:$E,'Adjusted IS'!$E11) | IU11: =SUMIFS('QofE PF adjustments'!O:O,'QofE PF adjustments'!$E:$E,'Adjusted IS'!$E11) | IV11: =SUMIFS('QofE PF adjustments'!P:P,'QofE PF adjustments'!$E:$E,'Adjusted IS'!$E11) | IW11: =SUMIFS('QofE PF adjustments'!Q:Q,'QofE PF adjustments'!$E:$E,'Adjusted IS'!$E11) | IX11: =SUMIFS('QofE PF adjustments'!R:R,'QofE PF adjustments'!$E:$E,'Adjusted IS'!$E11) | IY11: =SUMIFS('QofE PF adjustments'!S:S,'QofE PF adjustments'!$E:$E,'Adjusted IS'!$E11) | IZ11: =SUMIFS('QofE PF adjustments'!T:T,'QofE PF adjustments'!$E:$E,'Adjusted IS'!$E11) | JA11: =SUMIFS('QofE PF adjustments'!U:U,'QofE PF adjustments'!$E:$E,'Adjusted IS'!$E11) | JB11: =SUMIFS('QofE PF adjustments'!V:V,'QofE PF adjustments'!$E:$E,'Adjusted IS'!$E11) | JC11: =SUMIFS('QofE PF adjustments'!W:W,'QofE PF adjustments'!$E:$E,'Adjusted IS'!$E11) | JD11: =SUMIFS('QofE PF adjustments'!X:X,'QofE PF adjustments'!$E:$E,'Adjusted IS'!$E11) | JE11: =SUMIFS('QofE PF adjustments'!Y:Y,'QofE PF adjustments'!$E:$E,'Adjusted IS'!$E11) | JF11: =SUMIFS('QofE PF adjustments'!Z:Z,'QofE PF adjustments'!$E:$E,'Adjusted IS'!$E11) | JG11: =SUMIFS('QofE PF adjustments'!AA:AA,'QofE PF adjustments'!$E:$E,'Adjusted IS'!$E11) | JH11: =SUMIFS('QofE PF adjustments'!AB:AB,'QofE PF adjustments'!$E:$E,'Adjusted IS'!$E11) | JI11: =SUMIFS('QofE PF adjustments'!AC:AC,'QofE PF adjustments'!$E:$E,'Adjusted IS'!$E11) | JJ11: =SUMIFS('QofE PF adjustments'!AD:AD,'QofE PF adjustments'!$E:$E,'Adjusted IS'!$E11) | JK11: =SUMIFS('QofE PF adjustments'!AE:AE,'QofE PF adjustments'!$E:$E,'Adjusted IS'!$E11) | JL11: =SUMIFS('QofE PF adjustments'!AF:AF,'QofE PF adjustments'!$E:$E,'Adjusted IS'!$E11) | JM11: =SUMIFS('QofE PF adjustments'!AG:AG,'QofE PF adjustments'!$E:$E,'Adjusted IS'!$E11) | JN11: =SUMIFS('QofE PF adjustments'!AH:AH,'QofE PF adjustments'!$E:$E,'Adjusted IS'!$E11) | JO11: =SUMIFS('QofE PF adjustments'!AI:AI,'QofE PF adjustments'!$E:$E,'Adjusted IS'!$E11) | JP11: =SUMIFS('QofE PF adjustments'!AJ:AJ,'QofE PF adjustments'!$E:$E,'Adjusted IS'!$E11) | JQ11: =SUMIFS('QofE PF adjustments'!AK:AK,'QofE PF adjustments'!$E:$E,'Adjusted IS'!$E11) | JR11: =SUMIFS('QofE PF adjustments'!AL:AL,'QofE PF adjustments'!$E:$E,'Adjusted IS'!$E11) | JS11: =SUMIFS('QofE PF adjustments'!AM:AM,'QofE PF adjustments'!$E:$E,'Adjusted IS'!$E11) | JT11: =SUMIFS('QofE PF adjustments'!AN:AN,'QofE PF adjustments'!$E:$E,'Adjusted IS'!$E11) | JU11: =SUMIFS('QofE PF adjustments'!AO:AO,'QofE PF adjustments'!$E:$E,'Adjusted IS'!$E11) | JV11: =SUMIFS('QofE PF adjustments'!AP:AP,'QofE PF adjustments'!$E:$E,'Adjusted IS'!$E11) | JW11: =SUMIFS('QofE PF adjustments'!AQ:AQ,'QofE PF adjustments'!$E:$E,'Adjusted IS'!$E11) | JX11: =SUMIFS('QofE PF adjustments'!AR:AR,'QofE PF adjustments'!$E:$E,'Adjusted IS'!$E11) | JY11: =SUMIFS('QofE PF adjustments'!AS:AS,'QofE PF adjustments'!$E:$E,'Adjusted IS'!$E11) | JZ11: =SUMIFS('QofE PF adjustments'!AT:AT,'QofE PF adjustments'!$E:$E,'Adjusted IS'!$E11) | KA11: =SUMIFS('QofE PF adjustments'!AU:AU,'QofE PF adjustments'!$E:$E,'Adjusted IS'!$E11) | KB11: =SUM(IL11:IW11) | KC11: =SUM(IX11:JI11) | KD11: =SUM(JJ11:JU11) | KE11: =SUM(JN11:JY11) | KF11: =SUM(JP11:KA11) | KH11: =SUM(IL11,GP11) | KI11: =SUM(IM11,GQ11) | KJ11: =SUM(IN11,GR11) | KK11: =SUM(IO11,GS11) | KL11: =SUM(IP11,GT11) | KM11: =SUM(IQ11,GU11) | KN11: =SUM(IR11,GV11) | KO11: =SUM(IS11,GW11) | ... LW11: =SUM(KA11,IE11) | LX11: =SUM(KH11:KS11) | LY11: =SUM(KT11:LE11) | LZ11: =SUM(LF11:LQ11) | MA11: =SUM(LJ11:LU11) | MB11: =SUM(LL11:LW11) | MD11: =IFERROR(KH11/KH$117,0) | ME11: =IFERROR(KI11/KI$117,0) | MF11: =IFERROR(KJ11/KJ$117,0) | MG11: =IFERROR(KK11/KK$117,0) | MH11: =IFERROR(KL11/KL$117,0) | MI11: =IFERROR(KM11/KM$117,0) | MJ11: =IFERROR(KN11/KN$117,0) | MK11: =IFERROR(KO11/KO$117,0) | ... NX11: =IFERROR(MB11/MB$117,0) | NZ11: =LY11-LX11 | OA11: =LZ11-LY11 | OB11: =MA11-LZ11 | OC11: =MB11-LZ11 | OE11: Processing services revenue | OF11: Processing services revenue | OG11: Processing services revenue
C12: Merchant services debit transaction revenue | D12: 411103 | E12: =CONCATENATE(D12," - ",C12) | F12: ='Income statement'!F12 | G12: ='Income statement'!G12 | H12: ='Income statement'!H12 | I12: ='Income statement'!I12 | J12: ='Income statement'!J12 | K12: ='Income statement'!K12 | L12: ='Income statement'!L12 | M12: ='Income statement'!M12 | ... AU12: ='Income statement'!AU12 | AV12: =SUM(F12:Q12) | AW12: =SUM(R12:AC12) | AX12: =SUM(AD12:AO12) | AY12: =SUM(AH12:AS12) | AZ12: =SUM(AJ12:AU12) | BB12: =SUMIFS('QofE Def adjustments'!F:F,'QofE Def adjustments'!$E:$E,'Adjusted IS'!$E12) | BC12: =SUMIFS('QofE Def adjustments'!G:G,'QofE Def adjustments'!$E:$E,'Adjusted IS'!$E12) | BD12: =SUMIFS('QofE Def adjustments'!H:H,'QofE Def adjustments'!$E:$E,'Adjusted IS'!$E12) | BE12: =SUMIFS('QofE Def adjustments'!I:I,'QofE Def adjustments'!$E:$E,'Adjusted IS'!$E12) | BF12: =SUMIFS('QofE Def adjustments'!J:J,'QofE Def adjustments'!$E:$E,'Adjusted IS'!$E12) | BG12: =SUMIFS('QofE Def adjustments'!K:K,'QofE Def adjustments'!$E:$E,'Adjusted IS'!$E12) | BH12: =SUMIFS('QofE Def adjustments'!L:L,'QofE Def adjustments'!$E:$E,'Adjusted IS'!$E12) | BI12: =SUMIFS('QofE Def adjustments'!M:M,'QofE Def adjustments'!$E:$E,'Adjusted IS'!$E12) | BJ12: =SUMIFS('QofE Def adjustments'!N:N,'QofE Def adjustments'!$E:$E,'Adjusted IS'!$E12) | BK12: =SUMIFS('QofE Def adjustments'!O:O,'QofE Def adjustments'!$E:$E,'Adjusted IS'!$E12) | BL12: =SUMIFS('QofE Def adjustments'!P:P,'QofE Def adjustments'!$E:$E,'Adjusted IS'!$E12) | BM12: =SUMIFS('QofE Def adjustments'!Q:Q,'QofE Def adjustments'!$E:$E,'Adjusted IS'!$E12) | BN12: =SUMIFS('QofE Def adjustments'!R:R,'QofE Def adjustments'!$E:$E,'Adjusted IS'!$E12) | BO12: =SUMIFS('QofE Def adjustments'!S:S,'QofE Def adjustments'!$E:$E,'Adjusted IS'!$E12) | BP12: =SUMIFS('QofE Def adjustments'!T:T,'QofE Def adjustments'!$E:$E,'Adjusted IS'!$E12) | BQ12: =SUMIFS('QofE Def adjustments'!U:U,'QofE Def adjustments'!$E:$E,'Adjusted IS'!$E12) | BR12: =SUMIFS('QofE Def adjustments'!V:V,'QofE Def adjustments'!$E:$E,'Adjusted IS'!$E12) | BS12: =SUMIFS('QofE Def adjustments'!W:W,'QofE Def adjustments'!$E:$E,'Adjusted IS'!$E12) | BT12: =SUMIFS('QofE Def adjustments'!X:X,'QofE Def adjustments'!$E:$E,'Adjusted IS'!$E12) | BU12: =SUMIFS('QofE Def adjustments'!Y:Y,'QofE Def adjustments'!$E:$E,'Adjusted IS'!$E12) | BV12: =SUMIFS('QofE Def adjustments'!Z:Z,'QofE Def adjustments'!$E:$E,'Adjusted IS'!$E12) | BW12: =SUMIFS('QofE Def adjustments'!AA:AA,'QofE Def adjustments'!$E:$E,'Adjusted IS'!$E12) | BX12: =SUMIFS('QofE Def adjustments'!AB:AB,'QofE Def adjustments'!$E:$E,'Adjusted IS'!$E12) | BY12: =SUMIFS('QofE Def adjustments'!AC:AC,'QofE Def adjustments'!$E:$E,'Adjusted IS'!$E12) | BZ12: =SUMIFS('QofE Def adjustments'!AD:AD,'QofE Def adjustments'!$E:$E,'Adjusted IS'!$E12) | CA12: =SUMIFS('QofE Def adjustments'!AE:AE,'QofE Def adjustments'!$E:$E,'Adjusted IS'!$E12) | CB12: =SUMIFS('QofE Def adjustments'!AF:AF,'QofE Def adjustments'!$E:$E,'Adjusted IS'!$E12) | CC12: =SUMIFS('QofE Def adjustments'!AG:AG,'QofE Def adjustments'!$E:$E,'Adjusted IS'!$E12) | CD12: =SUMIFS('QofE Def adjustments'!AH:AH,'QofE Def adjustments'!$E:$E,'Adjusted IS'!$E12) | CE12: =SUMIFS('QofE Def adjustments'!AI:AI,'QofE Def adjustments'!$E:$E,'Adjusted IS'!$E12) | CF12: =SUMIFS('QofE Def adjustments'!AJ:AJ,'QofE Def adjustments'!$E:$E,'Adjusted IS'!$E12) | CG12: =SUMIFS('QofE Def adjustments'!AK:AK,'QofE Def adjustments'!$E:$E,'Adjusted IS'!$E12) | CH12: =SUMIFS('QofE Def adjustments'!AL:AL,'QofE Def adjustments'!$E:$E,'Adjusted IS'!$E12) | CI12: =SUMIFS('QofE Def adjustments'!AM:AM,'QofE Def adjustments'!$E:$E,'Adjusted IS'!$E12) | CJ12: =SUMIFS('QofE Def adjustments'!AN:AN,'QofE Def adjustments'!$E:$E,'Adjusted IS'!$E12) | CK12: =SUMIFS('QofE Def adjustments'!AO:AO,'QofE Def adjustments'!$E:$E,'Adjusted IS'!$E12) | CL12: =SUMIFS('QofE Def adjustments'!AP:AP,'QofE Def adjustments'!$E:$E,'Adjusted IS'!$E12) | CM12: =SUMIFS('QofE Def adjustments'!AQ:AQ,'QofE Def adjustments'!$E:$E,'Adjusted IS'!$E12) | CN12: =SUMIFS('QofE Def adjustments'!AR:AR,'QofE Def adjustments'!$E:$E,'Adjusted IS'!$E12) | CO12: =SUMIFS('QofE Def adjustments'!AS:AS,'QofE Def adjustments'!$E:$E,'Adjusted IS'!$E12) | CP12: =SUMIFS('QofE Def adjustments'!AT:AT,'QofE Def adjustments'!$E:$E,'Adjusted IS'!$E12) | CQ12: =SUMIFS('QofE Def adjustments'!AU:AU,'QofE Def adjustments'!$E:$E,'Adjusted IS'!$E12) | CR12: =SUM(BB12:BM12) | CS12: =SUM(BN12:BY12) | CT12: =SUM(BZ12:CK12) | CU12: =SUM(CD12:CO12) | CV12: =SUM(CF12:CQ12) | CX12: =SUM(BB12,F12) | CY12: =SUM(BC12,G12) | CZ12: =SUM(BD12,H12) | DA12: =SUM(BE12,I12) | DB12: =SUM(BF12,J12) | DC12: =SUM(BG12,K12) | DD12: =SUM(BH12,L12) | DE12: =SUM(BI12,M12) | ... EM12: =SUM(CQ12,AU12) | EN12: =SUM(CX12:DI12) | EO12: =SUM(DJ12:DU12) | EP12: =SUM(DV12:EG12) | EQ12: =SUM(DZ12:EK12) | ER12: =SUM(EB12:EM12) | ET12: =SUMIFS('QofE DD adjustments'!F:F,'QofE DD adjustments'!$E:$E,'Adjusted IS'!$E12) | EU12: =SUMIFS('QofE DD adjustments'!G:G,'QofE DD adjustments'!$E:$E,'Adjusted IS'!$E12) | EV12: =SUMIFS('QofE DD adjustments'!H:H,'QofE DD adjustments'!$E:$E,'Adjusted IS'!$E12) | EW12: =SUMIFS('QofE DD adjustments'!I:I,'QofE DD adjustments'!$E:$E,'Adjusted IS'!$E12) | EX12: =SUMIFS('QofE DD adjustments'!J:J,'QofE DD adjustments'!$E:$E,'Adjusted IS'!$E12) | EY12: =SUMIFS('QofE DD adjustments'!K:K,'QofE DD adjustments'!$E:$E,'Adjusted IS'!$E12) | EZ12: =SUMIFS('QofE DD adjustments'!L:L,'QofE DD adjustments'!$E:$E,'Adjusted IS'!$E12) | FA12: =SUMIFS('QofE DD adjustments'!M:M,'QofE DD adjustments'!$E:$E,'Adjusted IS'!$E12) | FB12: =SUMIFS('QofE DD adjustments'!N:N,'QofE DD adjustments'!$E:$E,'Adjusted IS'!$E12) | FC12: =SUMIFS('QofE DD adjustments'!O:O,'QofE DD adjustments'!$E:$E,'Adjusted IS'!$E12) | FD12: =SUMIFS('QofE DD adjustments'!P:P,'QofE DD adjustments'!$E:$E,'Adjusted IS'!$E12) | FE12: =SUMIFS('QofE DD adjustments'!Q:Q,'QofE DD adjustments'!$E:$E,'Adjusted IS'!$E12) | FF12: =SUMIFS('QofE DD adjustments'!R:R,'QofE DD adjustments'!$E:$E,'Adjusted IS'!$E12) | FG12: =SUMIFS('QofE DD adjustments'!S:S,'QofE DD adjustments'!$E:$E,'Adjusted IS'!$E12) | FH12: =SUMIFS('QofE DD adjustments'!T:T,'QofE DD adjustments'!$E:$E,'Adjusted IS'!$E12) | FI12: =SUMIFS('QofE DD adjustments'!U:U,'QofE DD adjustments'!$E:$E,'Adjusted IS'!$E12) | FJ12: =SUMIFS('QofE DD adjustments'!V:V,'QofE DD adjustments'!$E:$E,'Adjusted IS'!$E12) | FK12: =SUMIFS('QofE DD adjustments'!W:W,'QofE DD adjustments'!$E:$E,'Adjusted IS'!$E12) | FL12: =SUMIFS('QofE DD adjustments'!X:X,'QofE DD adjustments'!$E:$E,'Adjusted IS'!$E12) | FM12: =SUMIFS('QofE DD adjustments'!Y:Y,'QofE DD adjustments'!$E:$E,'Adjusted IS'!$E12) | FN12: =SUMIFS('QofE DD adjustments'!Z:Z,'QofE DD adjustments'!$E:$E,'Adjusted IS'!$E12) | FO12: =SUMIFS('QofE DD adjustments'!AA:AA,'QofE DD adjustments'!$E:$E,'Adjusted IS'!$E12) | FP12: =SUMIFS('QofE DD adjustments'!AB:AB,'QofE DD adjustments'!$E:$E,'Adjusted IS'!$E12) | FQ12: =SUMIFS('QofE DD adjustments'!AC:AC,'QofE DD adjustments'!$E:$E,'Adjusted IS'!$E12) | FR12: =SUMIFS('QofE DD adjustments'!AD:AD,'QofE DD adjustments'!$E:$E,'Adjusted IS'!$E12) | FS12: =SUMIFS('QofE DD adjustments'!AE:AE,'QofE DD adjustments'!$E:$E,'Adjusted IS'!$E12) | FT12: =SUMIFS('QofE DD adjustments'!AF:AF,'QofE DD adjustments'!$E:$E,'Adjusted IS'!$E12) | FU12: =SUMIFS('QofE DD adjustments'!AG:AG,'QofE DD adjustments'!$E:$E,'Adjusted IS'!$E12) | FV12: =SUMIFS('QofE DD adjustments'!AH:AH,'QofE DD adjustments'!$E:$E,'Adjusted IS'!$E12) | FW12: =SUMIFS('QofE DD adjustments'!AI:AI,'QofE DD adjustments'!$E:$E,'Adjusted IS'!$E12) | FX12: =SUMIFS('QofE DD adjustments'!AJ:AJ,'QofE DD adjustments'!$E:$E,'Adjusted IS'!$E12) | FY12: =SUMIFS('QofE DD adjustments'!AK:AK,'QofE DD adjustments'!$E:$E,'Adjusted IS'!$E12) | FZ12: =SUMIFS('QofE DD adjustments'!AL:AL,'QofE DD adjustments'!$E:$E,'Adjusted IS'!$E12) | GA12: =SUMIFS('QofE DD adjustments'!AM:AM,'QofE DD adjustments'!$E:$E,'Adjusted IS'!$E12) | GB12: =SUMIFS('QofE DD adjustments'!AN:AN,'QofE DD adjustments'!$E:$E,'Adjusted IS'!$E12) | GC12: =SUMIFS('QofE DD adjustments'!AO:AO,'QofE DD adjustments'!$E:$E,'Adjusted IS'!$E12) | GD12: =SUMIFS('QofE DD adjustments'!AP:AP,'QofE DD adjustments'!$E:$E,'Adjusted IS'!$E12) | GE12: =SUMIFS('QofE DD adjustments'!AQ:AQ,'QofE DD adjustments'!$E:$E,'Adjusted IS'!$E12) | GF12: =SUMIFS('QofE DD adjustments'!AR:AR,'QofE DD adjustments'!$E:$E,'Adjusted IS'!$E12) | GG12: =SUMIFS('QofE DD adjustments'!AS:AS,'QofE DD adjustments'!$E:$E,'Adjusted IS'!$E12) | GH12: =SUMIFS('QofE DD adjustments'!AT:AT,'QofE DD adjustments'!$E:$E,'Adjusted IS'!$E12) | GI12: =SUMIFS('QofE DD adjustments'!AU:AU,'QofE DD adjustments'!$E:$E,'Adjusted IS'!$E12) | GJ12: =SUM(ET12:FE12) | GK12: =SUM(FF12:FQ12) | GL12: =SUM(FR12:GC12) | GM12: =SUM(FV12:GG12) | GN12: =SUM(FX12:GI12) | GP12: =SUM(ET12,CX12) | GQ12: =SUM(EU12,CY12) | GR12: =SUM(EV12,CZ12) | GS12: =SUM(EW12,DA12) | GT12: =SUM(EX12,DB12) | GU12: =SUM(EY12,DC12) | GV12: =SUM(EZ12,DD12) | GW12: =SUM(FA12,DE12) | ... IE12: =SUM(GI12,EM12) | IF12: =SUM(GP12:HA12) | IG12: =SUM(HB12:HM12) | IH12: =SUM(HN12:HY12) | II12: =SUM(HR12:IC12) | IJ12: =SUM(HT12:IE12) | IL12: =SUMIFS('QofE PF adjustments'!F:F,'QofE PF adjustments'!$E:$E,'Adjusted IS'!$E12) | IM12: =SUMIFS('QofE PF adjustments'!G:G,'QofE PF adjustments'!$E:$E,'Adjusted IS'!$E12) | IN12: =SUMIFS('QofE PF adjustments'!H:H,'QofE PF adjustments'!$E:$E,'Adjusted IS'!$E12) | IO12: =SUMIFS('QofE PF adjustments'!I:I,'QofE PF adjustments'!$E:$E,'Adjusted IS'!$E12) | IP12: =SUMIFS('QofE PF adjustments'!J:J,'QofE PF adjustments'!$E:$E,'Adjusted IS'!$E12) | IQ12: =SUMIFS('QofE PF adjustments'!K:K,'QofE PF adjustments'!$E:$E,'Adjusted IS'!$E12) | IR12: =SUMIFS('QofE PF adjustments'!L:L,'QofE PF adjustments'!$E:$E,'Adjusted IS'!$E12) | IS12: =SUMIFS('QofE PF adjustments'!M:M,'QofE PF adjustments'!$E:$E,'Adjusted IS'!$E12) | IT12: =SUMIFS('QofE PF adjustments'!N:N,'QofE PF adjustments'!$E:$E,'Adjusted IS'!$E12) | IU12: =SUMIFS('QofE PF adjustments'!O:O,'QofE PF adjustments'!$E:$E,'Adjusted IS'!$E12) | IV12: =SUMIFS('QofE PF adjustments'!P:P,'QofE PF adjustments'!$E:$E,'Adjusted IS'!$E12) | IW12: =SUMIFS('QofE PF adjustments'!Q:Q,'QofE PF adjustments'!$E:$E,'Adjusted IS'!$E12) | IX12: =SUMIFS('QofE PF adjustments'!R:R,'QofE PF adjustments'!$E:$E,'Adjusted IS'!$E12) | IY12: =SUMIFS('QofE PF adjustments'!S:S,'QofE PF adjustments'!$E:$E,'Adjusted IS'!$E12) | IZ12: =SUMIFS('QofE PF adjustments'!T:T,'QofE PF adjustments'!$E:$E,'Adjusted IS'!$E12) | JA12: =SUMIFS('QofE PF adjustments'!U:U,'QofE PF adjustments'!$E:$E,'Adjusted IS'!$E12) | JB12: =SUMIFS('QofE PF adjustments'!V:V,'QofE PF adjustments'!$E:$E,'Adjusted IS'!$E12) | JC12: =SUMIFS('QofE PF adjustments'!W:W,'QofE PF adjustments'!$E:$E,'Adjusted IS'!$E12) | JD12: =SUMIFS('QofE PF adjustments'!X:X,'QofE PF adjustments'!$E:$E,'Adjusted IS'!$E12) | JE12: =SUMIFS('QofE PF adjustments'!Y:Y,'QofE PF adjustments'!$E:$E,'Adjusted IS'!$E12) | JF12: =SUMIFS('QofE PF adjustments'!Z:Z,'QofE PF adjustments'!$E:$E,'Adjusted IS'!$E12) | JG12: =SUMIFS('QofE PF adjustments'!AA:AA,'QofE PF adjustments'!$E:$E,'Adjusted IS'!$E12) | JH12: =SUMIFS('QofE PF adjustments'!AB:AB,'QofE PF adjustments'!$E:$E,'Adjusted IS'!$E12) | JI12: =SUMIFS('QofE PF adjustments'!AC:AC,'QofE PF adjustments'!$E:$E,'Adjusted IS'!$E12) | JJ12: =SUMIFS('QofE PF adjustments'!AD:AD,'QofE PF adjustments'!$E:$E,'Adjusted IS'!$E12) | JK12: =SUMIFS('QofE PF adjustments'!AE:AE,'QofE PF adjustments'!$E:$E,'Adjusted IS'!$E12) | JL12: =SUMIFS('QofE PF adjustments'!AF:AF,'QofE PF adjustments'!$E:$E,'Adjusted IS'!$E12) | JM12: =SUMIFS('QofE PF adjustments'!AG:AG,'QofE PF adjustments'!$E:$E,'Adjusted IS'!$E12) | JN12: =SUMIFS('QofE PF adjustments'!AH:AH,'QofE PF adjustments'!$E:$E,'Adjusted IS'!$E12) | JO12: =SUMIFS('QofE PF adjustments'!AI:AI,'QofE PF adjustments'!$E:$E,'Adjusted IS'!$E12) | JP12: =SUMIFS('QofE PF adjustments'!AJ:AJ,'QofE PF adjustments'!$E:$E,'Adjusted IS'!$E12) | JQ12: =SUMIFS('QofE PF adjustments'!AK:AK,'QofE PF adjustments'!$E:$E,'Adjusted IS'!$E12) | JR12: =SUMIFS('QofE PF adjustments'!AL:AL,'QofE PF adjustments'!$E:$E,'Adjusted IS'!$E12) | JS12: =SUMIFS('QofE PF adjustments'!AM:AM,'QofE PF adjustments'!$E:$E,'Adjusted IS'!$E12) | JT12: =SUMIFS('QofE PF adjustments'!AN:AN,'QofE PF adjustments'!$E:$E,'Adjusted IS'!$E12) | JU12: =SUMIFS('QofE PF adjustments'!AO:AO,'QofE PF adjustments'!$E:$E,'Adjusted IS'!$E12) | JV12: =SUMIFS('QofE PF adjustments'!AP:AP,'QofE PF adjustments'!$E:$E,'Adjusted IS'!$E12) | JW12: =SUMIFS('QofE PF adjustments'!AQ:AQ,'QofE PF adjustments'!$E:$E,'Adjusted IS'!$E12) | JX12: =SUMIFS('QofE PF adjustments'!AR:AR,'QofE PF adjustments'!$E:$E,'Adjusted IS'!$E12) | JY12: =SUMIFS('QofE PF adjustments'!AS:AS,'QofE PF adjustments'!$E:$E,'Adjusted IS'!$E12) | JZ12: =SUMIFS('QofE PF adjustments'!AT:AT,'QofE PF adjustments'!$E:$E,'Adjusted IS'!$E12) | KA12: =SUMIFS('QofE PF adjustments'!AU:AU,'QofE PF adjustments'!$E:$E,'Adjusted IS'!$E12) | KB12: =SUM(IL12:IW12) | KC12: =SUM(IX12:JI12) | KD12: =SUM(JJ12:JU12) | KE12: =SUM(JN12:JY12) | KF12: =SUM(JP12:KA12) | KH12: =SUM(IL12,GP12) | KI12: =SUM(IM12,GQ12) | KJ12: =SUM(IN12,GR12) | KK12: =SUM(IO12,GS12) | KL12: =SUM(IP12,GT12) | KM12: =SUM(IQ12,GU12) | KN12: =SUM(IR12,GV12) | KO12: =SUM(IS12,GW12) | ... LW12: =SUM(KA12,IE12) | LX12: =SUM(KH12:KS12) | LY12: =SUM(KT12:LE12) | LZ12: =SUM(LF12:LQ12) | MA12: =SUM(LJ12:LU12) | MB12: =SUM(LL12:LW12) | MD12: =IFERROR(KH12/KH$117,0) | ME12: =IFERROR(KI12/KI$117,0) | MF12: =IFERROR(KJ12/KJ$117,0) | MG12: =IFERROR(KK12/KK$117,0) | MH12: =IFERROR(KL12/KL$117,0) | MI12: =IFERROR(KM12/KM$117,0) | MJ12: =IFERROR(KN12/KN$117,0) | MK12: =IFERROR(KO12/KO$117,0) | ... NX12: =IFERROR(MB12/MB$117,0) | NZ12: =LY12-LX12 | OA12: =LZ12-LY12 | OB12: =MA12-LZ12 | OC12: =MB12-LZ12 | OE12: Processing services revenue | OF12: Processing services revenue | OG12: Processing services revenue
C13: Ifrs 15 adj to processing | D13: 411119 | E13: =CONCATENATE(D13," - ",C13) | F13: ='Income statement'!F13 | G13: ='Income statement'!G13 | H13: ='Income statement'!H13 | I13: ='Income statement'!I13 | J13: ='Income statement'!J13 | K13: ='Income statement'!K13 | L13: ='Income statement'!L13 | M13: ='Income statement'!M13 | ... AU13: ='Income statement'!AU13 | AV13: =SUM(F13:Q13) | AW13: =SUM(R13:AC13) | AX13: =SUM(AD13:AO13) | AY13: =SUM(AH13:AS13) | AZ13: =SUM(AJ13:AU13) | BB13: =SUMIFS('QofE Def adjustments'!F:F,'QofE Def adjustments'!$E:$E,'Adjusted IS'!$E13) | BC13: =SUMIFS('QofE Def adjustments'!G:G,'QofE Def adjustments'!$E:$E,'Adjusted IS'!$E13) | BD13: =SUMIFS('QofE Def adjustments'!H:H,'QofE Def adjustments'!$E:$E,'Adjusted IS'!$E13) | BE13: =SUMIFS('QofE Def adjustments'!I:I,'QofE Def adjustments'!$E:$E,'Adjusted IS'!$E13) | BF13: =SUMIFS('QofE Def adjustments'!J:J,'QofE Def adjustments'!$E:$E,'Adjusted IS'!$E13) | BG13: =SUMIFS('QofE Def adjustments'!K:K,'QofE Def adjustments'!$E:$E,'Adjusted IS'!$E13) | BH13: =SUMIFS('QofE Def adjustments'!L:L,'QofE Def adjustments'!$E:$E,'Adjusted IS'!$E13) | BI13: =SUMIFS('QofE Def adjustments'!M:M,'QofE Def adjustments'!$E:$E,'Adjusted IS'!$E13) | BJ13: =SUMIFS('QofE Def adjustments'!N:N,'QofE Def adjustments'!$E:$E,'Adjusted IS'!$E13) | BK13: =SUMIFS('QofE Def adjustments'!O:O,'QofE Def adjustments'!$E:$E,'Adjusted IS'!$E13) | BL13: =SUMIFS('QofE Def adjustments'!P:P,'QofE Def adjustments'!$E:$E,'Adjusted IS'!$E13) | BM13: =SUMIFS('QofE Def adjustments'!Q:Q,'QofE Def adjustments'!$E:$E,'Adjusted IS'!$E13) | BN13: =SUMIFS('QofE Def adjustments'!R:R,'QofE Def adjustments'!$E:$E,'Adjusted IS'!$E13) | BO13: =SUMIFS('QofE Def adjustments'!S:S,'QofE Def adjustments'!$E:$E,'Adjusted IS'!$E13) | BP13: =SUMIFS('QofE Def adjustments'!T:T,'QofE Def adjustments'!$E:$E,'Adjusted IS'!$E13) | BQ13: =SUMIFS('QofE Def adjustments'!U:U,'QofE Def adjustments'!$E:$E,'Adjusted IS'!$E13) | BR13: =SUMIFS('QofE Def adjustments'!V:V,'QofE Def adjustments'!$E:$E,'Adjusted IS'!$E13) | BS13: =SUMIFS('QofE Def adjustments'!W:W,'QofE Def adjustments'!$E:$E,'Adjusted IS'!$E13) | BT13: =SUMIFS('QofE Def adjustments'!X:X,'QofE Def adjustments'!$E:$E,'Adjusted IS'!$E13) | BU13: =SUMIFS('QofE Def adjustments'!Y:Y,'QofE Def adjustments'!$E:$E,'Adjusted IS'!$E13) | BV13: =SUMIFS('QofE Def adjustments'!Z:Z,'QofE Def adjustments'!$E:$E,'Adjusted IS'!$E13) | BW13: =SUMIFS('QofE Def adjustments'!AA:AA,'QofE Def adjustments'!$E:$E,'Adjusted IS'!$E13) | BX13: =SUMIFS('QofE Def adjustments'!AB:AB,'QofE Def adjustments'!$E:$E,'Adjusted IS'!$E13) | BY13: =SUMIFS('QofE Def adjustments'!AC:AC,'QofE Def adjustments'!$E:$E,'Adjusted IS'!$E13) | BZ13: =SUMIFS('QofE Def adjustments'!AD:AD,'QofE Def adjustments'!$E:$E,'Adjusted IS'!$E13) | CA13: =SUMIFS('QofE Def adjustments'!AE:AE,'QofE Def adjustments'!$E:$E,'Adjusted IS'!$E13) | CB13: =SUMIFS('QofE Def adjustments'!AF:AF,'QofE Def adjustments'!$E:$E,'Adjusted IS'!$E13) | CC13: =SUMIFS('QofE Def adjustments'!AG:AG,'QofE Def adjustments'!$E:$E,'Adjusted IS'!$E13) | CD13: =SUMIFS('QofE Def adjustments'!AH:AH,'QofE Def adjustments'!$E:$E,'Adjusted IS'!$E13) | CE13: =SUMIFS('QofE Def adjustments'!AI:AI,'QofE Def adjustments'!$E:$E,'Adjusted IS'!$E13) | CF13: =SUMIFS('QofE Def adjustments'!AJ:AJ,'QofE Def adjustments'!$E:$E,'Adjusted IS'!$E13) | CG13: =SUMIFS('QofE Def adjustments'!AK:AK,'QofE Def adjustments'!$E:$E,'Adjusted IS'!$E13) | CH13: =SUMIFS('QofE Def adjustments'!AL:AL,'QofE Def adjustments'!$E:$E,'Adjusted IS'!$E13) | CI13: =SUMIFS('QofE Def adjustments'!AM:AM,'QofE Def adjustments'!$E:$E,'Adjusted IS'!$E13) | CJ13: =SUMIFS('QofE Def adjustments'!AN:AN,'QofE Def adjustments'!$E:$E,'Adjusted IS'!$E13) | CK13: =SUMIFS('QofE Def adjustments'!AO:AO,'QofE Def adjustments'!$E:$E,'Adjusted IS'!$E13) | CL13: =SUMIFS('QofE Def adjustments'!AP:AP,'QofE Def adjustments'!$E:$E,'Adjusted IS'!$E13) | CM13: =SUMIFS('QofE Def adjustments'!AQ:AQ,'QofE Def adjustments'!$E:$E,'Adjusted IS'!$E13) | CN13: =SUMIFS('QofE Def adjustments'!AR:AR,'QofE Def adjustments'!$E:$E,'Adjusted IS'!$E13) | CO13: =SUMIFS('QofE Def adjustments'!AS:AS,'QofE Def adjustments'!$E:$E,'Adjusted IS'!$E13) | CP13: =SUMIFS('QofE Def adjustments'!AT:AT,'QofE Def adjustments'!$E:$E,'Adjusted IS'!$E13) | CQ13: =SUMIFS('QofE Def adjustments'!AU:AU,'QofE Def adjustments'!$E:$E,'Adjusted IS'!$E13) | CR13: =SUM(BB13:BM13) | CS13: =SUM(BN13:BY13) | CT13: =SUM(BZ13:CK13) | CU13: =SUM(CD13:CO13) | CV13: =SUM(CF13:CQ13) | CX13: =SUM(BB13,F13) | CY13: =SUM(BC13,G13) | CZ13: =SUM(BD13,H13) | DA13: =SUM(BE13,I13) | DB13: =SUM(BF13,J13) | DC13: =SUM(BG13,K13) | DD13: =SUM(BH13,L13) | DE13: =SUM(BI13,M13) | ... EM13: =SUM(CQ13,AU13) | EN13: =SUM(CX13:DI13) | EO13: =SUM(DJ13:DU13) | EP13: =SUM(DV13:EG13) | EQ13: =SUM(DZ13:EK13) | ER13: =SUM(EB13:EM13) | ET13: =SUMIFS('QofE DD adjustments'!F:F,'QofE DD adjustments'!$E:$E,'Adjusted IS'!$E13) | EU13: =SUMIFS('QofE DD adjustments'!G:G,'QofE DD adjustments'!$E:$E,'Adjusted IS'!$E13) | EV13: =SUMIFS('QofE DD adjustments'!H:H,'QofE DD adjustments'!$E:$E,'Adjusted IS'!$E13) | EW13: =SUMIFS('QofE DD adjustments'!I:I,'QofE DD adjustments'!$E:$E,'Adjusted IS'!$E13) | EX13: =SUMIFS('QofE DD adjustments'!J:J,'QofE DD adjustments'!$E:$E,'Adjusted IS'!$E13) | EY13: =SUMIFS('QofE DD adjustments'!K:K,'QofE DD adjustments'!$E:$E,'Adjusted IS'!$E13) | EZ13: =SUMIFS('QofE DD adjustments'!L:L,'QofE DD adjustments'!$E:$E,'Adjusted IS'!$E13) | FA13: =SUMIFS('QofE DD adjustments'!M:M,'QofE DD adjustments'!$E:$E,'Adjusted IS'!$E13) | FB13: =SUMIFS('QofE DD adjustments'!N:N,'QofE DD adjustments'!$E:$E,'Adjusted IS'!$E13) | FC13: =SUMIFS('QofE DD adjustments'!O:O,'QofE DD adjustments'!$E:$E,'Adjusted IS'!$E13) | FD13: =SUMIFS('QofE DD adjustments'!P:P,'QofE DD adjustments'!$E:$E,'Adjusted IS'!$E13) | FE13: =SUMIFS('QofE DD adjustments'!Q:Q,'QofE DD adjustments'!$E:$E,'Adjusted IS'!$E13) | FF13: =SUMIFS('QofE DD adjustments'!R:R,'QofE DD adjustments'!$E:$E,'Adjusted IS'!$E13) | FG13: =SUMIFS('QofE DD adjustments'!S:S,'QofE DD adjustments'!$E:$E,'Adjusted IS'!$E13) | FH13: =SUMIFS('QofE DD adjustments'!T:T,'QofE DD adjustments'!$E:$E,'Adjusted IS'!$E13) | FI13: =SUMIFS('QofE DD adjustments'!U:U,'QofE DD adjustments'!$E:$E,'Adjusted IS'!$E13) | FJ13: =SUMIFS('QofE DD adjustments'!V:V,'QofE DD adjustments'!$E:$E,'Adjusted IS'!$E13) | FK13: =SUMIFS('QofE DD adjustments'!W:W,'QofE DD adjustments'!$E:$E,'Adjusted IS'!$E13) | FL13: =SUMIFS('QofE DD adjustments'!X:X,'QofE DD adjustments'!$E:$E,'Adjusted IS'!$E13) | FM13: =SUMIFS('QofE DD adjustments'!Y:Y,'QofE DD adjustments'!$E:$E,'Adjusted IS'!$E13) | FN13: =SUMIFS('QofE DD adjustments'!Z:Z,'QofE DD adjustments'!$E:$E,'Adjusted IS'!$E13) | FO13: =SUMIFS('QofE DD adjustments'!AA:AA,'QofE DD adjustments'!$E:$E,'Adjusted IS'!$E13) | FP13: =SUMIFS('QofE DD adjustments'!AB:AB,'QofE DD adjustments'!$E:$E,'Adjusted IS'!$E13) | FQ13: =SUMIFS('QofE DD adjustments'!AC:AC,'QofE DD adjustments'!$E:$E,'Adjusted IS'!$E13) | FR13: =SUMIFS('QofE DD adjustments'!AD:AD,'QofE DD adjustments'!$E:$E,'Adjusted IS'!$E13) | FS13: =SUMIFS('QofE DD adjustments'!AE:AE,'QofE DD adjustments'!$E:$E,'Adjusted IS'!$E13) | FT13: =SUMIFS('QofE DD adjustments'!AF:AF,'QofE DD adjustments'!$E:$E,'Adjusted IS'!$E13) | FU13: =SUMIFS('QofE DD adjustments'!AG:AG,'QofE DD adjustments'!$E:$E,'Adjusted IS'!$E13) | FV13: =SUMIFS('QofE DD adjustments'!AH:AH,'QofE DD adjustments'!$E:$E,'Adjusted IS'!$E13) | FW13: =SUMIFS('QofE DD adjustments'!AI:AI,'QofE DD adjustments'!$E:$E,'Adjusted IS'!$E13) | FX13: =SUMIFS('QofE DD adjustments'!AJ:AJ,'QofE DD adjustments'!$E:$E,'Adjusted IS'!$E13) | FY13: =SUMIFS('QofE DD adjustments'!AK:AK,'QofE DD adjustments'!$E:$E,'Adjusted IS'!$E13) | FZ13: =SUMIFS('QofE DD adjustments'!AL:AL,'QofE DD adjustments'!$E:$E,'Adjusted IS'!$E13) | GA13: =SUMIFS('QofE DD adjustments'!AM:AM,'QofE DD adjustments'!$E:$E,'Adjusted IS'!$E13) | GB13: =SUMIFS('QofE DD adjustments'!AN:AN,'QofE DD adjustments'!$E:$E,'Adjusted IS'!$E13) | GC13: =SUMIFS('QofE DD adjustments'!AO:AO,'QofE DD adjustments'!$E:$E,'Adjusted IS'!$E13) | GD13: =SUMIFS('QofE DD adjustments'!AP:AP,'QofE DD adjustments'!$E:$E,'Adjusted IS'!$E13) | GE13: =SUMIFS('QofE DD adjustments'!AQ:AQ,'QofE DD adjustments'!$E:$E,'Adjusted IS'!$E13) | GF13: =SUMIFS('QofE DD adjustments'!AR:AR,'QofE DD adjustments'!$E:$E,'Adjusted IS'!$E13) | GG13: =SUMIFS('QofE DD adjustments'!AS:AS,'QofE DD adjustments'!$E:$E,'Adjusted IS'!$E13) | GH13: =SUMIFS('QofE DD adjustments'!AT:AT,'QofE DD adjustments'!$E:$E,'Adjusted IS'!$E13) | GI13: =SUMIFS('QofE DD adjustments'!AU:AU,'QofE DD adjustments'!$E:$E,'Adjusted IS'!$E13) | GJ13: =SUM(ET13:FE13) | GK13: =SUM(FF13:FQ13) | GL13: =SUM(FR13:GC13) | GM13: =SUM(FV13:GG13) | GN13: =SUM(FX13:GI13) | GP13: =SUM(ET13,CX13) | GQ13: =SUM(EU13,CY13) | GR13: =SUM(EV13,CZ13) | GS13: =SUM(EW13,DA13) | GT13: =SUM(EX13,DB13) | GU13: =SUM(EY13,DC13) | GV13: =SUM(EZ13,DD13) | GW13: =SUM(FA13,DE13) | ... IE13: =SUM(GI13,EM13) | IF13: =SUM(GP13:HA13) | IG13: =SUM(HB13:HM13) | IH13: =SUM(HN13:HY13) | II13: =SUM(HR13:IC13) | IJ13: =SUM(HT13:IE13) | IL13: =SUMIFS('QofE PF adjustments'!F:F,'QofE PF adjustments'!$E:$E,'Adjusted IS'!$E13) | IM13: =SUMIFS('QofE PF adjustments'!G:G,'QofE PF adjustments'!$E:$E,'Adjusted IS'!$E13) | IN13: =SUMIFS('QofE PF adjustments'!H:H,'QofE PF adjustments'!$E:$E,'Adjusted IS'!$E13) | IO13: =SUMIFS('QofE PF adjustments'!I:I,'QofE PF adjustments'!$E:$E,'Adjusted IS'!$E13) | IP13: =SUMIFS('QofE PF adjustments'!J:J,'QofE PF adjustments'!$E:$E,'Adjusted IS'!$E13) | IQ13: =SUMIFS('QofE PF adjustments'!K:K,'QofE PF adjustments'!$E:$E,'Adjusted IS'!$E13) | IR13: =SUMIFS('QofE PF adjustments'!L:L,'QofE PF adjustments'!$E:$E,'Adjusted IS'!$E13) | IS13: =SUMIFS('QofE PF adjustments'!M:M,'QofE PF adjustments'!$E:$E,'Adjusted IS'!$E13) | IT13: =SUMIFS('QofE PF adjustments'!N:N,'QofE PF adjustments'!$E:$E,'Adjusted IS'!$E13) | IU13: =SUMIFS('QofE PF adjustments'!O:O,'QofE PF adjustments'!$E:$E,'Adjusted IS'!$E13) | IV13: =SUMIFS('QofE PF adjustments'!P:P,'QofE PF adjustments'!$E:$E,'Adjusted IS'!$E13) | IW13: =SUMIFS('QofE PF adjustments'!Q:Q,'QofE PF adjustments'!$E:$E,'Adjusted IS'!$E13) | IX13: =SUMIFS('QofE PF adjustments'!R:R,'QofE PF adjustments'!$E:$E,'Adjusted IS'!$E13) | IY13: =SUMIFS('QofE PF adjustments'!S:S,'QofE PF adjustments'!$E:$E,'Adjusted IS'!$E13) | IZ13: =SUMIFS('QofE PF adjustments'!T:T,'QofE PF adjustments'!$E:$E,'Adjusted IS'!$E13) | JA13: =SUMIFS('QofE PF adjustments'!U:U,'QofE PF adjustments'!$E:$E,'Adjusted IS'!$E13) | JB13: =SUMIFS('QofE PF adjustments'!V:V,'QofE PF adjustments'!$E:$E,'Adjusted IS'!$E13) | JC13: =SUMIFS('QofE PF adjustments'!W:W,'QofE PF adjustments'!$E:$E,'Adjusted IS'!$E13) | JD13: =SUMIFS('QofE PF adjustments'!X:X,'QofE PF adjustments'!$E:$E,'Adjusted IS'!$E13) | JE13: =SUMIFS('QofE PF adjustments'!Y:Y,'QofE PF adjustments'!$E:$E,'Adjusted IS'!$E13) | JF13: =SUMIFS('QofE PF adjustments'!Z:Z,'QofE PF adjustments'!$E:$E,'Adjusted IS'!$E13) | JG13: =SUMIFS('QofE PF adjustments'!AA:AA,'QofE PF adjustments'!$E:$E,'Adjusted IS'!$E13) | JH13: =SUMIFS('QofE PF adjustments'!AB:AB,'QofE PF adjustments'!$E:$E,'Adjusted IS'!$E13) | JI13: =SUMIFS('QofE PF adjustments'!AC:AC,'QofE PF adjustments'!$E:$E,'Adjusted IS'!$E13) | JJ13: =SUMIFS('QofE PF adjustments'!AD:AD,'QofE PF adjustments'!$E:$E,'Adjusted IS'!$E13) | JK13: =SUMIFS('QofE PF adjustments'!AE:AE,'QofE PF adjustments'!$E:$E,'Adjusted IS'!$E13) | JL13: =SUMIFS('QofE PF adjustments'!AF:AF,'QofE PF adjustments'!$E:$E,'Adjusted IS'!$E13) | JM13: =SUMIFS('QofE PF adjustments'!AG:AG,'QofE PF adjustments'!$E:$E,'Adjusted IS'!$E13) | JN13: =SUMIFS('QofE PF adjustments'!AH:AH,'QofE PF adjustments'!$E:$E,'Adjusted IS'!$E13) | JO13: =SUMIFS('QofE PF adjustments'!AI:AI,'QofE PF adjustments'!$E:$E,'Adjusted IS'!$E13) | JP13: =SUMIFS('QofE PF adjustments'!AJ:AJ,'QofE PF adjustments'!$E:$E,'Adjusted IS'!$E13) | JQ13: =SUMIFS('QofE PF adjustments'!AK:AK,'QofE PF adjustments'!$E:$E,'Adjusted IS'!$E13) | JR13: =SUMIFS('QofE PF adjustments'!AL:AL,'QofE PF adjustments'!$E:$E,'Adjusted IS'!$E13) | JS13: =SUMIFS('QofE PF adjustments'!AM:AM,'QofE PF adjustments'!$E:$E,'Adjusted IS'!$E13) | JT13: =SUMIFS('QofE PF adjustments'!AN:AN,'QofE PF adjustments'!$E:$E,'Adjusted IS'!$E13) | JU13: =SUMIFS('QofE PF adjustments'!AO:AO,'QofE PF adjustments'!$E:$E,'Adjusted IS'!$E13) | JV13: =SUMIFS('QofE PF adjustments'!AP:AP,'QofE PF adjustments'!$E:$E,'Adjusted IS'!$E13) | JW13: =SUMIFS('QofE PF adjustments'!AQ:AQ,'QofE PF adjustments'!$E:$E,'Adjusted IS'!$E13) | JX13: =SUMIFS('QofE PF adjustments'!AR:AR,'QofE PF adjustments'!$E:$E,'Adjusted IS'!$E13) | JY13: =SUMIFS('QofE PF adjustments'!AS:AS,'QofE PF adjustments'!$E:$E,'Adjusted IS'!$E13) | JZ13: =SUMIFS('QofE PF adjustments'!AT:AT,'QofE PF adjustments'!$E:$E,'Adjusted IS'!$E13) | KA13: =SUMIFS('QofE PF adjustments'!AU:AU,'QofE PF adjustments'!$E:$E,'Adjusted IS'!$E13) | KB13: =SUM(IL13:IW13) | KC13: =SUM(IX13:JI13) | KD13: =SUM(JJ13:JU13) | KE13: =SUM(JN13:JY13) | KF13: =SUM(JP13:KA13) | KH13: =SUM(IL13,GP13) | KI13: =SUM(IM13,GQ13) | KJ13: =SUM(IN13,GR13) | KK13: =SUM(IO13,GS13) | KL13: =SUM(IP13,GT13) | KM13: =SUM(IQ13,GU13) | KN13: =SUM(IR13,GV13) | KO13: =SUM(IS13,GW13) | ... LW13: =SUM(KA13,IE13) | LX13: =SUM(KH13:KS13) | LY13: =SUM(KT13:LE13) | LZ13: =SUM(LF13:LQ13) | MA13: =SUM(LJ13:LU13) | MB13: =SUM(LL13:LW13) | MD13: =IFERROR(KH13/KH$117,0) | ME13: =IFERROR(KI13/KI$117,0) | MF13: =IFERROR(KJ13/KJ$117,0) | MG13: =IFERROR(KK13/KK$117,0) | MH13: =IFERROR(KL13/KL$117,0) | MI13: =IFERROR(KM13/KM$117,0) | MJ13: =IFERROR(KN13/KN$117,0) | MK13: =IFERROR(KO13/KO$117,0) | ... NX13: =IFERROR(MB13/MB$117,0) | NZ13: =LY13-LX13 | OA13: =LZ13-LY13 | OB13: =MA13-LZ13 | OC13: =MB13-LZ13 | OE13: Processing services revenue | OF13: Processing services revenue | OG13: Processing services revenue
