Workbook

Sheet Key information
C2: Fill in all input areas identified in yellow. Do not change any other field!
B5: 1 | C5: Project information | L5: Instructions
C7: Project name: | E7: Project Test | L7: Type as "Project [xxx]"
C9: Client name: | E9: Client Oy | L9: Insert the Client's official business name
C11: Target name: | E11: Target Oy | L11: Insert the Target's official business name
C13: Engagement partner: | L13: Select the engagement partner from the drop-down list
C15: Engagement manager: | L15: Select the engagement manager from the drop-down list
C17: Engagement letter date: | E17: 2 January 2023 | L17: e.g. '3 August 2021
C19: Report date: | E19: 23 January 2023 | L19: e.g. '10 August 2021
C21: Type of project: | E21: Financial due diligence | L21: e.g. Financial due diligence
C23: Databook form: | E23: DRAFT | L23: Leave blank for final
B26: 2 | C26: Periods under analysis
C28: 1st month-end of the period: | E28: 43861 | L28: e.g. 31/01/2019
C30: Financial year end: | E30: 31 December | L30: e.g. '31 December
C32: Last month (in text): | E32: 30 Nobember 2022 | L32: e.g. '31 July 2021
C34: YTD period (months): | E34: 11 | L34: e.g. January = 1, February = 2, etc.
E36: 1st year | F36: 2nd year | G36: LTM period | H36: Budget/FC
C37: P&L periods | E37: =IF($E$79=1,"FY"&YEAR($E$28)-2000,"FY"&YEAR($E$28)-2000&"/"&YEAR($E$28)-1999) -> FY20 | F37: =IF($E$79=1,"FY"&YEAR($E$28)-1999,"FY"&YEAR($E$28)-1999&"/"&YEAR($E$28)-1998) -> FY21 | G37: =IF(E34=12,IF($E$79=1,"FY"&YEAR($E$28)-1998,"FY"&YEAR($E$28)-1998&"/"&YEAR($E$28)-1997),"LTM "&VLOOKUP(F79,$E$82:$F$103,2)&"-"&G39-2000) -> LTM Nov-22 | H37: =IF(E34=12,IF($E$79=1,"FY"&YEAR($E$28)-1997&"B","FY"&YEAR($E$28)-1997&"/"&YEAR($E$28)-1996&"B"),IF($E$79=1,"FY"&YEAR(E28)-1998&"LE","FY"&YEAR($E$28)-1998&"/"&YEAR(E28)-1997&"LE")) -> FY22LE | L37: These will be used as labels in all the tables - change manually only if needed / wrong
E38: =E37 -> FY20 | F38: =F37 -> FY21 | G38: =IF($E$79=1,"FY"&YEAR($E$28)-1998,"FY"&YEAR($E$28)-1998&"/"&YEAR($E$28)-1997) -> FY22
E39: =YEAR(E28) -> 2020 | F39: =E39+1 -> 2021 | G39: =IF(F79>12,F39+2,F39+1) -> 2022
C41: YTD periods | E41: =IF($E$34=12,"n/a",IF($E$79=1,"YTD "&VLOOKUP($E$34,$E$82:$F$103,2)&"-"&YEAR($E$28)-2000,IF($E$34+$E$79>13,"YTD "&VLOOKUP($F$79,$E$82:$F$103,2)&"-"&YEAR($E$28)-1999,"YTD "&VLOOKUP($F$79,$E$82:$F$103,2)&"-"&YEAR($E$28)-2000))) -> YTD Nov-20 | F41: =IF($E$34=12,"n/a",IF($E$79=1,"YTD "&VLOOKUP($E$34,$E$82:$F$103,2)&"-"&YEAR($E$28)-1999,IF($E$34+$E$79>13,"YTD "&VLOOKUP($F$79,$E$82:$F$103,2)&"-"&YEAR($E$28)-1998,"YTD "&VLOOKUP($F$79,$E$82:$F$103,2)&"-"&YEAR($E$28)-1999))) -> YTD Nov-21 | G41: =IF($E$34=12,"n/a",IF($E$79=1,"YTD "&VLOOKUP($E$34,$E$82:$F$103,2)&"-"&YEAR($E$28)-1998,IF($E$34+$E$79>13,"YTD "&VLOOKUP($F$79,$E$82:$F$103,2)&"-"&YEAR($E$28)-1997,"YTD "&VLOOKUP($F$79,$E$82:$F$103,2)&"-"&YEAR($E$28)-1998))) -> YTD Nov-22
C43: Balance sheet periods | E43: =EOMONTH(E28,11) -> 44196 | F43: =EOMONTH(E43,12) -> 44561 | G43: =EOMONTH(F43,E34) -> 44895
B46: 3 | C46: Currency & measure of unit
C48: Preferred currency: | E48: EUR | F48: Format in tables | L48: e.g. EUR - always use the three letter format
C50: Preferred format in tables: | E50: thousands | F50: =IF(E48="EUR",G119,E48&G120) -> €'000 | G50: change if incorrect | L50: choose from the drop-down list
C52: Source data format: | E52: full value | L52: choose from the drop-down list
C54: Equity / liabilities in the source data: | E54: Positive figures | L54: choose from the drop-down list
B57: 4 | C57: Table headings (if needed)
C59: Table heading (leave empty if not needed) | L59: This is used in the table headings - e.g. Group, consolidated
C71: Input --> DO NOT DELETE
C72: Engagement partner | E72: =VLOOKUP($E$13,$C$142:$G$203,3,FALSE) -> #N/A | F72: =VLOOKUP($E$13,$C$142:$G$203,4,FALSE) -> #N/A | G72: =VLOOKUP($E$13,$C$142:$G$203,5,FALSE) -> #N/A
C73: Engagement manager | E73: =VLOOKUP($E$15,$C$142:$G$203,3,FALSE) -> #N/A | F73: =VLOOKUP($E$15,$C$142:$G$203,4,FALSE) -> #N/A | G73: =VLOOKUP($E$15,$C$142:$G$203,5,FALSE) -> #N/A
C75: Input --> DO NOT DELETE
C76: LTM period | E76: =IF(E34=12,IF($E$79=1,"FY"&YEAR($E$28)-1998,"FY"&YEAR($E$28)-1998&"/"&YEAR($E$28)-1997),"LTM "&VLOOKUP(F79,$E$82:$F$103,2)&"-"&G39-2000) -> LTM Nov-22
C78: Input --> DO NOT DELETE
C79: First month | E79: =MONTH(E28) -> 1 | F79: =E79+E34-1 -> 11
C81: Input --> DO NOT DELETE
E82: 1 | F82: Jan | G82: FY17 | H82: 17
E83: =+E82+1 -> 2 | F83: Feb | G83: FY18 | H83: 18
E84: =+E83+1 -> 3 | F84: Mar | G84: FY19 | H84: 19
...

Sheet Cover
B8: ='Key information'!E7 -> Project Test
B12: =IF('Key information'!E23="","",'Key information'!E23) -> DRAFT
B20: ='Key information'!E21 -> Financial due diligence
B21: =TODAY() -> 45575
B23: Deal Advisory, Transaction Services

Sheet Table of Contents
A1: ='Key information'!E7 -> Project Test
B3: Table of contents
B4: Link to tabs | C4: Description
B5: Key information | C5: Key information sheet - Delete before sending!
B6: Disclaimer | C6: Disclaimer - to be included when sending to a client!
B7: Summary >>
B8: Highlights | C8: Highlight tables to be used on Business overview/SIPOC page
B9: PL_monthly | C9: Monthly Profit and loss data and summary P&L table
B10: BS_monthly | C10: Monthly Balance sheet data and summary BS table
B11: QoE | C11: Quality of Earnings analysis
B12: PL adj | C12: Adjusted P&L table
B13: Current trading | C13: Current trading and run rate analysis
B14: NWC overview | C14: Net working capital monthly data and summary table
B15: NWC adj | C15: Adjusted monthly NWC and key metrics
B16: Net debt | C16: Net debt analysis
B17: Rec >>
B18: PL rec | C18: Profit and loss reconciliation table
B19: BS rec | C19: Balance sheet reconciliation table
B20: Supporting analysis >>
B21: Seasonality | C21: Seasonality of net sales and EBITDA
B22: Top customers | C22: Top customers analysis
B23: Cost base | C23: Cost breakdown
B24: Personnel | C24: Personnel costs and personnel-related KPIs
B25: Top suppliers | C25: Top suppliers analysis
B26: Op. cash flows | C26: Operating cash flow, reported and adjusted
B27: PL templates >>
B28: PL_FC | C28: P&L forecast summary table
B29: Net sales bridge | C29: Net sales bridge
B30: EBITDA bridge | C30: EBITDA bridge
B31: Net sales by type | C31: Net sales breakdown - by type
B32: Net sales by region | C32: Net sales breakdown - by region
B33: Related parties | C33: Summary of related party transactions and balances
B34: BS templates >>
B35: BS_net assets | C35: Net assets form of balance sheet
B36: NWC - days analysis | C36: NWC days analysis (DSO, DIO, DPO)
B37: Inventories | C37: Breakdown of inventories
B38: AR | C38: Accounts receivable ageing analysis
B39: AP | C39: Accounts payable ageing analysis
B40: Fixed assets | C40: Fixed assets breakdown
B41: Capex | C41: Capital expenditure by type
...

Sheet _TM_Table of Contents
A1: Left | B1: Top | C1: Right | D1: Bottom | E1: Ref
A2: 2 | B2: 2 | C2: 3 | D2: 37 | E2: $B$2:$C$37
A3: 6 | B3: 3 | C3: 6 | D3: 3 | E3: $F$3

Sheet _TM_Disclaimer1
A1: Left | B1: Top | C1: Right | D1: Bottom | E1: Ref
A2: 2 | B2: 2 | C2: 2 | D2: 32 | E2: $B$2:$B$32

Sheet Disclaimer
B2: Notice and disclaimer
C4: Context and scope of work
C6: ="This Excel Data Book is provided to "&'Key information'!E9&" ('the Client') pursuant to our engagement letter and is subject in all respects to the terms and conditions of that engagement letter dated "&'Key information'!E17&", including restrictions on disclosure of this to third parties." -> This Excel Data Book is provided to Client Oy ('the Client') pursuant to our engagement letter and is subject in all respects to the terms and conditions of that engagement letter dated 2 January 2023, including restrictions on disclosure of this to third parties.
C8: ="Our Excel Data Book has focused on the limited analysis on "&'Key information'!E11&" ('Target') for financial years ended "&'Key information'!E30&" "&'Key information'!E39&" and "&'Key information'!F39&" ('"&'Key information'!E37&"' and '"&'Key information'!F37&"') and the last twelve months ended "&'Key information'!E32&" ('"&'Key information'!E76&"')." -> Our Excel Data Book has focused on the limited analysis on Target Oy ('Target') for financial years ended 31 December 2020 and 2021 ('FY20' and 'FY21') and the last twelve months ended 30 Nobember 2022 ('LTM Nov-22').
C10: This Excel Data Book is being provided to Client on a confidential basis and may not be disclosed to any other person or entity without the express written consent of KPMG and Client. KPMG neither warrants nor represents that the information contained in this report is accurate, complete, sufficient or appropriate for use by any person or entity other than Client or for any purpose other than set out in the Engagement Letter. This Excel Data Book may not be relied upon by any person or entity other than Client, and KPMG hereby expressly disclaims any and all responsibility or liability to any person or entity other than Client in connection with their use of this Excel Data Book and corresponding report.
C12: ="This Excel Data Book is to be used in conjunction with the "&'Key information'!E21&" report dated "&'Key information'!E19&". We have no obligation to update the Excel Data Book or to revise the information contained herein to reflect events and transactions occurring subsequent to "&'Key information'!E19&"." -> This Excel Data Book is to be used in conjunction with the Financial due diligence report dated 23 January 2023. We have no obligation to update the Excel Data Book or to revise the information contained herein to reflect events and transactions occurring subsequent to 23 January 2023.
C14: Sources of information
C16: In preparing the Excel Data Book, our primary source has been Target management information and representations made to us by the management. We do not accept responsibility for such information which remains the responsibility of management. Details of our principal information sources are set out in the report and we have satisfied ourselves, so far as possible, that the information presented in the Excel Data Book is consistent with other information which was made available to us in the course of our work in accordance with the terms of our Engagement Letter. We have not, however, sought to establish the reliability of the sources by reference to other evidence.
C18: This engagement is not an assurance engagement conducted in accordance with any generally accepted assurance standards and consequently no assurance opinion is expressed.
C20: Our Quality of earnings analysis is for indicative purposes only. We have sought to illustrate the effect on EBITDA of adjusting for those items identified in the course of our work in accordance with the terms of our engagement letter we consider to be "non-recurring" or "exceptional" or otherwise unrepresentative of the trend in EBITDA; however such analysis is necessarily subjective. Because there is no authoritative literature or common standard with respect to the calculation of ‘adjusted’ earnings, there is no basis to state whether all appropriate and comparable adjustments have been made. In addition, while the adjustments may indeed relate to items which are 'non-recurring' or 'exceptional' or otherwise unrepresentative of the trend, it is possible that earnings for future periods may be affected by such items, which may be different from the historical items.
C22: The last twelve months/LTM run rate analysis has been prepared for illustrative purposes. There is no authoritative literature or common standard with respect to the calculation of 'run rate' EBITDA, and therefore there is no basis on which to state whether, in the illustrative analysis of 'run rate‘ EBITDA, all appropriate and comparable adjustments have been made. We have set out in our report the basis on which items have been included in or excluded from the run rate calculations for particular years. It is for you to satisfy yourselves as to whether the items included or excluded are appropriate for your purposes. The decision as to what items should be included in or excluded from the calculation of 'run rate' EBITDA is highly judgemental; you may choose to interpret the information presented differently.
C24: We must emphasize that the realisation of the prospective financial information set out within our report is dependent on the continuing validity of the assumptions on which it is based. The assumptions will need to be reviewed and revised to reflect such changes in trading patterns, cost structures or the direction of the business as emerge. We accept no responsibility for the realization of the prospective financial information. Actual results are likely to be different from those shown in the prospective financial information because events and circumstances frequently do not occur as expected, and the differences may be material.

Sheet _TM_Glossary
A1: Left | B1: Top | C1: Right | D1: Bottom | E1: Ref
A2: 2 | B2: 21 | C2: 7 | D2: 35 | E2: $B$21:$G$35
A3: 9 | B3: 5 | C3: 9 | D3: 5 | E3: $I$5

Sheet Summary >>
C15: Summary
C21: ='Key information'!E7 -> Project Test
C26: PRIVATE AND CONFIDENTIAL

Sheet _TM_Dashboard_data
A1: Left | B1: Top | C1: Right | D1: Bottom | E1: Ref
A2: 2 | B2: 7 | C2: 5 | D2: 13 | E2: $B$7:$E$13
A3: 7 | B3: 7 | C3: 10 | D3: 15 | E3: $G$7:$J$15
A4: 12 | B4: 7 | C4: 15 | D4: 15 | E4: $L$7:$O$15
A5: 17 | B5: 7 | C5: 20 | D5: 15 | E5: $Q$7:$T$15
A6: 2 | B6: 17 | C6: 15 | D6: 22 | E6: $B$17:$O$22
A7: 22 | B7: 7 | C7: 22 | D7: 7 | E7: $V$7

Sheet _TM_Highlights
A1: Left | B1: Top | C1: Right | D1: Bottom | E1: Ref
A2: 2 | B2: 6 | C2: 5 | D2: 14 | E2: $B$6:$E$14
A3: 14 | B3: 6 | C3: 17 | D3: 13 | E3: $N$6:$Q$13
A4: 14 | B4: 16 | C4: 17 | D4: 22 | E4: $N$16:$Q$22
A5: 19 | B5: 6 | C5: 19 | D5: 6 | E5: $S$6

Sheet Highlights
B1: ='Key information'!E7 -> Project Test
B2: Summary tables
B3: Source: Management accounts, Management information, KPMG analysis
B9: QoE: | C9: =IF('Key information'!E48="EUR","€m",'Key information'!E48&"m") -> €m | D9: ='Key information'!E37 -> FY20 | E9: ='Key information'!F37 -> FY21 | F9: ='Key information'!G37 -> LTM Nov-22
C10: Net sales, reported | D10: =PL_monthly!AN15/'Key information'!$H$108 -> 0 | E10: =PL_monthly!AO15/'Key information'!$H$108 -> 0 | F10: =PL_monthly!AP15/'Key information'!$H$108 -> 0
C11: Adjustments | D11: =QoE!AO15/'Key information'!$H$108 -> 0 | E11: =QoE!AP15/'Key information'!$H$108 -> 0 | F11: =QoE!AQ15/'Key information'!$H$108 -> 0
C12: Net sales, adjusted | D12: =D10+D11 -> 0 | E12: =E10+E11 -> 0 | F12: =F10+F11 -> 0
C13: EBITDA, reported | D13: =PL_monthly!AN50/'Key information'!$H$108 -> 0 | E13: =PL_monthly!AO50/'Key information'!$H$108 -> 0 | F13: =PL_monthly!AP50/'Key information'!$H$108 -> 0
C14: Adjustments | D14: =(QoE!AO20+QoE!AO28)/'Key information'!$H$108 -> 0 | E14: =(QoE!AP20+QoE!AP28)/'Key information'!$H$108 -> 0 | F14: =(QoE!AQ20+QoE!AQ28)/'Key information'!$H$108 -> 0
C15: EBITDA, adjusted | D15: =D13+D14 -> 0 | E15: =E13+E14 -> 0 | F15: =F13+F14 -> 0
C17: Key performance indicators
C18: EBITDA margin, reported | D18: =IFERROR(D13/#REF!,0) -> 0 | E18: =IFERROR(E13/#REF!,0) -> 0 | F18: =IFERROR(F13/#REF!,0) -> 0
C19: EBITDA margin, adjusted | D19: =IFERROR(D15/D12,0) -> 0 | E19: =IFERROR(E15/E12,0) -> 0 | F19: =IFERROR(F15/F12,0) -> 0
B22: NWC: | C22: =C9 -> €m | D22: =D9 -> FY20 | E22: =E9 -> FY21 | F22: =F9 -> LTM Nov-22
C23: Year-end | D23: ='NWC adj'!D34/'Key information'!$H$108 -> 0 | E23: ='NWC adj'!E34/'Key information'!$H$108 -> 0 | F23: ='NWC adj'!F34/'Key information'!$H$108 -> 0
C24: Average | D24: ='NWC adj'!D32/'Key information'!$H$108 -> 0 | E24: ='NWC adj'!E32/'Key information'!$H$108 -> 0 | F24: ='NWC adj'!F32/'Key information'!$H$108 -> 0
C25: Minimum | D25: ='NWC adj'!D30/'Key information'!$H$108 -> 0 | E25: ='NWC adj'!E30/'Key information'!$H$108 -> 0 | F25: ='NWC adj'!F30/'Key information'!$H$108 -> 0
C26: Maximum | D26: ='NWC adj'!D31/'Key information'!$H$108 -> 0 | E26: ='NWC adj'!E31/'Key information'!$H$108 -> 0 | F26: ='NWC adj'!F31/'Key information'!$H$108 -> 0
C28: Key performance indicators
C29: Year-end, % of net sales | D29: ='NWC overview'!AO41 -> 0 | E29: ='NWC overview'!AP41 -> 0 | F29: ='NWC overview'!AQ41 -> 0
C30: Average, % of net sales | D30: ='NWC overview'!AR41 -> 0 | E30: ='NWC overview'!AS41 -> 0 | F30: ='NWC overview'!AT41 -> 0 | J30: The tables below need to be manually filled/linked to source data. The charts will be ↓↓↓ drawn based on the data in the tables. ↓↓↓
C31: Min-max variance (€m) | D31: =D26-D25 -> 0 | E31: =E26-E25 -> 0 | F31: =F26-F25 -> 0
B34: ND: | C34: =C9 -> €m | D34: =D9 -> FY20 | E34: =E9 -> FY21 | F34: =F9 -> LTM Nov-22 | J34: ="Net sales by location"&IF('Key information'!E59="",""," - "&'Key information'!E59) -> Net sales by location
C35: Cash | D35: ='Net debt'!AO10/'Key information'!$H$108 -> 0 | E35: ='Net debt'!AP10/'Key information'!$H$108 -> 0 | F35: ='Net debt'!AQ10/'Key information'!$H$108 -> 0 | J35: =+C9 -> €m | K35: =+F9 -> LTM Nov-22 | R35: =[1]Highlights!F83 -> Largest | S35: =[1]Highlights!F84 -> Top 5 | T35: =[1]Highlights!F85 -> Top 10 | U35: =[1]Highlights!F86 -> Top 15 | V35: =[1]Highlights!F87 -> Top 20
C36: Loan receivables | D36: ='Net debt'!AO12/'Key information'!$H$108 -> 0 | E36: ='Net debt'!AP12/'Key information'!$H$108 -> 0 | F36: ='Net debt'!AQ12/'Key information'!$H$108 -> 0
C37: Other receivables | D37: ='Net debt'!AO11/'Key information'!$H$108 -> 0 | E37: ='Net debt'!AP11/'Key information'!$H$108 -> 0 | F37: ='Net debt'!AQ11/'Key information'!$H$108 -> 0 | J37: Location1 | K37: 200 | R37: =[1]Highlights!G83 -> 0.1 | S37: =[1]Highlights!G84 -> 0.18 | T37: =[1]Highlights!G85 -> 0.22 | U37: =[1]Highlights!G86 -> 0.25 | V37: =[1]Highlights!G87 -> 0.27
C38: Interest-bearing loans, short-term | D38: =('Net debt'!AO13+'Net debt'!AO15+'Net debt'!AO17)/'Key information'!$H$108 -> 0 | E38: =('Net debt'!AP13+'Net debt'!AP15+'Net debt'!AP17)/'Key information'!$H$108 -> 0 | F38: =('Net debt'!AQ13+'Net debt'!AQ15+'Net debt'!AQ17)/'Key information'!$H$108 -> 0 | J38: Location2 | K38: 180
C39: Interest-bearing loans, long-term | D39: =('Net debt'!AO14+'Net debt'!AO16+'Net debt'!AO18+'Net debt'!AO19)/'Key information'!$H$108 -> 0 | E39: =('Net debt'!AP14+'Net debt'!AP16+'Net debt'!AP18+'Net debt'!AP19)/'Key information'!$H$108 -> 0 | F39: =('Net debt'!AQ14+'Net debt'!AQ16+'Net debt'!AQ18+'Net debt'!AQ19)/'Key information'!$H$108 -> 0 | J39: Location3 | K39: 150
C40: ='Net debt'!C20 -> Net cash, reported | D40: =SUM(D35:D39) -> 0 | E40: =SUM(E35:E39) -> 0 | F40: =SUM(F35:F39) -> 0 | J40: Location4 | K40: 100
C41: Adjustments | D41: =SUM('Net debt'!AO25,'Net debt'!AO31)/'Key information'!$H$108 -> 0 | E41: =SUM('Net debt'!AP25,'Net debt'!AP31)/'Key information'!$H$108 -> 0 | F41: =SUM('Net debt'!AQ25,'Net debt'!AQ31)/'Key information'!$H$108 -> 0 | J41: Location5 | K41: 40
C42: ='Net debt'!C32 -> Net cash, adjusted | D42: =D40+D41 -> 0 | E42: =E40+E41 -> 0 | F42: =F40+F41 -> 0 | J42: Total | K42: =SUM(K37:K41) -> 670
J44: ="Net sales by type"&IF('Key information'!E59="",""," - "&'Key information'!E59) -> Net sales by type
J45: =C9 -> €m | K45: =+F9 -> LTM Nov-22
J47: Type1 | K47: 300
J48: Type2 | K48: 170
J49: Type3 | K49: 100
J50: Type4 | K50: 60
J51: Type5 | K51: 30
J52: Others | K52: =K53-SUM(K47:K51) -> 10
J53: Total | K53: =K42 -> 670

Sheet PL_monthly
B1: ='Key information'!E7 -> Project Test
B2: =C8 -> Profit and loss accounts
B3: =IF(AQ15=0,"Source: Management accounts, KPMG analysis","Source: Management accounts, Management forecast, KPMG analysis") -> Source: Management accounts, KPMG analysis
AX5: Materiality level: net sales, COGS | CK5: 100
AX6: Materiality level: other items | CK6: 15
C8: ="Profit and loss accounts"&IF('Key information'!E59="",""," - "&'Key information'!E59) -> Profit and loss accounts | AV8: Notes/questions | AX8: Trending calculations
B9: TAG | C9: ='Key information'!F50 -> €'000 | D9: ='Key information'!E28 -> 43861 | E9: =EOMONTH(D9,1) -> 43890 | F9: =EOMONTH(E9,1) -> 43921 | G9: =EOMONTH(F9,1) -> 43951 | H9: =EOMONTH(G9,1) -> 43982 | I9: =EOMONTH(H9,1) -> 44012 | J9: =EOMONTH(I9,1) -> 44043 | K9: =EOMONTH(J9,1) -> 44074 | L9: =EOMONTH(K9,1) -> 44104 | ... AM9: =EOMONTH(AL9,1) -> 44926 | AN9: ='Key information'!E37 -> FY20 | AO9: ='Key information'!F37 -> FY21 | AP9: ='Key information'!G37 -> LTM Nov-22 | AQ9: ='Key information'!H37 -> FY22LE | AS9: ='Key information'!F41 -> YTD Nov-21 | AT9: ='Key information'!G41 -> YTD Nov-22 | AX9: =C9 -> €'000 | AY9: =D9 -> 43861 | AZ9: =E9 -> 43890 | BA9: =F9 -> 43921 | BB9: =G9 -> 43951 | BC9: =H9 -> 43982 | BD9: =I9 -> 44012 | BE9: =J9 -> 44043 | ... CH9: =AM9 -> 44926 | CI9: Number of pos. items | CJ9: Number of neg. items | CK9: Number of flagged items
B10: SAL1 | C10: [Net sales account 1] | D10: =SUMIFS(PL!F:F,PL!$B:$B,$B10)/'Key information'!$E$114 -> 0 | E10: =SUMIFS(PL!G:G,PL!$B:$B,$B10)/'Key information'!$E$114 -> 0 | F10: =SUMIFS(PL!H:H,PL!$B:$B,$B10)/'Key information'!$E$114 -> 0 | G10: =SUMIFS(PL!I:I,PL!$B:$B,$B10)/'Key information'!$E$114 -> 0 | H10: =SUMIFS(PL!J:J,PL!$B:$B,$B10)/'Key information'!$E$114 -> 0 | I10: =SUMIFS(PL!K:K,PL!$B:$B,$B10)/'Key information'!$E$114 -> 0 | J10: =SUMIFS(PL!L:L,PL!$B:$B,$B10)/'Key information'!$E$114 -> 0 | K10: =SUMIFS(PL!M:M,PL!$B:$B,$B10)/'Key information'!$E$114 -> 0 | L10: =SUMIFS(PL!N:N,PL!$B:$B,$B10)/'Key information'!$E$114 -> 0 | M10: =SUMIFS(PL!O:O,PL!$B:$B,$B10)/'Key information'!$E$114 -> 0 | N10: =SUMIFS(PL!P:P,PL!$B:$B,$B10)/'Key information'!$E$114 -> 0 | O10: =SUMIFS(PL!Q:Q,PL!$B:$B,$B10)/'Key information'!$E$114 -> 0 | P10: =SUMIFS(PL!R:R,PL!$B:$B,$B10)/'Key information'!$E$114 -> 0 | Q10: =SUMIFS(PL!S:S,PL!$B:$B,$B10)/'Key information'!$E$114 -> 0 | R10: =SUMIFS(PL!T:T,PL!$B:$B,$B10)/'Key information'!$E$114 -> 0 | S10: =SUMIFS(PL!U:U,PL!$B:$B,$B10)/'Key information'!$E$114 -> 0 | T10: =SUMIFS(PL!V:V,PL!$B:$B,$B10)/'Key information'!$E$114 -> 0 | U10: =SUMIFS(PL!W:W,PL!$B:$B,$B10)/'Key information'!$E$114 -> 0 | V10: =SUMIFS(PL!X:X,PL!$B:$B,$B10)/'Key information'!$E$114 -> 0 | W10: =SUMIFS(PL!Y:Y,PL!$B:$B,$B10)/'Key information'!$E$114 -> 0 | X10: =SUMIFS(PL!Z:Z,PL!$B:$B,$B10)/'Key information'!$E$114 -> 0 | Y10: =SUMIFS(PL!AA:AA,PL!$B:$B,$B10)/'Key information'!$E$114 -> 0 | Z10: =SUMIFS(PL!AB:AB,PL!$B:$B,$B10)/'Key information'!$E$114 -> 0 | AA10: =SUMIFS(PL!AC:AC,PL!$B:$B,$B10)/'Key information'!$E$114 -> 0 | AB10: =SUMIFS(PL!AD:AD,PL!$B:$B,$B10)/'Key information'!$E$114 -> 0 | AC10: =SUMIFS(PL!AE:AE,PL!$B:$B,$B10)/'Key information'!$E$114 -> 0 | AD10: =SUMIFS(PL!AF:AF,PL!$B:$B,$B10)/'Key information'!$E$114 -> 0 | AE10: =SUMIFS(PL!AG:AG,PL!$B:$B,$B10)/'Key information'!$E$114 -> 0 | AF10: =SUMIFS(PL!AH:AH,PL!$B:$B,$B10)/'Key information'!$E$114 -> 0 | AG10: =SUMIFS(PL!AI:AI,PL!$B:$B,$B10)/'Key information'!$E$114 -> 0 | AH10: =SUMIFS(PL!AJ:AJ,PL!$B:$B,$B10)/'Key information'!$E$114 -> 0 | AI10: =SUMIFS(PL!AK:AK,PL!$B:$B,$B10)/'Key information'!$E$114 -> 0 | AJ10: =SUMIFS(PL!AL:AL,PL!$B:$B,$B10)/'Key information'!$E$114 -> 0 | AK10: =SUMIFS(PL!AM:AM,PL!$B:$B,$B10)/'Key information'!$E$114 -> 0 | AL10: =SUMIFS(PL!AN:AN,PL!$B:$B,$B10)/'Key information'!$E$114 -> 0 | AM10: =SUMIFS(PL!AO:AO,PL!$B:$B,$B10)/'Key information'!$E$114 -> 0 | AN10: =SUM(D10:O10) -> 0 | AO10: =SUM(P10:AA10) -> 0 | AP10: =SUM(OFFSET(AM10,0,(-12+'Key information'!$E$34)):OFFSET(AA10,0,(-11+'Key information'!$E$34))) -> 0 | AQ10: =SUMIF(PL!$B:$B,PL_monthly!B10,PL!$AP:$AP)/'Key information'!$E$114 -> 0 | AS10: =SUM(OFFSET(AA10,0,(-12+'Key information'!$E$34)):P10) -> 0 | AT10: =SUM(OFFSET(AM10,0,(-12+'Key information'!$E$34)):AB10) -> 0 | AX10: [Net sales account 1] | AY10: =IF(ABS(D10)>ABS(SUM($D10:$O10)/8),IF(ABS(D10)>=$CK$5,D10,0),0) -> 0 | AZ10: =IF(ABS(E10)>ABS(SUM($D10:$O10)/8),IF(ABS(E10)>=$CK$5,E10,0),0) -> 0 | BA10: =IF(ABS(F10)>ABS(SUM($D10:$O10)/8),IF(ABS(F10)>=$CK$5,F10,0),0) -> 0 | BB10: =IF(ABS(G10)>ABS(SUM($D10:$O10)/8),IF(ABS(G10)>=$CK$5,G10,0),0) -> 0 | BC10: =IF(ABS(H10)>ABS(SUM($D10:$O10)/8),IF(ABS(H10)>=$CK$5,H10,0),0) -> 0 | BD10: =IF(ABS(I10)>ABS(SUM($D10:$O10)/8),IF(ABS(I10)>=$CK$5,I10,0),0) -> 0 | BE10: =IF(ABS(J10)>ABS(SUM($D10:$O10)/8),IF(ABS(J10)>=$CK$5,J10,0),0) -> 0 | BF10: =IF(ABS(K10)>ABS(SUM($D10:$O10)/8),IF(ABS(K10)>=$CK$5,K10,0),0) -> 0 | ... BJ10: =IF(ABS(O10)>ABS(SUM($D10:$O10)/8),IF(ABS(O10)>=$CK$5,O10,0),0) -> 0 | BK10: =IF(ABS(P10)>ABS(SUM($P10:$AA10)/8),IF(ABS(P10)>=$CK$5,P10,0),0) -> 0 | BL10: =IF(ABS(Q10)>ABS(SUM($P10:$AA10)/8),IF(ABS(Q10)>=$CK$5,Q10,0),0) -> 0 | BM10: =IF(ABS(R10)>ABS(SUM($P10:$AA10)/8),IF(ABS(R10)>=$CK$5,R10,0),0) -> 0 | BN10: =IF(ABS(S10)>ABS(SUM($P10:$AA10)/8),IF(ABS(S10)>=$CK$5,S10,0),0) -> 0 | BO10: =IF(ABS(T10)>ABS(SUM($P10:$AA10)/8),IF(ABS(T10)>=$CK$5,T10,0),0) -> 0 | BP10: =IF(ABS(U10)>ABS(SUM($P10:$AA10)/8),IF(ABS(U10)>=$CK$5,U10,0),0) -> 0 | BQ10: =IF(ABS(V10)>ABS(SUM($P10:$AA10)/8),IF(ABS(V10)>=$CK$5,V10,0),0) -> 0 | BR10: =IF(ABS(W10)>ABS(SUM($P10:$AA10)/8),IF(ABS(W10)>=$CK$5,W10,0),0) -> 0 | ... BV10: =IF(ABS(AA10)>ABS(SUM($P10:$AA10)/8),IF(ABS(AA10)>=$CK$5,AA10,0),0) -> 0 | BW10: =IF(ABS(AB10)>ABS(SUM($AB10:$AM10)/'Key information'!$E$34*12/8),IF(ABS(AB10)>=$CK$5,AB10,0),0) -> 0 | BX10: =IF(ABS(AC10)>ABS(SUM($AB10:$AM10)/'Key information'!$E$34*12/8),IF(ABS(AC10)>=$CK$5,AC10,0),0) -> 0 | BY10: =IF(ABS(AD10)>ABS(SUM($AB10:$AM10)/'Key information'!$E$34*12/8),IF(ABS(AD10)>=$CK$5,AD10,0),0) -> 0 | BZ10: =IF(ABS(AE10)>ABS(SUM($AB10:$AM10)/'Key information'!$E$34*12/8),IF(ABS(AE10)>=$CK$5,AE10,0),0) -> 0 | CA10: =IF(ABS(AF10)>ABS(SUM($AB10:$AM10)/'Key information'!$E$34*12/8),IF(ABS(AF10)>=$CK$5,AF10,0),0) -> 0 | CB10: =IF(ABS(AG10)>ABS(SUM($AB10:$AM10)/'Key information'!$E$34*12/8),IF(ABS(AG10)>=$CK$5,AG10,0),0) -> 0 | CC10: =IF(ABS(AH10)>ABS(SUM($AB10:$AM10)/'Key information'!$E$34*12/8),IF(ABS(AH10)>=$CK$5,AH10,0),0) -> 0 | CD10: =IF(ABS(AI10)>ABS(SUM($AB10:$AM10)/'Key information'!$E$34*12/8),IF(ABS(AI10)>=$CK$5,AI10,0),0) -> 0 | ... CH10: =IF(ABS(AM10)>ABS(SUM($AB10:$AM10)/'Key information'!$E$34*12/8),IF(ABS(AM10)>=$CK$5,AM10,0),0) -> 0 | CI10: =COUNTIF(AY10:OFFSET(CH10,0,(-12+'Key information'!$E$34)),">0") -> 0 | CJ10: =COUNTIF(AY10:OFFSET(CH10,0,(-12+'Key information'!$E$34)),"<0") -> 0 | CK10: =SUM(CI10:CJ10) -> 0
B11: SAL2 | C11: [Net sales account 2] | D11: =SUMIFS(PL!F:F,PL!$B:$B,$B11)/'Key information'!$E$114 -> 0 | E11: =SUMIFS(PL!G:G,PL!$B:$B,$B11)/'Key information'!$E$114 -> 0 | F11: =SUMIFS(PL!H:H,PL!$B:$B,$B11)/'Key information'!$E$114 -> 0 | G11: =SUMIFS(PL!I:I,PL!$B:$B,$B11)/'Key information'!$E$114 -> 0 | H11: =SUMIFS(PL!J:J,PL!$B:$B,$B11)/'Key information'!$E$114 -> 0 | I11: =SUMIFS(PL!K:K,PL!$B:$B,$B11)/'Key information'!$E$114 -> 0 | J11: =SUMIFS(PL!L:L,PL!$B:$B,$B11)/'Key information'!$E$114 -> 0 | K11: =SUMIFS(PL!M:M,PL!$B:$B,$B11)/'Key information'!$E$114 -> 0 | L11: =SUMIFS(PL!N:N,PL!$B:$B,$B11)/'Key information'!$E$114 -> 0 | M11: =SUMIFS(PL!O:O,PL!$B:$B,$B11)/'Key information'!$E$114 -> 0 | N11: =SUMIFS(PL!P:P,PL!$B:$B,$B11)/'Key information'!$E$114 -> 0 | O11: =SUMIFS(PL!Q:Q,PL!$B:$B,$B11)/'Key information'!$E$114 -> 0 | P11: =SUMIFS(PL!R:R,PL!$B:$B,$B11)/'Key information'!$E$114 -> 0 | Q11: =SUMIFS(PL!S:S,PL!$B:$B,$B11)/'Key information'!$E$114 -> 0 | R11: =SUMIFS(PL!T:T,PL!$B:$B,$B11)/'Key information'!$E$114 -> 0 | S11: =SUMIFS(PL!U:U,PL!$B:$B,$B11)/'Key information'!$E$114 -> 0 | T11: =SUMIFS(PL!V:V,PL!$B:$B,$B11)/'Key information'!$E$114 -> 0 | U11: =SUMIFS(PL!W:W,PL!$B:$B,$B11)/'Key information'!$E$114 -> 0 | V11: =SUMIFS(PL!X:X,PL!$B:$B,$B11)/'Key information'!$E$114 -> 0 | W11: =SUMIFS(PL!Y:Y,PL!$B:$B,$B11)/'Key information'!$E$114 -> 0 | X11: =SUMIFS(PL!Z:Z,PL!$B:$B,$B11)/'Key information'!$E$114 -> 0 | Y11: =SUMIFS(PL!AA:AA,PL!$B:$B,$B11)/'Key information'!$E$114 -> 0 | Z11: =SUMIFS(PL!AB:AB,PL!$B:$B,$B11)/'Key information'!$E$114 -> 0 | AA11: =SUMIFS(PL!AC:AC,PL!$B:$B,$B11)/'Key information'!$E$114 -> 0 | AB11: =SUMIFS(PL!AD:AD,PL!$B:$B,$B11)/'Key information'!$E$114 -> 0 | AC11: =SUMIFS(PL!AE:AE,PL!$B:$B,$B11)/'Key information'!$E$114 -> 0 | AD11: =SUMIFS(PL!AF:AF,PL!$B:$B,$B11)/'Key information'!$E$114 -> 0 | AE11: =SUMIFS(PL!AG:AG,PL!$B:$B,$B11)/'Key information'!$E$114 -> 0 | AF11: =SUMIFS(PL!AH:AH,PL!$B:$B,$B11)/'Key information'!$E$114 -> 0 | AG11: =SUMIFS(PL!AI:AI,PL!$B:$B,$B11)/'Key information'!$E$114 -> 0 | AH11: =SUMIFS(PL!AJ:AJ,PL!$B:$B,$B11)/'Key information'!$E$114 -> 0 | AI11: =SUMIFS(PL!AK:AK,PL!$B:$B,$B11)/'Key information'!$E$114 -> 0 | AJ11: =SUMIFS(PL!AL:AL,PL!$B:$B,$B11)/'Key information'!$E$114 -> 0 | AK11: =SUMIFS(PL!AM:AM,PL!$B:$B,$B11)/'Key information'!$E$114 -> 0 | AL11: =SUMIFS(PL!AN:AN,PL!$B:$B,$B11)/'Key information'!$E$114 -> 0 | AM11: =SUMIFS(PL!AO:AO,PL!$B:$B,$B11)/'Key information'!$E$114 -> 0 | AN11: =SUM(D11:O11) -> 0 | AO11: =SUM(P11:AA11) -> 0 | AP11: =SUM(OFFSET(AM11,0,(-12+'Key information'!$E$34)):OFFSET(AA11,0,(-11+'Key information'!$E$34))) -> 0 | AQ11: =SUMIF(PL!$B:$B,PL_monthly!B11,PL!$AP:$AP)/'Key information'!$E$114 -> 0 | AS11: =SUM(OFFSET(AA11,0,(-12+'Key information'!$E$34)):P11) -> 0 | AT11: =SUM(OFFSET(AM11,0,(-12+'Key information'!$E$34)):AB11) -> 0 | AX11: [Net sales account 2] | AY11: =IF(ABS(D11)>ABS(SUM($D11:$O11)/8),IF(ABS(D11)>=$CK$5,D11,0),0) -> 0 | AZ11: =IF(ABS(E11)>ABS(SUM($D11:$O11)/8),IF(ABS(E11)>=$CK$5,E11,0),0) -> 0 | BA11: =IF(ABS(F11)>ABS(SUM($D11:$O11)/8),IF(ABS(F11)>=$CK$5,F11,0),0) -> 0 | BB11: =IF(ABS(G11)>ABS(SUM($D11:$O11)/8),IF(ABS(G11)>=$CK$5,G11,0),0) -> 0 | BC11: =IF(ABS(H11)>ABS(SUM($D11:$O11)/8),IF(ABS(H11)>=$CK$5,H11,0),0) -> 0 | BD11: =IF(ABS(I11)>ABS(SUM($D11:$O11)/8),IF(ABS(I11)>=$CK$5,I11,0),0) -> 0 | BE11: =IF(ABS(J11)>ABS(SUM($D11:$O11)/8),IF(ABS(J11)>=$CK$5,J11,0),0) -> 0 | BF11: =IF(ABS(K11)>ABS(SUM($D11:$O11)/8),IF(ABS(K11)>=$CK$5,K11,0),0) -> 0 | ... BJ11: =IF(ABS(O11)>ABS(SUM($D11:$O11)/8),IF(ABS(O11)>=$CK$5,O11,0),0) -> 0 | BK11: =IF(ABS(P11)>ABS(SUM($P11:$AA11)/8),IF(ABS(P11)>=$CK$5,P11,0),0) -> 0 | BL11: =IF(ABS(Q11)>ABS(SUM($P11:$AA11)/8),IF(ABS(Q11)>=$CK$5,Q11,0),0) -> 0 | BM11: =IF(ABS(R11)>ABS(SUM($P11:$AA11)/8),IF(ABS(R11)>=$CK$5,R11,0),0) -> 0 | BN11: =IF(ABS(S11)>ABS(SUM($P11:$AA11)/8),IF(ABS(S11)>=$CK$5,S11,0),0) -> 0 | BO11: =IF(ABS(T11)>ABS(SUM($P11:$AA11)/8),IF(ABS(T11)>=$CK$5,T11,0),0) -> 0 | BP11: =IF(ABS(U11)>ABS(SUM($P11:$AA11)/8),IF(ABS(U11)>=$CK$5,U11,0),0) -> 0 | BQ11: =IF(ABS(V11)>ABS(SUM($P11:$AA11)/8),IF(ABS(V11)>=$CK$5,V11,0),0) -> 0 | BR11: =IF(ABS(W11)>ABS(SUM($P11:$AA11)/8),IF(ABS(W11)>=$CK$5,W11,0),0) -> 0 | ... BV11: =IF(ABS(AA11)>ABS(SUM($P11:$AA11)/8),IF(ABS(AA11)>=$CK$5,AA11,0),0) -> 0 | BW11: =IF(ABS(AB11)>ABS(SUM($AB11:$AM11)/'Key information'!$E$34*12/8),IF(ABS(AB11)>=$CK$5,AB11,0),0) -> 0 | BX11: =IF(ABS(AC11)>ABS(SUM($AB11:$AM11)/'Key information'!$E$34*12/8),IF(ABS(AC11)>=$CK$5,AC11,0),0) -> 0 | BY11: =IF(ABS(AD11)>ABS(SUM($AB11:$AM11)/'Key information'!$E$34*12/8),IF(ABS(AD11)>=$CK$5,AD11,0),0) -> 0 | BZ11: =IF(ABS(AE11)>ABS(SUM($AB11:$AM11)/'Key information'!$E$34*12/8),IF(ABS(AE11)>=$CK$5,AE11,0),0) -> 0 | CA11: =IF(ABS(AF11)>ABS(SUM($AB11:$AM11)/'Key information'!$E$34*12/8),IF(ABS(AF11)>=$CK$5,AF11,0),0) -> 0 | CB11: =IF(ABS(AG11)>ABS(SUM($AB11:$AM11)/'Key information'!$E$34*12/8),IF(ABS(AG11)>=$CK$5,AG11,0),0) -> 0 | CC11: =IF(ABS(AH11)>ABS(SUM($AB11:$AM11)/'Key information'!$E$34*12/8),IF(ABS(AH11)>=$CK$5,AH11,0),0) -> 0 | CD11: =IF(ABS(AI11)>ABS(SUM($AB11:$AM11)/'Key information'!$E$34*12/8),IF(ABS(AI11)>=$CK$5,AI11,0),0) -> 0 | ... CH11: =IF(ABS(AM11)>ABS(SUM($AB11:$AM11)/'Key information'!$E$34*12/8),IF(ABS(AM11)>=$CK$5,AM11,0),0) -> 0 | CI11: =COUNTIF(AY11:OFFSET(CH11,0,(-12+'Key information'!$E$34)),">0") -> 0 | CJ11: =COUNTIF(AY11:OFFSET(CH11,0,(-12+'Key information'!$E$34)),"<0") -> 0 | CK11: =SUM(CI11:CJ11) -> 0
B12: SAL3 | C12: [Net sales account 3] | D12: =SUMIFS(PL!F:F,PL!$B:$B,$B12)/'Key information'!$E$114 -> 0 | E12: =SUMIFS(PL!G:G,PL!$B:$B,$B12)/'Key information'!$E$114 -> 0 | F12: =SUMIFS(PL!H:H,PL!$B:$B,$B12)/'Key information'!$E$114 -> 0 | G12: =SUMIFS(PL!I:I,PL!$B:$B,$B12)/'Key information'!$E$114 -> 0 | H12: =SUMIFS(PL!J:J,PL!$B:$B,$B12)/'Key information'!$E$114 -> 0 | I12: =SUMIFS(PL!K:K,PL!$B:$B,$B12)/'Key information'!$E$114 -> 0 | J12: =SUMIFS(PL!L:L,PL!$B:$B,$B12)/'Key information'!$E$114 -> 0 | K12: =SUMIFS(PL!M:M,PL!$B:$B,$B12)/'Key information'!$E$114 -> 0 | L12: =SUMIFS(PL!N:N,PL!$B:$B,$B12)/'Key information'!$E$114 -> 0 | M12: =SUMIFS(PL!O:O,PL!$B:$B,$B12)/'Key information'!$E$114 -> 0 | N12: =SUMIFS(PL!P:P,PL!$B:$B,$B12)/'Key information'!$E$114 -> 0 | O12: =SUMIFS(PL!Q:Q,PL!$B:$B,$B12)/'Key information'!$E$114 -> 0 | P12: =SUMIFS(PL!R:R,PL!$B:$B,$B12)/'Key information'!$E$114 -> 0 | Q12: =SUMIFS(PL!S:S,PL!$B:$B,$B12)/'Key information'!$E$114 -> 0 | R12: =SUMIFS(PL!T:T,PL!$B:$B,$B12)/'Key information'!$E$114 -> 0 | S12: =SUMIFS(PL!U:U,PL!$B:$B,$B12)/'Key information'!$E$114 -> 0 | T12: =SUMIFS(PL!V:V,PL!$B:$B,$B12)/'Key information'!$E$114 -> 0 | U12: =SUMIFS(PL!W:W,PL!$B:$B,$B12)/'Key information'!$E$114 -> 0 | V12: =SUMIFS(PL!X:X,PL!$B:$B,$B12)/'Key information'!$E$114 -> 0 | W12: =SUMIFS(PL!Y:Y,PL!$B:$B,$B12)/'Key information'!$E$114 -> 0 | X12: =SUMIFS(PL!Z:Z,PL!$B:$B,$B12)/'Key information'!$E$114 -> 0 | Y12: =SUMIFS(PL!AA:AA,PL!$B:$B,$B12)/'Key information'!$E$114 -> 0 | Z12: =SUMIFS(PL!AB:AB,PL!$B:$B,$B12)/'Key information'!$E$114 -> 0 | AA12: =SUMIFS(PL!AC:AC,PL!$B:$B,$B12)/'Key information'!$E$114 -> 0 | AB12: =SUMIFS(PL!AD:AD,PL!$B:$B,$B12)/'Key information'!$E$114 -> 0 | AC12: =SUMIFS(PL!AE:AE,PL!$B:$B,$B12)/'Key information'!$E$114 -> 0 | AD12: =SUMIFS(PL!AF:AF,PL!$B:$B,$B12)/'Key information'!$E$114 -> 0 | AE12: =SUMIFS(PL!AG:AG,PL!$B:$B,$B12)/'Key information'!$E$114 -> 0 | AF12: =SUMIFS(PL!AH:AH,PL!$B:$B,$B12)/'Key information'!$E$114 -> 0 | AG12: =SUMIFS(PL!AI:AI,PL!$B:$B,$B12)/'Key information'!$E$114 -> 0 | AH12: =SUMIFS(PL!AJ:AJ,PL!$B:$B,$B12)/'Key information'!$E$114 -> 0 | AI12: =SUMIFS(PL!AK:AK,PL!$B:$B,$B12)/'Key information'!$E$114 -> 0 | AJ12: =SUMIFS(PL!AL:AL,PL!$B:$B,$B12)/'Key information'!$E$114 -> 0 | AK12: =SUMIFS(PL!AM:AM,PL!$B:$B,$B12)/'Key information'!$E$114 -> 0 | AL12: =SUMIFS(PL!AN:AN,PL!$B:$B,$B12)/'Key information'!$E$114 -> 0 | AM12: =SUMIFS(PL!AO:AO,PL!$B:$B,$B12)/'Key information'!$E$114 -> 0 | AN12: =SUM(D12:O12) -> 0 | AO12: =SUM(P12:AA12) -> 0 | AP12: =SUM(OFFSET(AM12,0,(-12+'Key information'!$E$34)):OFFSET(AA12,0,(-11+'Key information'!$E$34))) -> 0 | AQ12: =SUMIF(PL!$B:$B,PL_monthly!B12,PL!$AP:$AP)/'Key information'!$E$114 -> 0 | AS12: =SUM(OFFSET(AA12,0,(-12+'Key information'!$E$34)):P12) -> 0 | AT12: =SUM(OFFSET(AM12,0,(-12+'Key information'!$E$34)):AB12) -> 0 | AX12: [Net sales account 3] | AY12: =IF(ABS(D12)>ABS(SUM($D12:$O12)/8),IF(ABS(D12)>=$CK$5,D12,0),0) -> 0 | AZ12: =IF(ABS(E12)>ABS(SUM($D12:$O12)/8),IF(ABS(E12)>=$CK$5,E12,0),0) -> 0 | BA12: =IF(ABS(F12)>ABS(SUM($D12:$O12)/8),IF(ABS(F12)>=$CK$5,F12,0),0) -> 0 | BB12: =IF(ABS(G12)>ABS(SUM($D12:$O12)/8),IF(ABS(G12)>=$CK$5,G12,0),0) -> 0 | BC12: =IF(ABS(H12)>ABS(SUM($D12:$O12)/8),IF(ABS(H12)>=$CK$5,H12,0),0) -> 0 | BD12: =IF(ABS(I12)>ABS(SUM($D12:$O12)/8),IF(ABS(I12)>=$CK$5,I12,0),0) -> 0 | BE12: =IF(ABS(J12)>ABS(SUM($D12:$O12)/8),IF(ABS(J12)>=$CK$5,J12,0),0) -> 0 | BF12: =IF(ABS(K12)>ABS(SUM($D12:$O12)/8),IF(ABS(K12)>=$CK$5,K12,0),0) -> 0 | ... BJ12: =IF(ABS(O12)>ABS(SUM($D12:$O12)/8),IF(ABS(O12)>=$CK$5,O12,0),0) -> 0 | BK12: =IF(ABS(P12)>ABS(SUM($P12:$AA12)/8),IF(ABS(P12)>=$CK$5,P12,0),0) -> 0 | BL12: =IF(ABS(Q12)>ABS(SUM($P12:$AA12)/8),IF(ABS(Q12)>=$CK$5,Q12,0),0) -> 0 | BM12: =IF(ABS(R12)>ABS(SUM($P12:$AA12)/8),IF(ABS(R12)>=$CK$5,R12,0),0) -> 0 | BN12: =IF(ABS(S12)>ABS(SUM($P12:$AA12)/8),IF(ABS(S12)>=$CK$5,S12,0),0) -> 0 | BO12: =IF(ABS(T12)>ABS(SUM($P12:$AA12)/8),IF(ABS(T12)>=$CK$5,T12,0),0) -> 0 | BP12: =IF(ABS(U12)>ABS(SUM($P12:$AA12)/8),IF(ABS(U12)>=$CK$5,U12,0),0) -> 0 | BQ12: =IF(ABS(V12)>ABS(SUM($P12:$AA12)/8),IF(ABS(V12)>=$CK$5,V12,0),0) -> 0 | BR12: =IF(ABS(W12)>ABS(SUM($P12:$AA12)/8),IF(ABS(W12)>=$CK$5,W12,0),0) -> 0 | ... BV12: =IF(ABS(AA12)>ABS(SUM($P12:$AA12)/8),IF(ABS(AA12)>=$CK$5,AA12,0),0) -> 0 | BW12: =IF(ABS(AB12)>ABS(SUM($AB12:$AM12)/'Key information'!$E$34*12/8),IF(ABS(AB12)>=$CK$5,AB12,0),0) -> 0 | BX12: =IF(ABS(AC12)>ABS(SUM($AB12:$AM12)/'Key information'!$E$34*12/8),IF(ABS(AC12)>=$CK$5,AC12,0),0) -> 0 | BY12: =IF(ABS(AD12)>ABS(SUM($AB12:$AM12)/'Key information'!$E$34*12/8),IF(ABS(AD12)>=$CK$5,AD12,0),0) -> 0 | BZ12: =IF(ABS(AE12)>ABS(SUM($AB12:$AM12)/'Key information'!$E$34*12/8),IF(ABS(AE12)>=$CK$5,AE12,0),0) -> 0 | CA12: =IF(ABS(AF12)>ABS(SUM($AB12:$AM12)/'Key information'!$E$34*12/8),IF(ABS(AF12)>=$CK$5,AF12,0),0) -> 0 | CB12: =IF(ABS(AG12)>ABS(SUM($AB12:$AM12)/'Key information'!$E$34*12/8),IF(ABS(AG12)>=$CK$5,AG12,0),0) -> 0 | CC12: =IF(ABS(AH12)>ABS(SUM($AB12:$AM12)/'Key information'!$E$34*12/8),IF(ABS(AH12)>=$CK$5,AH12,0),0) -> 0 | CD12: =IF(ABS(AI12)>ABS(SUM($AB12:$AM12)/'Key information'!$E$34*12/8),IF(ABS(AI12)>=$CK$5,AI12,0),0) -> 0 | ... CH12: =IF(ABS(AM12)>ABS(SUM($AB12:$AM12)/'Key information'!$E$34*12/8),IF(ABS(AM12)>=$CK$5,AM12,0),0) -> 0 | CI12: =COUNTIF(AY12:OFFSET(CH12,0,(-12+'Key information'!$E$34)),">0") -> 0 | CJ12: =COUNTIF(AY12:OFFSET(CH12,0,(-12+'Key information'!$E$34)),"<0") -> 0 | CK12: =SUM(CI12:CJ12) -> 0
B13: SAL4 | C13: [Net sales account 4] | D13: =SUMIFS(PL!F:F,PL!$B:$B,$B13)/'Key information'!$E$114 -> 0 | E13: =SUMIFS(PL!G:G,PL!$B:$B,$B13)/'Key information'!$E$114 -> 0 | F13: =SUMIFS(PL!H:H,PL!$B:$B,$B13)/'Key information'!$E$114 -> 0 | G13: =SUMIFS(PL!I:I,PL!$B:$B,$B13)/'Key information'!$E$114 -> 0 | H13: =SUMIFS(PL!J:J,PL!$B:$B,$B13)/'Key information'!$E$114 -> 0 | I13: =SUMIFS(PL!K:K,PL!$B:$B,$B13)/'Key information'!$E$114 -> 0 | J13: =SUMIFS(PL!L:L,PL!$B:$B,$B13)/'Key information'!$E$114 -> 0 | K13: =SUMIFS(PL!M:M,PL!$B:$B,$B13)/'Key information'!$E$114 -> 0 | L13: =SUMIFS(PL!N:N,PL!$B:$B,$B13)/'Key information'!$E$114 -> 0 | M13: =SUMIFS(PL!O:O,PL!$B:$B,$B13)/'Key information'!$E$114 -> 0 | N13: =SUMIFS(PL!P:P,PL!$B:$B,$B13)/'Key information'!$E$114 -> 0 | O13: =SUMIFS(PL!Q:Q,PL!$B:$B,$B13)/'Key information'!$E$114 -> 0 | P13: =SUMIFS(PL!R:R,PL!$B:$B,$B13)/'Key information'!$E$114 -> 0 | Q13: =SUMIFS(PL!S:S,PL!$B:$B,$B13)/'Key information'!$E$114 -> 0 | R13: =SUMIFS(PL!T:T,PL!$B:$B,$B13)/'Key information'!$E$114 -> 0 | S13: =SUMIFS(PL!U:U,PL!$B:$B,$B13)/'Key information'!$E$114 -> 0 | T13: =SUMIFS(PL!V:V,PL!$B:$B,$B13)/'Key information'!$E$114 -> 0 | U13: =SUMIFS(PL!W:W,PL!$B:$B,$B13)/'Key information'!$E$114 -> 0 | V13: =SUMIFS(PL!X:X,PL!$B:$B,$B13)/'Key information'!$E$114 -> 0 | W13: =SUMIFS(PL!Y:Y,PL!$B:$B,$B13)/'Key information'!$E$114 -> 0 | X13: =SUMIFS(PL!Z:Z,PL!$B:$B,$B13)/'Key information'!$E$114 -> 0 | Y13: =SUMIFS(PL!AA:AA,PL!$B:$B,$B13)/'Key information'!$E$114 -> 0 | Z13: =SUMIFS(PL!AB:AB,PL!$B:$B,$B13)/'Key information'!$E$114 -> 0 | AA13: =SUMIFS(PL!AC:AC,PL!$B:$B,$B13)/'Key information'!$E$114 -> 0 | AB13: =SUMIFS(PL!AD:AD,PL!$B:$B,$B13)/'Key information'!$E$114 -> 0 | AC13: =SUMIFS(PL!AE:AE,PL!$B:$B,$B13)/'Key information'!$E$114 -> 0 | AD13: =SUMIFS(PL!AF:AF,PL!$B:$B,$B13)/'Key information'!$E$114 -> 0 | AE13: =SUMIFS(PL!AG:AG,PL!$B:$B,$B13)/'Key information'!$E$114 -> 0 | AF13: =SUMIFS(PL!AH:AH,PL!$B:$B,$B13)/'Key information'!$E$114 -> 0 | AG13: =SUMIFS(PL!AI:AI,PL!$B:$B,$B13)/'Key information'!$E$114 -> 0 | AH13: =SUMIFS(PL!AJ:AJ,PL!$B:$B,$B13)/'Key information'!$E$114 -> 0 | AI13: =SUMIFS(PL!AK:AK,PL!$B:$B,$B13)/'Key information'!$E$114 -> 0 | AJ13: =SUMIFS(PL!AL:AL,PL!$B:$B,$B13)/'Key information'!$E$114 -> 0 | AK13: =SUMIFS(PL!AM:AM,PL!$B:$B,$B13)/'Key information'!$E$114 -> 0 | AL13: =SUMIFS(PL!AN:AN,PL!$B:$B,$B13)/'Key information'!$E$114 -> 0 | AM13: =SUMIFS(PL!AO:AO,PL!$B:$B,$B13)/'Key information'!$E$114 -> 0 | AN13: =SUM(D13:O13) -> 0 | AO13: =SUM(P13:AA13) -> 0 | AP13: =SUM(OFFSET(AM13,0,(-12+'Key information'!$E$34)):OFFSET(AA13,0,(-11+'Key information'!$E$34))) -> 0 | AQ13: =SUMIF(PL!$B:$B,PL_monthly!B13,PL!$AP:$AP)/'Key information'!$E$114 -> 0 | AS13: =SUM(OFFSET(AA13,0,(-12+'Key information'!$E$34)):P13) -> 0 | AT13: =SUM(OFFSET(AM13,0,(-12+'Key information'!$E$34)):AB13) -> 0 | AX13: [Net sales account 4] | AY13: =IF(ABS(D13)>ABS(SUM($D13:$O13)/8),IF(ABS(D13)>=$CK$5,D13,0),0) -> 0 | AZ13: =IF(ABS(E13)>ABS(SUM($D13:$O13)/8),IF(ABS(E13)>=$CK$5,E13,0),0) -> 0 | BA13: =IF(ABS(F13)>ABS(SUM($D13:$O13)/8),IF(ABS(F13)>=$CK$5,F13,0),0) -> 0 | BB13: =IF(ABS(G13)>ABS(SUM($D13:$O13)/8),IF(ABS(G13)>=$CK$5,G13,0),0) -> 0 | BC13: =IF(ABS(H13)>ABS(SUM($D13:$O13)/8),IF(ABS(H13)>=$CK$5,H13,0),0) -> 0 | BD13: =IF(ABS(I13)>ABS(SUM($D13:$O13)/8),IF(ABS(I13)>=$CK$5,I13,0),0) -> 0 | BE13: =IF(ABS(J13)>ABS(SUM($D13:$O13)/8),IF(ABS(J13)>=$CK$5,J13,0),0) -> 0 | BF13: =IF(ABS(K13)>ABS(SUM($D13:$O13)/8),IF(ABS(K13)>=$CK$5,K13,0),0) -> 0 | ... BJ13: =IF(ABS(O13)>ABS(SUM($D13:$O13)/8),IF(ABS(O13)>=$CK$5,O13,0),0) -> 0 | BK13: =IF(ABS(P13)>ABS(SUM($P13:$AA13)/8),IF(ABS(P13)>=$CK$5,P13,0),0) -> 0 | BL13: =IF(ABS(Q13)>ABS(SUM($P13:$AA13)/8),IF(ABS(Q13)>=$CK$5,Q13,0),0) -> 0 | BM13: =IF(ABS(R13)>ABS(SUM($P13:$AA13)/8),IF(ABS(R13)>=$CK$5,R13,0),0) -> 0 | BN13: =IF(ABS(S13)>ABS(SUM($P13:$AA13)/8),IF(ABS(S13)>=$CK$5,S13,0),0) -> 0 | BO13: =IF(ABS(T13)>ABS(SUM($P13:$AA13)/8),IF(ABS(T13)>=$CK$5,T13,0),0) -> 0 | BP13: =IF(ABS(U13)>ABS(SUM($P13:$AA13)/8),IF(ABS(U13)>=$CK$5,U13,0),0) -> 0 | BQ13: =IF(ABS(V13)>ABS(SUM($P13:$AA13)/8),IF(ABS(V13)>=$CK$5,V13,0),0) -> 0 | BR13: =IF(ABS(W13)>ABS(SUM($P13:$AA13)/8),IF(ABS(W13)>=$CK$5,W13,0),0) -> 0 | ... BV13: =IF(ABS(AA13)>ABS(SUM($P13:$AA13)/8),IF(ABS(AA13)>=$CK$5,AA13,0),0) -> 0 | BW13: =IF(ABS(AB13)>ABS(SUM($AB13:$AM13)/'Key information'!$E$34*12/8),IF(ABS(AB13)>=$CK$5,AB13,0),0) -> 0 | BX13: =IF(ABS(AC13)>ABS(SUM($AB13:$AM13)/'Key information'!$E$34*12/8),IF(ABS(AC13)>=$CK$5,AC13,0),0) -> 0 | BY13: =IF(ABS(AD13)>ABS(SUM($AB13:$AM13)/'Key information'!$E$34*12/8),IF(ABS(AD13)>=$CK$5,AD13,0),0) -> 0 | BZ13: =IF(ABS(AE13)>ABS(SUM($AB13:$AM13)/'Key information'!$E$34*12/8),IF(ABS(AE13)>=$CK$5,AE13,0),0) -> 0 | CA13: =IF(ABS(AF13)>ABS(SUM($AB13:$AM13)/'Key information'!$E$34*12/8),IF(ABS(AF13)>=$CK$5,AF13,0),0) -> 0 | CB13: =IF(ABS(AG13)>ABS(SUM($AB13:$AM13)/'Key information'!$E$34*12/8),IF(ABS(AG13)>=$CK$5,AG13,0),0) -> 0 | CC13: =IF(ABS(AH13)>ABS(SUM($AB13:$AM13)/'Key information'!$E$34*12/8),IF(ABS(AH13)>=$CK$5,AH13,0),0) -> 0 | CD13: =IF(ABS(AI13)>ABS(SUM($AB13:$AM13)/'Key information'!$E$34*12/8),IF(ABS(AI13)>=$CK$5,AI13,0),0) -> 0 | ... CH13: =IF(ABS(AM13)>ABS(SUM($AB13:$AM13)/'Key information'!$E$34*12/8),IF(ABS(AM13)>=$CK$5,AM13,0),0) -> 0 | CI13: =COUNTIF(AY13:OFFSET(CH13,0,(-12+'Key information'!$E$34)),">0") -> 0 | CJ13: =COUNTIF(AY13:OFFSET(CH13,0,(-12+'Key information'!$E$34)),"<0") -> 0 | CK13: =SUM(CI13:CJ13) -> 0
B14: SAL5 | C14: [Net sales account 5] | D14: =SUMIFS(PL!F:F,PL!$B:$B,$B14)/'Key information'!$E$114 -> 0 | E14: =SUMIFS(PL!G:G,PL!$B:$B,$B14)/'Key information'!$E$114 -> 0 | F14: =SUMIFS(PL!H:H,PL!$B:$B,$B14)/'Key information'!$E$114 -> 0 | G14: =SUMIFS(PL!I:I,PL!$B:$B,$B14)/'Key information'!$E$114 -> 0 | H14: =SUMIFS(PL!J:J,PL!$B:$B,$B14)/'Key information'!$E$114 -> 0 | I14: =SUMIFS(PL!K:K,PL!$B:$B,$B14)/'Key information'!$E$114 -> 0 | J14: =SUMIFS(PL!L:L,PL!$B:$B,$B14)/'Key information'!$E$114 -> 0 | K14: =SUMIFS(PL!M:M,PL!$B:$B,$B14)/'Key information'!$E$114 -> 0 | L14: =SUMIFS(PL!N:N,PL!$B:$B,$B14)/'Key information'!$E$114 -> 0 | M14: =SUMIFS(PL!O:O,PL!$B:$B,$B14)/'Key information'!$E$114 -> 0 | N14: =SUMIFS(PL!P:P,PL!$B:$B,$B14)/'Key information'!$E$114 -> 0 | O14: =SUMIFS(PL!Q:Q,PL!$B:$B,$B14)/'Key information'!$E$114 -> 0 | P14: =SUMIFS(PL!R:R,PL!$B:$B,$B14)/'Key information'!$E$114 -> 0 | Q14: =SUMIFS(PL!S:S,PL!$B:$B,$B14)/'Key information'!$E$114 -> 0 | R14: =SUMIFS(PL!T:T,PL!$B:$B,$B14)/'Key information'!$E$114 -> 0 | S14: =SUMIFS(PL!U:U,PL!$B:$B,$B14)/'Key information'!$E$114 -> 0 | T14: =SUMIFS(PL!V:V,PL!$B:$B,$B14)/'Key information'!$E$114 -> 0 | U14: =SUMIFS(PL!W:W,PL!$B:$B,$B14)/'Key information'!$E$114 -> 0 | V14: =SUMIFS(PL!X:X,PL!$B:$B,$B14)/'Key information'!$E$114 -> 0 | W14: =SUMIFS(PL!Y:Y,PL!$B:$B,$B14)/'Key information'!$E$114 -> 0 | X14: =SUMIFS(PL!Z:Z,PL!$B:$B,$B14)/'Key information'!$E$114 -> 0 | Y14: =SUMIFS(PL!AA:AA,PL!$B:$B,$B14)/'Key information'!$E$114 -> 0 | Z14: =SUMIFS(PL!AB:AB,PL!$B:$B,$B14)/'Key information'!$E$114 -> 0 | AA14: =SUMIFS(PL!AC:AC,PL!$B:$B,$B14)/'Key information'!$E$114 -> 0 | AB14: =SUMIFS(PL!AD:AD,PL!$B:$B,$B14)/'Key information'!$E$114 -> 0 | AC14: =SUMIFS(PL!AE:AE,PL!$B:$B,$B14)/'Key information'!$E$114 -> 0 | AD14: =SUMIFS(PL!AF:AF,PL!$B:$B,$B14)/'Key information'!$E$114 -> 0 | AE14: =SUMIFS(PL!AG:AG,PL!$B:$B,$B14)/'Key information'!$E$114 -> 0 | AF14: =SUMIFS(PL!AH:AH,PL!$B:$B,$B14)/'Key information'!$E$114 -> 0 | AG14: =SUMIFS(PL!AI:AI,PL!$B:$B,$B14)/'Key information'!$E$114 -> 0 | AH14: =SUMIFS(PL!AJ:AJ,PL!$B:$B,$B14)/'Key information'!$E$114 -> 0 | AI14: =SUMIFS(PL!AK:AK,PL!$B:$B,$B14)/'Key information'!$E$114 -> 0 | AJ14: =SUMIFS(PL!AL:AL,PL!$B:$B,$B14)/'Key information'!$E$114 -> 0 | AK14: =SUMIFS(PL!AM:AM,PL!$B:$B,$B14)/'Key information'!$E$114 -> 0 | AL14: =SUMIFS(PL!AN:AN,PL!$B:$B,$B14)/'Key information'!$E$114 -> 0 | AM14: =SUMIFS(PL!AO:AO,PL!$B:$B,$B14)/'Key information'!$E$114 -> 0 | AN14: =SUM(D14:O14) -> 0 | AO14: =SUM(P14:AA14) -> 0 | AP14: =SUM(OFFSET(AM14,0,(-12+'Key information'!$E$34)):OFFSET(AA14,0,(-11+'Key information'!$E$34))) -> 0 | AQ14: =SUMIF(PL!$B:$B,PL_monthly!B14,PL!$AP:$AP)/'Key information'!$E$114 -> 0 | AS14: =SUM(OFFSET(AA14,0,(-12+'Key information'!$E$34)):P14) -> 0 | AT14: =SUM(OFFSET(AM14,0,(-12+'Key information'!$E$34)):AB14) -> 0 | AX14: [Net sales account 5] | AY14: =IF(ABS(D14)>ABS(SUM($D14:$O14)/8),IF(ABS(D14)>=$CK$5,D14,0),0) -> 0 | AZ14: =IF(ABS(E14)>ABS(SUM($D14:$O14)/8),IF(ABS(E14)>=$CK$5,E14,0),0) -> 0 | BA14: =IF(ABS(F14)>ABS(SUM($D14:$O14)/8),IF(ABS(F14)>=$CK$5,F14,0),0) -> 0 | BB14: =IF(ABS(G14)>ABS(SUM($D14:$O14)/8),IF(ABS(G14)>=$CK$5,G14,0),0) -> 0 | BC14: =IF(ABS(H14)>ABS(SUM($D14:$O14)/8),IF(ABS(H14)>=$CK$5,H14,0),0) -> 0 | BD14: =IF(ABS(I14)>ABS(SUM($D14:$O14)/8),IF(ABS(I14)>=$CK$5,I14,0),0) -> 0 | BE14: =IF(ABS(J14)>ABS(SUM($D14:$O14)/8),IF(ABS(J14)>=$CK$5,J14,0),0) -> 0 | BF14: =IF(ABS(K14)>ABS(SUM($D14:$O14)/8),IF(ABS(K14)>=$CK$5,K14,0),0) -> 0 | ... BJ14: =IF(ABS(O14)>ABS(SUM($D14:$O14)/8),IF(ABS(O14)>=$CK$5,O14,0),0) -> 0 | BK14: =IF(ABS(P14)>ABS(SUM($P14:$AA14)/8),IF(ABS(P14)>=$CK$5,P14,0),0) -> 0 | BL14: =IF(ABS(Q14)>ABS(SUM($P14:$AA14)/8),IF(ABS(Q14)>=$CK$5,Q14,0),0) -> 0 | BM14: =IF(ABS(R14)>ABS(SUM($P14:$AA14)/8),IF(ABS(R14)>=$CK$5,R14,0),0) -> 0 | BN14: =IF(ABS(S14)>ABS(SUM($P14:$AA14)/8),IF(ABS(S14)>=$CK$5,S14,0),0) -> 0 | BO14: =IF(ABS(T14)>ABS(SUM($P14:$AA14)/8),IF(ABS(T14)>=$CK$5,T14,0),0) -> 0 | BP14: =IF(ABS(U14)>ABS(SUM($P14:$AA14)/8),IF(ABS(U14)>=$CK$5,U14,0),0) -> 0 | BQ14: =IF(ABS(V14)>ABS(SUM($P14:$AA14)/8),IF(ABS(V14)>=$CK$5,V14,0),0) -> 0 | BR14: =IF(ABS(W14)>ABS(SUM($P14:$AA14)/8),IF(ABS(W14)>=$CK$5,W14,0),0) -> 0 | ... BV14: =IF(ABS(AA14)>ABS(SUM($P14:$AA14)/8),IF(ABS(AA14)>=$CK$5,AA14,0),0) -> 0 | BW14: =IF(ABS(AB14)>ABS(SUM($AB14:$AM14)/'Key information'!$E$34*12/8),IF(ABS(AB14)>=$CK$5,AB14,0),0) -> 0 | BX14: =IF(ABS(AC14)>ABS(SUM($AB14:$AM14)/'Key information'!$E$34*12/8),IF(ABS(AC14)>=$CK$5,AC14,0),0) -> 0 | BY14: =IF(ABS(AD14)>ABS(SUM($AB14:$AM14)/'Key information'!$E$34*12/8),IF(ABS(AD14)>=$CK$5,AD14,0),0) -> 0 | BZ14: =IF(ABS(AE14)>ABS(SUM($AB14:$AM14)/'Key information'!$E$34*12/8),IF(ABS(AE14)>=$CK$5,AE14,0),0) -> 0 | CA14: =IF(ABS(AF14)>ABS(SUM($AB14:$AM14)/'Key information'!$E$34*12/8),IF(ABS(AF14)>=$CK$5,AF14,0),0) -> 0 | CB14: =IF(ABS(AG14)>ABS(SUM($AB14:$AM14)/'Key information'!$E$34*12/8),IF(ABS(AG14)>=$CK$5,AG14,0),0) -> 0 | CC14: =IF(ABS(AH14)>ABS(SUM($AB14:$AM14)/'Key information'!$E$34*12/8),IF(ABS(AH14)>=$CK$5,AH14,0),0) -> 0 | CD14: =IF(ABS(AI14)>ABS(SUM($AB14:$AM14)/'Key information'!$E$34*12/8),IF(ABS(AI14)>=$CK$5,AI14,0),0) -> 0 | ... CH14: =IF(ABS(AM14)>ABS(SUM($AB14:$AM14)/'Key information'!$E$34*12/8),IF(ABS(AM14)>=$CK$5,AM14,0),0) -> 0 | CI14: =COUNTIF(AY14:OFFSET(CH14,0,(-12+'Key information'!$E$34)),">0") -> 0 | CJ14: =COUNTIF(AY14:OFFSET(CH14,0,(-12+'Key information'!$E$34)),"<0") -> 0 | CK14: =SUM(CI14:CJ14) -> 0
C15: Net sales | D15: =SUM(D10:D14) -> 0 | E15: =SUM(E10:E14) -> 0 | F15: =SUM(F10:F14) -> 0 | G15: =SUM(G10:G14) -> 0 | H15: =SUM(H10:H14) -> 0 | I15: =SUM(I10:I14) -> 0 | J15: =SUM(J10:J14) -> 0 | K15: =SUM(K10:K14) -> 0 | ... AQ15: =SUM(AQ10:AQ14) -> 0 | AS15: =SUM(AS10:AS14) -> 0 | AT15: =SUM(AT10:AT14) -> 0 | AX15: Net sales | CI15: =SUM(CI10:CI14) -> 0 | CJ15: =SUM(CJ10:CJ14) -> 0 | CK15: =SUM(CK10:CK14) -> 0
B16: CHNGFI | C16: Change in finished and semifinished goods inventories | D16: =SUMIFS(PL!F:F,PL!$B:$B,$B16)/'Key information'!$E$114 -> 0 | E16: =SUMIFS(PL!G:G,PL!$B:$B,$B16)/'Key information'!$E$114 -> 0 | F16: =SUMIFS(PL!H:H,PL!$B:$B,$B16)/'Key information'!$E$114 -> 0 | G16: =SUMIFS(PL!I:I,PL!$B:$B,$B16)/'Key information'!$E$114 -> 0 | H16: =SUMIFS(PL!J:J,PL!$B:$B,$B16)/'Key information'!$E$114 -> 0 | I16: =SUMIFS(PL!K:K,PL!$B:$B,$B16)/'Key information'!$E$114 -> 0 | J16: =SUMIFS(PL!L:L,PL!$B:$B,$B16)/'Key information'!$E$114 -> 0 | K16: =SUMIFS(PL!M:M,PL!$B:$B,$B16)/'Key information'!$E$114 -> 0 | L16: =SUMIFS(PL!N:N,PL!$B:$B,$B16)/'Key information'!$E$114 -> 0 | M16: =SUMIFS(PL!O:O,PL!$B:$B,$B16)/'Key information'!$E$114 -> 0 | N16: =SUMIFS(PL!P:P,PL!$B:$B,$B16)/'Key information'!$E$114 -> 0 | O16: =SUMIFS(PL!Q:Q,PL!$B:$B,$B16)/'Key information'!$E$114 -> 0 | P16: =SUMIFS(PL!R:R,PL!$B:$B,$B16)/'Key information'!$E$114 -> 0 | Q16: =SUMIFS(PL!S:S,PL!$B:$B,$B16)/'Key information'!$E$114 -> 0 | R16: =SUMIFS(PL!T:T,PL!$B:$B,$B16)/'Key information'!$E$114 -> 0 | S16: =SUMIFS(PL!U:U,PL!$B:$B,$B16)/'Key information'!$E$114 -> 0 | T16: =SUMIFS(PL!V:V,PL!$B:$B,$B16)/'Key information'!$E$114 -> 0 | U16: =SUMIFS(PL!W:W,PL!$B:$B,$B16)/'Key information'!$E$114 -> 0 | V16: =SUMIFS(PL!X:X,PL!$B:$B,$B16)/'Key information'!$E$114 -> 0 | W16: =SUMIFS(PL!Y:Y,PL!$B:$B,$B16)/'Key information'!$E$114 -> 0 | X16: =SUMIFS(PL!Z:Z,PL!$B:$B,$B16)/'Key information'!$E$114 -> 0 | Y16: =SUMIFS(PL!AA:AA,PL!$B:$B,$B16)/'Key information'!$E$114 -> 0 | Z16: =SUMIFS(PL!AB:AB,PL!$B:$B,$B16)/'Key information'!$E$114 -> 0 | AA16: =SUMIFS(PL!AC:AC,PL!$B:$B,$B16)/'Key information'!$E$114 -> 0 | AB16: =SUMIFS(PL!AD:AD,PL!$B:$B,$B16)/'Key information'!$E$114 -> 0 | AC16: =SUMIFS(PL!AE:AE,PL!$B:$B,$B16)/'Key information'!$E$114 -> 0 | AD16: =SUMIFS(PL!AF:AF,PL!$B:$B,$B16)/'Key information'!$E$114 -> 0 | AE16: =SUMIFS(PL!AG:AG,PL!$B:$B,$B16)/'Key information'!$E$114 -> 0 | AF16: =SUMIFS(PL!AH:AH,PL!$B:$B,$B16)/'Key information'!$E$114 -> 0 | AG16: =SUMIFS(PL!AI:AI,PL!$B:$B,$B16)/'Key information'!$E$114 -> 0 | AH16: =SUMIFS(PL!AJ:AJ,PL!$B:$B,$B16)/'Key information'!$E$114 -> 0 | AI16: =SUMIFS(PL!AK:AK,PL!$B:$B,$B16)/'Key information'!$E$114 -> 0 | AJ16: =SUMIFS(PL!AL:AL,PL!$B:$B,$B16)/'Key information'!$E$114 -> 0 | AK16: =SUMIFS(PL!AM:AM,PL!$B:$B,$B16)/'Key information'!$E$114 -> 0 | AL16: =SUMIFS(PL!AN:AN,PL!$B:$B,$B16)/'Key information'!$E$114 -> 0 | AM16: =SUMIFS(PL!AO:AO,PL!$B:$B,$B16)/'Key information'!$E$114 -> 0 | AN16: =SUM(D16:O16) -> 0 | AO16: =SUM(P16:AA16) -> 0 | AP16: =SUM(OFFSET(AM16,0,(-12+'Key information'!$E$34)):OFFSET(AA16,0,(-11+'Key information'!$E$34))) -> 0 | AQ16: =SUMIF(PL!$B:$B,PL_monthly!B16,PL!$AP:$AP)/'Key information'!$E$114 -> 0 | AS16: =SUM(OFFSET(AA16,0,(-12+'Key information'!$E$34)):P16) -> 0 | AT16: =SUM(OFFSET(AM16,0,(-12+'Key information'!$E$34)):AB16) -> 0 | AX16: Change in finished and semifinished goods inventories | AY16: =IF(ABS(D16)>ABS(SUM($D16:$O16)/8),IF(ABS(D16)>=$CK$5,D16,0),0) -> 0 | AZ16: =IF(ABS(E16)>ABS(SUM($D16:$O16)/8),IF(ABS(E16)>=$CK$5,E16,0),0) -> 0 | BA16: =IF(ABS(F16)>ABS(SUM($D16:$O16)/8),IF(ABS(F16)>=$CK$5,F16,0),0) -> 0 | BB16: =IF(ABS(G16)>ABS(SUM($D16:$O16)/8),IF(ABS(G16)>=$CK$5,G16,0),0) -> 0 | BC16: =IF(ABS(H16)>ABS(SUM($D16:$O16)/8),IF(ABS(H16)>=$CK$5,H16,0),0) -> 0 | BD16: =IF(ABS(I16)>ABS(SUM($D16:$O16)/8),IF(ABS(I16)>=$CK$5,I16,0),0) -> 0 | BE16: =IF(ABS(J16)>ABS(SUM($D16:$O16)/8),IF(ABS(J16)>=$CK$5,J16,0),0) -> 0 | BF16: =IF(ABS(K16)>ABS(SUM($D16:$O16)/8),IF(ABS(K16)>=$CK$5,K16,0),0) -> 0 | ... BJ16: =IF(ABS(O16)>ABS(SUM($D16:$O16)/8),IF(ABS(O16)>=$CK$5,O16,0),0) -> 0 | BK16: =IF(ABS(P16)>ABS(SUM($P16:$AA16)/8),IF(ABS(P16)>=$CK$5,P16,0),0) -> 0 | BL16: =IF(ABS(Q16)>ABS(SUM($P16:$AA16)/8),IF(ABS(Q16)>=$CK$5,Q16,0),0) -> 0 | BM16: =IF(ABS(R16)>ABS(SUM($P16:$AA16)/8),IF(ABS(R16)>=$CK$5,R16,0),0) -> 0 | BN16: =IF(ABS(S16)>ABS(SUM($P16:$AA16)/8),IF(ABS(S16)>=$CK$5,S16,0),0) -> 0 | BO16: =IF(ABS(T16)>ABS(SUM($P16:$AA16)/8),IF(ABS(T16)>=$CK$5,T16,0),0) -> 0 | BP16: =IF(ABS(U16)>ABS(SUM($P16:$AA16)/8),IF(ABS(U16)>=$CK$5,U16,0),0) -> 0 | BQ16: =IF(ABS(V16)>ABS(SUM($P16:$AA16)/8),IF(ABS(V16)>=$CK$5,V16,0),0) -> 0 | BR16: =IF(ABS(W16)>ABS(SUM($P16:$AA16)/8),IF(ABS(W16)>=$CK$5,W16,0),0) -> 0 | ... BV16: =IF(ABS(AA16)>ABS(SUM($P16:$AA16)/8),IF(ABS(AA16)>=$CK$5,AA16,0),0) -> 0 | BW16: =IF(ABS(AB16)>ABS(SUM($AB16:$AM16)/'Key information'!$E$34*12/8),IF(ABS(AB16)>=$CK$5,AB16,0),0) -> 0 | BX16: =IF(ABS(AC16)>ABS(SUM($AB16:$AM16)/'Key information'!$E$34*12/8),IF(ABS(AC16)>=$CK$5,AC16,0),0) -> 0 | BY16: =IF(ABS(AD16)>ABS(SUM($AB16:$AM16)/'Key information'!$E$34*12/8),IF(ABS(AD16)>=$CK$5,AD16,0),0) -> 0 | BZ16: =IF(ABS(AE16)>ABS(SUM($AB16:$AM16)/'Key information'!$E$34*12/8),IF(ABS(AE16)>=$CK$5,AE16,0),0) -> 0 | CA16: =IF(ABS(AF16)>ABS(SUM($AB16:$AM16)/'Key information'!$E$34*12/8),IF(ABS(AF16)>=$CK$5,AF16,0),0) -> 0 | CB16: =IF(ABS(AG16)>ABS(SUM($AB16:$AM16)/'Key information'!$E$34*12/8),IF(ABS(AG16)>=$CK$5,AG16,0),0) -> 0 | CC16: =IF(ABS(AH16)>ABS(SUM($AB16:$AM16)/'Key information'!$E$34*12/8),IF(ABS(AH16)>=$CK$5,AH16,0),0) -> 0 | CD16: =IF(ABS(AI16)>ABS(SUM($AB16:$AM16)/'Key information'!$E$34*12/8),IF(ABS(AI16)>=$CK$5,AI16,0),0) -> 0 | ... CH16: =IF(ABS(AM16)>ABS(SUM($AB16:$AM16)/'Key information'!$E$34*12/8),IF(ABS(AM16)>=$CK$5,AM16,0),0) -> 0 | CI16: =COUNTIF(AY16:OFFSET(CH16,0,(-12+'Key information'!$E$34)),">0") -> 0 | CJ16: =COUNTIF(AY16:OFFSET(CH16,0,(-12+'Key information'!$E$34)),"<0") -> 0 | CK16: =SUM(CI16:CJ16) -> 0
B17: OWNUSE | C17: Manufacturing for own use | D17: =SUMIFS(PL!F:F,PL!$B:$B,$B17)/'Key information'!$E$114 -> 0 | E17: =SUMIFS(PL!G:G,PL!$B:$B,$B17)/'Key information'!$E$114 -> 0 | F17: =SUMIFS(PL!H:H,PL!$B:$B,$B17)/'Key information'!$E$114 -> 0 | G17: =SUMIFS(PL!I:I,PL!$B:$B,$B17)/'Key information'!$E$114 -> 0 | H17: =SUMIFS(PL!J:J,PL!$B:$B,$B17)/'Key information'!$E$114 -> 0 | I17: =SUMIFS(PL!K:K,PL!$B:$B,$B17)/'Key information'!$E$114 -> 0 | J17: =SUMIFS(PL!L:L,PL!$B:$B,$B17)/'Key information'!$E$114 -> 0 | K17: =SUMIFS(PL!M:M,PL!$B:$B,$B17)/'Key information'!$E$114 -> 0 | L17: =SUMIFS(PL!N:N,PL!$B:$B,$B17)/'Key information'!$E$114 -> 0 | M17: =SUMIFS(PL!O:O,PL!$B:$B,$B17)/'Key information'!$E$114 -> 0 | N17: =SUMIFS(PL!P:P,PL!$B:$B,$B17)/'Key information'!$E$114 -> 0 | O17: =SUMIFS(PL!Q:Q,PL!$B:$B,$B17)/'Key information'!$E$114 -> 0 | P17: =SUMIFS(PL!R:R,PL!$B:$B,$B17)/'Key information'!$E$114 -> 0 | Q17: =SUMIFS(PL!S:S,PL!$B:$B,$B17)/'Key information'!$E$114 -> 0 | R17: =SUMIFS(PL!T:T,PL!$B:$B,$B17)/'Key information'!$E$114 -> 0 | S17: =SUMIFS(PL!U:U,PL!$B:$B,$B17)/'Key information'!$E$114 -> 0 | T17: =SUMIFS(PL!V:V,PL!$B:$B,$B17)/'Key information'!$E$114 -> 0 | U17: =SUMIFS(PL!W:W,PL!$B:$B,$B17)/'Key information'!$E$114 -> 0 | V17: =SUMIFS(PL!X:X,PL!$B:$B,$B17)/'Key information'!$E$114 -> 0 | W17: =SUMIFS(PL!Y:Y,PL!$B:$B,$B17)/'Key information'!$E$114 -> 0 | X17: =SUMIFS(PL!Z:Z,PL!$B:$B,$B17)/'Key information'!$E$114 -> 0 | Y17: =SUMIFS(PL!AA:AA,PL!$B:$B,$B17)/'Key information'!$E$114 -> 0 | Z17: =SUMIFS(PL!AB:AB,PL!$B:$B,$B17)/'Key information'!$E$114 -> 0 | AA17: =SUMIFS(PL!AC:AC,PL!$B:$B,$B17)/'Key information'!$E$114 -> 0 | AB17: =SUMIFS(PL!AD:AD,PL!$B:$B,$B17)/'Key information'!$E$114 -> 0 | AC17: =SUMIFS(PL!AE:AE,PL!$B:$B,$B17)/'Key information'!$E$114 -> 0 | AD17: =SUMIFS(PL!AF:AF,PL!$B:$B,$B17)/'Key information'!$E$114 -> 0 | AE17: =SUMIFS(PL!AG:AG,PL!$B:$B,$B17)/'Key information'!$E$114 -> 0 | AF17: =SUMIFS(PL!AH:AH,PL!$B:$B,$B17)/'Key information'!$E$114 -> 0 | AG17: =SUMIFS(PL!AI:AI,PL!$B:$B,$B17)/'Key information'!$E$114 -> 0 | AH17: =SUMIFS(PL!AJ:AJ,PL!$B:$B,$B17)/'Key information'!$E$114 -> 0 | AI17: =SUMIFS(PL!AK:AK,PL!$B:$B,$B17)/'Key information'!$E$114 -> 0 | AJ17: =SUMIFS(PL!AL:AL,PL!$B:$B,$B17)/'Key information'!$E$114 -> 0 | AK17: =SUMIFS(PL!AM:AM,PL!$B:$B,$B17)/'Key information'!$E$114 -> 0 | AL17: =SUMIFS(PL!AN:AN,PL!$B:$B,$B17)/'Key information'!$E$114 -> 0 | AM17: =SUMIFS(PL!AO:AO,PL!$B:$B,$B17)/'Key information'!$E$114 -> 0 | AN17: =SUM(D17:O17) -> 0 | AO17: =SUM(P17:AA17) -> 0 | AP17: =SUM(OFFSET(AM17,0,(-12+'Key information'!$E$34)):OFFSET(AA17,0,(-11+'Key information'!$E$34))) -> 0 | AQ17: =SUMIF(PL!$B:$B,PL_monthly!B17,PL!$AP:$AP)/'Key information'!$E$114 -> 0 | AS17: =SUM(OFFSET(AA17,0,(-12+'Key information'!$E$34)):P17) -> 0 | AT17: =SUM(OFFSET(AM17,0,(-12+'Key information'!$E$34)):AB17) -> 0 | AX17: Manufacturing for own use | AY17: =IF(ABS(D17)>ABS(SUM($D17:$O17)/8),IF(ABS(D17)>=$CK$5,D17,0),0) -> 0 | AZ17: =IF(ABS(E17)>ABS(SUM($D17:$O17)/8),IF(ABS(E17)>=$CK$5,E17,0),0) -> 0 | BA17: =IF(ABS(F17)>ABS(SUM($D17:$O17)/8),IF(ABS(F17)>=$CK$5,F17,0),0) -> 0 | BB17: =IF(ABS(G17)>ABS(SUM($D17:$O17)/8),IF(ABS(G17)>=$CK$5,G17,0),0) -> 0 | BC17: =IF(ABS(H17)>ABS(SUM($D17:$O17)/8),IF(ABS(H17)>=$CK$5,H17,0),0) -> 0 | BD17: =IF(ABS(I17)>ABS(SUM($D17:$O17)/8),IF(ABS(I17)>=$CK$5,I17,0),0) -> 0 | BE17: =IF(ABS(J17)>ABS(SUM($D17:$O17)/8),IF(ABS(J17)>=$CK$5,J17,0),0) -> 0 | BF17: =IF(ABS(K17)>ABS(SUM($D17:$O17)/8),IF(ABS(K17)>=$CK$5,K17,0),0) -> 0 | ... BJ17: =IF(ABS(O17)>ABS(SUM($D17:$O17)/8),IF(ABS(O17)>=$CK$5,O17,0),0) -> 0 | BK17: =IF(ABS(P17)>ABS(SUM($P17:$AA17)/8),IF(ABS(P17)>=$CK$5,P17,0),0) -> 0 | BL17: =IF(ABS(Q17)>ABS(SUM($P17:$AA17)/8),IF(ABS(Q17)>=$CK$5,Q17,0),0) -> 0 | BM17: =IF(ABS(R17)>ABS(SUM($P17:$AA17)/8),IF(ABS(R17)>=$CK$5,R17,0),0) -> 0 | BN17: =IF(ABS(S17)>ABS(SUM($P17:$AA17)/8),IF(ABS(S17)>=$CK$5,S17,0),0) -> 0 | BO17: =IF(ABS(T17)>ABS(SUM($P17:$AA17)/8),IF(ABS(T17)>=$CK$5,T17,0),0) -> 0 | BP17: =IF(ABS(U17)>ABS(SUM($P17:$AA17)/8),IF(ABS(U17)>=$CK$5,U17,0),0) -> 0 | BQ17: =IF(ABS(V17)>ABS(SUM($P17:$AA17)/8),IF(ABS(V17)>=$CK$5,V17,0),0) -> 0 | BR17: =IF(ABS(W17)>ABS(SUM($P17:$AA17)/8),IF(ABS(W17)>=$CK$5,W17,0),0) -> 0 | ... BV17: =IF(ABS(AA17)>ABS(SUM($P17:$AA17)/8),IF(ABS(AA17)>=$CK$5,AA17,0),0) -> 0 | BW17: =IF(ABS(AB17)>ABS(SUM($AB17:$AM17)/'Key information'!$E$34*12/8),IF(ABS(AB17)>=$CK$5,AB17,0),0) -> 0 | BX17: =IF(ABS(AC17)>ABS(SUM($AB17:$AM17)/'Key information'!$E$34*12/8),IF(ABS(AC17)>=$CK$5,AC17,0),0) -> 0 | BY17: =IF(ABS(AD17)>ABS(SUM($AB17:$AM17)/'Key information'!$E$34*12/8),IF(ABS(AD17)>=$CK$5,AD17,0),0) -> 0 | BZ17: =IF(ABS(AE17)>ABS(SUM($AB17:$AM17)/'Key information'!$E$34*12/8),IF(ABS(AE17)>=$CK$5,AE17,0),0) -> 0 | CA17: =IF(ABS(AF17)>ABS(SUM($AB17:$AM17)/'Key information'!$E$34*12/8),IF(ABS(AF17)>=$CK$5,AF17,0),0) -> 0 | CB17: =IF(ABS(AG17)>ABS(SUM($AB17:$AM17)/'Key information'!$E$34*12/8),IF(ABS(AG17)>=$CK$5,AG17,0),0) -> 0 | CC17: =IF(ABS(AH17)>ABS(SUM($AB17:$AM17)/'Key information'!$E$34*12/8),IF(ABS(AH17)>=$CK$5,AH17,0),0) -> 0 | CD17: =IF(ABS(AI17)>ABS(SUM($AB17:$AM17)/'Key information'!$E$34*12/8),IF(ABS(AI17)>=$CK$5,AI17,0),0) -> 0 | ... CH17: =IF(ABS(AM17)>ABS(SUM($AB17:$AM17)/'Key information'!$E$34*12/8),IF(ABS(AM17)>=$CK$5,AM17,0),0) -> 0 | CI17: =COUNTIF(AY17:OFFSET(CH17,0,(-12+'Key information'!$E$34)),">0") -> 0 | CJ17: =COUNTIF(AY17:OFFSET(CH17,0,(-12+'Key information'!$E$34)),"<0") -> 0 | CK17: =SUM(CI17:CJ17) -> 0
